Workbook

Sheet BÁO CÁO
B2: BÁO CÁO BÁN HÀNG KÊNH ONLINE THÁNG | H2: 2 | I2: 2026 | S2: ROAS Shopee | T2: =L9/L5 -> 9.6096082
B3: Ngày báo cáo: | D3: 46054 | F3: =TODAY() -> 46082
B4: CHỈ TIÊU | D4: TARGET | E4: THỰC ĐẠT | F4: CHÊNH LỆCH TĐ/TARGET | G4: % TĐ/TARGET | H4: % CHÊNH LỆCH | I4: CHI PHÍ Ads | L4: SHOPEE | M4: GOOGLE ADS Youtube | N4: LAZADA | O4: TIKTOK | P4: FACEBOOK | Q4: ZALO | U4: =L5+N5+R3 -> 7590676
B5: DOANH SỐ | D5: =C16 -> 125000000 | E5: =K16 -> 85299165 | F5: =E5-D5 -> -39700835 | G5: =E5/D5 -> 0.68239332 | H5: =E5/D5-1 -> -0.31760668 | I5: CHI PHÍ QUẢNG CÁO | L5: ='ADS SHOPEE'!Y213 -> 7050676 | N5: 540000 | O5: 1160000 | R5: Tổng chi phí QC: | T5: =L5+M5+N5+O5+P5+Q5+L10+L11 -> 14971476
B6: Tổng PO | D6: =D16 -> 192.30769 | E6: =L16 -> 89 | F6: =E6-D6 -> -103.30769 | G6: =E6/D6 -> 0.4628 | H6: =E6/D6-1 -> -0.5372 | I6: ROAS | L6: =L9/I16 -> 0.84639063 | R6: %Chi phí Quảng cáo/NET SALE: | T6: =T5/E5 -> 0.17551726
B7: Số PO Trung Bình | D7: =D5/D6 -> 650000 | E7: =E5/E6 -> 958417.58 | F7: =E7-D7 -> 308417.58 | G7: =E7/D7 -> 1.4744886 | H7: =E7/D7-1 -> 0.47448859 | I7: % C.Phí QC/DOANH SỐ QC | L7: =L5/L9 -> 0.10406252
B8: Doanh số Trung Bình/ngày | D8: =D5/30 -> 4166666.7 | E8: =AVERAGEIF(B17:B44,"<"&TODAY(),K17:K44) -> 3046398.8 | I8: % CPhí QC/DOANH SỐ TĐ | L8: =L5/I16 -> 0.088077537 | R8: %Chi phí sàn + voucher + chiến dịch + Aff: | T8: 0.19
B9: Số lượng đơn Trung Bình/ngày | E9: =IFERROR(__xludf.DUMMYFUNCTION("IFERROR(SUM(FILTER(L17:L44, B17:B44<=$F$3)) / COUNT(FILTER(B17:B44, B17:B44<=$F$3)), """")"),3.1785714285714284) -> 3.1785714 | F9: % TỔNG CHI PHÍ/DOANH THU: | H9: =T6+T8 -> 0.36551726 | I9: Doanh số từ quảng cáo | L9: ='ADS SHOPEE'!W213 -> 67754234 | R9: % TỔNG CHI PHÍ/DOANH THU: | T9: =T6+T8 -> 0.36551726
I10: Gói tương tác cơ bản | L10: 1350000
I11: Gói tiếp thị standard | L11: 4870800
B13: GIÁ TRỊ TRUNG BÌNH PO | D13: 650000 | N13: =K16/C16-1 -> -0.31760668 | O13: =L16/D16-1 -> -0.5372
B14: Ngày | C14: TARGET | E14: THỰC HIỆN | N14: % THỰC ĐẠT/TARGET | P14: CHÊNH LỆCH THỰC ĐẠT/TARGET | R14: Đơn đã hủy | S14: Doanh số đơn hủy | T14: Đơn đã hoàn trả / hoàn tiền | U14: Doanh số các đơn Trả hàng/ Hoàn tiền
B15: =COUNTA(B17:B47) -> 28 | C15: Doanh số | D15: Tổng số PO | E15: Doanh số ZALO + HOTLINE | F15: Doanh số HARAVAN = WEBSITE | G15: Doanh số FANPAGE | H15: Doanh số LAZADA | I15: Doanh số SHOPPE | J15: Doanh số TIKTOK | K15: Tổng Doanh số Online | L15: Tổng số PO | M15: Giá Trị Po Trung Bình | N15: Doanh số | O15: Tổng số PO | P15: Doanh số | Q15: Tổng số PO
B16: TOTAL | C16: =SUBTOTAL(9,C17:C47) -> 125000000 | D16: =SUBTOTAL(9,D17:D50) -> 192.30769 | E16: =SUBTOTAL(9,E17:E50) -> 2107000 | F16: =SUBTOTAL(9,F17:F50) -> 909000 | G16: =SUBTOTAL(9,G17:G50) -> 0 | H16: =SUBTOTAL(9,H17:H50) -> 0 | I16: =SUBTOTAL(9,I17:I50) -> 80050785 | J16: =SUBTOTAL(9,J17:J50) -> 2232380 | K16: =SUBTOTAL(9,K17:K50) -> 85299165 | L16: =SUBTOTAL(9,L17:L50) -> 89 | M16: =K16/L16 -> 958417.58 | N16: =K16/C16 -> 0.68239332 | O16: =L16/D16 -> 0.4628 | P16: =SUBTOTAL(9,P17:P50) -> -39700835 | Q16: =SUBTOTAL(9,Q17:Q50) -> -103.30769 | R16: =SUBTOTAL(9,R17:R50) -> 12 | S16: =SUBTOTAL(9,S17:S50) -> 12539712 | T16: =SUBTOTAL(9,T17:T50) -> 2 | U16: =SUBTOTAL(9,U17:U50) -> 1570000
B17: 46054 | C17: =SUMIFS(TARGET!E:E,TARGET!D:D,B17) -> 4464285.7 | D17: =C17/$D$13 -> 6.8681319 | E17: =SUMIFS(ZALO!C:C,ZALO!A:A,B17) -> 0 | F17: =SUMIFS(WEB!C:C,WEB!A:A,B17) -> 0 | G17: =SUMIFS(FANPAGE!C:C,FANPAGE!A:A,B17) -> 0 | H17: =SUMIFS(LAZADA!B:B,LAZADA!A:A,B17) -> 0 | I17: =SUMIFS('DS Shoppe (đã xác nhận)'!B:B,'DS Shoppe (đã xác nhận)'!A:A,B17) -> 2764634 | J17: =SUMIFS(TIKTOK!B:B,TIKTOK!A:A,B25) -> 0 | K17: =SUM(E17:J17) -> 2764634 | L17: =SUMIFS('DS Shoppe (đã xác nhận)'!C:C,'DS Shoppe (đã xác nhận)'!A:A,B17)+SUMIFS(LAZADA!E:E,LAZADA!A:A,B17)+SUMIFS(WEB!B:B,WEB!A:A,B17)+SUMIFS(ZALO!B:B,ZALO!A:A,B17)+SUMIFS(FANPAGE!B:B,FANPAGE!A:A,B17)+SUMIFS(TIKTOK!J6:J35,TIKTOK!A6:A35,B17) -> 4 | M17: =K17/L17 -> 691158.5 | N17: =K17/C17 -> 0.61927802 | O17: =L17/D17 -> 0.5824 | P17: =K17-C17 -> -1699651.7 | Q17: =L17-D17 -> -2.8681319 | R17: =SUMIFS('DS Shoppe (đã xác nhận)'!H:H,'DS Shoppe (đã xác nhận)'!A:A,B17) -> 0 | S17: =SUMIFS('DS Shoppe (đã xác nhận)'!I:I,'DS Shoppe (đã xác nhận)'!A:A,B17) -> 0 | T17: =SUMIFS('DS Shoppe (đã xác nhận)'!J:J,'DS Shoppe (đã xác nhận)'!A:A,B17) -> 0 | U17: =SUMIFS('DS Shoppe (đã xác nhận)'!K:K,'DS Shoppe (đã xác nhận)'!A:A,B17) -> 0
B18: =B17+1 -> 46055 | C18: =SUMIFS(TARGET!E:E,TARGET!D:D,B18) -> 4464285.7 | D18: =C18/$D$13 -> 6.8681319 | E18: =SUMIFS(ZALO!C:C,ZALO!A:A,B18) -> 0 | F18: =SUMIFS(WEB!C:C,WEB!A:A,B18) -> 0 | G18: =SUMIFS(FANPAGE!C:C,FANPAGE!A:A,B18) -> 0 | H18: =SUMIFS(LAZADA!B:B,LAZADA!A:A,B18) -> 0 | I18: =SUMIFS('DS Shoppe (đã xác nhận)'!B:B,'DS Shoppe (đã xác nhận)'!A:A,B18) -> 12891791 | J18: =SUMIFS(TIKTOK!B:B,TIKTOK!A:A,B18) -> 0 | K18: =SUM(E18:J18) -> 12891791 | L18: =SUMIFS('DS Shoppe (đã xác nhận)'!C:C,'DS Shoppe (đã xác nhận)'!A:A,B18)+SUMIFS(LAZADA!E:E,LAZADA!A:A,B18)+SUMIFS(WEB!B:B,WEB!A:A,B18)+SUMIFS(ZALO!B:B,ZALO!A:A,B18)+SUMIFS(FANPAGE!B:B,FANPAGE!A:A,B18)+SUMIFS(TIKTOK!J7:J36,TIKTOK!A7:A36,B18) -> 15 | M18: =K18/L18 -> 859452.73 | N18: =K18/C18 -> 2.8877612 | O18: =L18/D18 -> 2.184 | P18: =K18-C18 -> 8427505.3 | Q18: =L18-D18 -> 8.1318681 | R18: =SUMIFS('DS Shoppe (đã xác nhận)'!H:H,'DS Shoppe (đã xác nhận)'!A:A,B18) -> 0 | S18: =SUMIFS('DS Shoppe (đã xác nhận)'!I:I,'DS Shoppe (đã xác nhận)'!A:A,B18) -> 0 | T18: =SUMIFS('DS Shoppe (đã xác nhận)'!J:J,'DS Shoppe (đã xác nhận)'!A:A,B18) -> 0 | U18: =SUMIFS('DS Shoppe (đã xác nhận)'!K:K,'DS Shoppe (đã xác nhận)'!A:A,B18) -> 0
B19: =B18+1 -> 46056 | C19: =SUMIFS(TARGET!E:E,TARGET!D:D,B19) -> 4464285.7 | D19: =C19/$D$13 -> 6.8681319 | E19: =SUMIFS(ZALO!C:C,ZALO!A:A,B19) -> 0 | F19: =SUMIFS(WEB!C:C,WEB!A:A,B19) -> 0 | G19: =SUMIFS(FANPAGE!C:C,FANPAGE!A:A,B19) -> 0 | H19: =SUMIFS(LAZADA!B:B,LAZADA!A:A,B19) -> 0 | I19: =SUMIFS('DS Shoppe (đã xác nhận)'!B:B,'DS Shoppe (đã xác nhận)'!A:A,B19) -> 3577124 | J19: =SUMIFS(TIKTOK!B:B,TIKTOK!A:A,B19) -> 0 | K19: =SUM(E19:J19) -> 3577124 | L19: =SUMIFS('DS Shoppe (đã xác nhận)'!C:C,'DS Shoppe (đã xác nhận)'!A:A,B19)+SUMIFS(LAZADA!E:E,LAZADA!A:A,B19)+SUMIFS(WEB!B:B,WEB!A:A,B19)+SUMIFS(ZALO!B:B,ZALO!A:A,B19)+SUMIFS(FANPAGE!B:B,FANPAGE!A:A,B19)+SUMIFS(TIKTOK!J8:J37,TIKTOK!A8:A37,B19) -> 5 | M19: =IF(L19=0,"0",K19/L19) -> 715424.8 | N19: =K19/C19 -> 0.80127578 | O19: =L19/D19 -> 0.728 | P19: =K19-C19 -> -887161.71 | Q19: =L19-D19 -> -1.8681319 | R19: =SUMIFS('DS Shoppe (đã xác nhận)'!H:H,'DS Shoppe (đã xác nhận)'!A:A,B19) -> 0 | S19: =SUMIFS('DS Shoppe (đã xác nhận)'!I:I,'DS Shoppe (đã xác nhận)'!A:A,B19) -> 0 | T19: =SUMIFS('DS Shoppe (đã xác nhận)'!J:J,'DS Shoppe (đã xác nhận)'!A:A,B19) -> 0 | U19: =SUMIFS('DS Shoppe (đã xác nhận)'!K:K,'DS Shoppe (đã xác nhận)'!A:A,B19) -> 0
B20: =B19+1 -> 46057 | C20: =SUMIFS(TARGET!E:E,TARGET!D:D,B20) -> 4464285.7 | D20: =C20/$D$13 -> 6.8681319 | E20: =SUMIFS(ZALO!C:C,ZALO!A:A,B20) -> 0 | F20: =SUMIFS(WEB!C:C,WEB!A:A,B20) -> 0 | G20: =SUMIFS(FANPAGE!C:C,FANPAGE!A:A,B20) -> 0 | H20: =SUMIFS(LAZADA!B:B,LAZADA!A:A,B20) -> 0 | I20: =SUMIFS('DS Shoppe (đã xác nhận)'!B:B,'DS Shoppe (đã xác nhận)'!A:A,B20) -> 2578636 | J20: =SUMIFS(TIKTOK!B:B,TIKTOK!A:A,B20) -> 0 | K20: =SUM(E20:J20) -> 2578636 | L20: =SUMIFS('DS Shoppe (đã xác nhận)'!C:C,'DS Shoppe (đã xác nhận)'!A:A,B20)+SUMIFS(LAZADA!E:E,LAZADA!A:A,B20)+SUMIFS(WEB!B:B,WEB!A:A,B20)+SUMIFS(ZALO!B:B,ZALO!A:A,B20)+SUMIFS(FANPAGE!B:B,FANPAGE!A:A,B20)+SUMIFS(TIKTOK!J9:J38,TIKTOK!A9:A38,B20) -> 3 | M20: =IF(L20=0,"0",K20/L20) -> 859545.33 | N20: =K20/C20 -> 0.57761446 | O20: =L20/D20 -> 0.4368 | P20: =K20-C20 -> -1885649.7 | Q20: =L20-D20 -> -3.8681319 | R20: =SUMIFS('DS Shoppe (đã xác nhận)'!H:H,'DS Shoppe (đã xác nhận)'!A:A,B20) -> 0 | S20: =SUMIFS('DS Shoppe (đã xác nhận)'!I:I,'DS Shoppe (đã xác nhận)'!A:A,B20) -> 0 | T20: =SUMIFS('DS Shoppe (đã xác nhận)'!J:J,'DS Shoppe (đã xác nhận)'!A:A,B20) -> 0 | U20: =SUMIFS('DS Shoppe (đã xác nhận)'!K:K,'DS Shoppe (đã xác nhận)'!A:A,B20) -> 0
B21: =B20+1 -> 46058 | C21: =SUMIFS(TARGET!E:E,TARGET!D:D,B21) -> 4464285.7 | D21: =C21/$D$13 -> 6.8681319 | E21: =SUMIFS(ZALO!C:C,ZALO!A:A,B21) -> 0 | F21: =SUMIFS(WEB!C:C,WEB!A:A,B21) -> 0 | G21: =SUMIFS(FANPAGE!C:C,FANPAGE!A:A,B21) -> 0 | H21: =SUMIFS(LAZADA!B:B,LAZADA!A:A,B21) -> 0 | I21: =SUMIFS('DS Shoppe (đã xác nhận)'!B:B,'DS Shoppe (đã xác nhận)'!A:A,B21) -> 4938391 | J21: =SUMIFS(TIKTOK!B:B,TIKTOK!A:A,B21) -> 0 | K21: =SUM(E21:J21) -> 4938391 | L21: =SUMIFS('DS Shoppe (đã xác nhận)'!C:C,'DS Shoppe (đã xác nhận)'!A:A,B21)+SUMIFS(LAZADA!E:E,LAZADA!A:A,B21)+SUMIFS(WEB!B:B,WEB!A:A,B21)+SUMIFS(ZALO!B:B,ZALO!A:A,B21)+SUMIFS(FANPAGE!B:B,FANPAGE!A:A,B21)+SUMIFS(TIKTOK!J10:J39,TIKTOK!A10:A39,B21) -> 3 | M21: =IF(L21=0,"0",K21/L21) -> 1646130.3 | N21: =K21/C21 -> 1.1061996 | O21: =L21/D21 -> 0.4368 | P21: =K21-C21 -> 474105.29 | Q21: =L21-D21 -> -3.8681319 | R21: =SUMIFS('DS Shoppe (đã xác nhận)'!H:H,'DS Shoppe (đã xác nhận)'!A:A,B21) -> 0 | S21: =SUMIFS('DS Shoppe (đã xác nhận)'!I:I,'DS Shoppe (đã xác nhận)'!A:A,B21) -> 0 | T21: =SUMIFS('DS Shoppe (đã xác nhận)'!J:J,'DS Shoppe (đã xác nhận)'!A:A,B21) -> 0 | U21: =SUMIFS('DS Shoppe (đã xác nhận)'!K:K,'DS Shoppe (đã xác nhận)'!A:A,B21) -> 0
B22: =B21+1 -> 46059 | C22: =SUMIFS(TARGET!E:E,TARGET!D:D,B22) -> 4464285.7 | D22: =C22/$D$13 -> 6.8681319 | E22: =SUMIFS(ZALO!C:C,ZALO!A:A,B22) -> 0 | F22: =SUMIFS(WEB!C:C,WEB!A:A,B22) -> 0 | G22: =SUMIFS(FANPAGE!C:C,FANPAGE!A:A,B22) -> 0 | H22: =SUMIFS(LAZADA!B:B,LAZADA!A:A,B22) -> 0 | I22: =SUMIFS('DS Shoppe (đã xác nhận)'!B:B,'DS Shoppe (đã xác nhận)'!A:A,B22) -> 60000 | J22: =SUMIFS(TIKTOK!B:B,TIKTOK!A:A,B22) -> 0 | K22: =SUM(E22:J22) -> 60000 | L22: =SUMIFS('DS Shoppe (đã xác nhận)'!C:C,'DS Shoppe (đã xác nhận)'!A:A,B22)+SUMIFS(LAZADA!E:E,LAZADA!A:A,B22)+SUMIFS(WEB!B:B,WEB!A:A,B22)+SUMIFS(ZALO!B:B,ZALO!A:A,B22)+SUMIFS(FANPAGE!B:B,FANPAGE!A:A,B22)+SUMIFS(TIKTOK!J11:J40,TIKTOK!A11:A40,B22) -> 1 | M22: =IF(L22=0,"0",K22/L22) -> 60000 | N22: =K22/C22 -> 0.01344 | O22: =L22/D22 -> 0.1456 | P22: =K22-C22 -> -4404285.7 | Q22: =L22-D22 -> -5.8681319 | R22: =SUMIFS('DS Shoppe (đã xác nhận)'!H:H,'DS Shoppe (đã xác nhận)'!A:A,B22) -> 0 | S22: =SUMIFS('DS Shoppe (đã xác nhận)'!I:I,'DS Shoppe (đã xác nhận)'!A:A,B22) -> 0 | T22: =SUMIFS('DS Shoppe (đã xác nhận)'!J:J,'DS Shoppe (đã xác nhận)'!A:A,B22) -> 0 | U22: =SUMIFS('DS Shoppe (đã xác nhận)'!K:K,'DS Shoppe (đã xác nhận)'!A:A,B22) -> 0
B23: =B22+1 -> 46060 | C23: =SUMIFS(TARGET!E:E,TARGET!D:D,B23) -> 4464285.7 | D23: =C23/$D$13 -> 6.8681319 | E23: =SUMIFS(ZALO!C:C,ZALO!A:A,B23) -> 0 | F23: =SUMIFS(WEB!C:C,WEB!A:A,B23) -> 0 | G23: =SUMIFS(FANPAGE!C:C,FANPAGE!A:A,B23) -> 0 | H23: =SUMIFS(LAZADA!B:B,LAZADA!A:A,B23) -> 0 | I23: =SUMIFS('DS Shoppe (đã xác nhận)'!B:B,'DS Shoppe (đã xác nhận)'!A:A,B23) -> 2158140 | J23: =SUMIFS(TIKTOK!B:B,TIKTOK!A:A,B23) -> 0 | K23: =SUM(E23:J23) -> 2158140 | L23: =SUMIFS('DS Shoppe (đã xác nhận)'!C:C,'DS Shoppe (đã xác nhận)'!A:A,B23)+SUMIFS(LAZADA!E:E,LAZADA!A:A,B23)+SUMIFS(WEB!B:B,WEB!A:A,B23)+SUMIFS(ZALO!B:B,ZALO!A:A,B23)+SUMIFS(FANPAGE!B:B,FANPAGE!A:A,B23)+SUMIFS(TIKTOK!J12:J41,TIKTOK!A12:A41,B23) -> 2 | M23: =IF(L23=0,"0",K23/L23) -> 1079070 | N23: =K23/C23 -> 0.48342336 | O23: =L23/D23 -> 0.2912 | P23: =K23-C23 -> -2306145.7 | Q23: =L23-D23 -> -4.8681319 | R23: =SUMIFS('DS Shoppe (đã xác nhận)'!H:H,'DS Shoppe (đã xác nhận)'!A:A,B23) -> 0 | S23: =SUMIFS('DS Shoppe (đã xác nhận)'!I:I,'DS Shoppe (đã xác nhận)'!A:A,B23) -> 0 | T23: =SUMIFS('DS Shoppe (đã xác nhận)'!J:J,'DS Shoppe (đã xác nhận)'!A:A,B23) -> 0 | U23: =SUMIFS('DS Shoppe (đã xác nhận)'!K:K,'DS Shoppe (đã xác nhận)'!A:A,B23) -> 0
B24: =B23+1 -> 46061 | C24: =SUMIFS(TARGET!E:E,TARGET!D:D,B24) -> 4464285.7 | D24: =C24/$D$13 -> 6.8681319 | E24: =SUMIFS(ZALO!C:C,ZALO!A:A,B24) -> 0 | F24: =SUMIFS(WEB!C:C,WEB!A:A,B24) -> 0 | G24: =SUMIFS(FANPAGE!C:C,FANPAGE!A:A,B24) -> 0 | H24: =SUMIFS(LAZADA!B:B,LAZADA!A:A,B24) -> 0 | I24: =SUMIFS('DS Shoppe (đã xác nhận)'!B:B,'DS Shoppe (đã xác nhận)'!A:A,B24) -> 4782887 | J24: =SUMIFS(TIKTOK!B:B,TIKTOK!A:A,B24) -> 0 | K24: =SUM(E24:J24) -> 4782887 | L24: =SUMIFS('DS Shoppe (đã xác nhận)'!C:C,'DS Shoppe (đã xác nhận)'!A:A,B24)+SUMIFS(LAZADA!E:E,LAZADA!A:A,B24)+SUMIFS(WEB!B:B,WEB!A:A,B24)+SUMIFS(ZALO!B:B,ZALO!A:A,B24)+SUMIFS(FANPAGE!B:B,FANPAGE!A:A,B24)+SUMIFS(TIKTOK!J13:J42,TIKTOK!A13:A42,B24) -> 6 | M24: =IF(L24=0,"0",K24/L24) -> 797147.83 | N24: =K24/C24 -> 1.0713667 | O24: =L24/D24 -> 0.8736 | P24: =K24-C24 -> 318601.29 | Q24: =L24-D24 -> -0.86813187 | R24: =SUMIFS('DS Shoppe (đã xác nhận)'!H:H,'DS Shoppe (đã xác nhận)'!A:A,B24) -> 0 | S24: =SUMIFS('DS Shoppe (đã xác nhận)'!I:I,'DS Shoppe (đã xác nhận)'!A:A,B24) -> 0 | T24: =SUMIFS('DS Shoppe (đã xác nhận)'!J:J,'DS Shoppe (đã xác nhận)'!A:A,B24) -> 1 | U24: =SUMIFS('DS Shoppe (đã xác nhận)'!K:K,'DS Shoppe (đã xác nhận)'!A:A,B24) -> 846000
B25: =B24+1 -> 46062 | C25: =SUMIFS(TARGET!E:E,TARGET!D:D,B25) -> 4464285.7 | D25: =C25/$D$13 -> 6.8681319 | E25: =SUMIFS(ZALO!C:C,ZALO!A:A,B25) -> 0 | F25: =SUMIFS(WEB!C:C,WEB!A:A,B25) -> 909000 | G25: =SUMIFS(FANPAGE!C:C,FANPAGE!A:A,B25) -> 0 | H25: =SUMIFS(LAZADA!B:B,LAZADA!A:A,B25) -> 0 | I25: =SUMIFS('DS Shoppe (đã xác nhận)'!B:B,'DS Shoppe (đã xác nhận)'!A:A,B25) -> 1835353 | J25: =SUMIFS(TIKTOK!B:B,TIKTOK!A:A,B25) -> 0 | K25: =SUM(E25:J25) -> 2744353 | L25: =SUMIFS('DS Shoppe (đã xác nhận)'!C:C,'DS Shoppe (đã xác nhận)'!A:A,B25)+SUMIFS(LAZADA!E:E,LAZADA!A:A,B25)+SUMIFS(WEB!B:B,WEB!A:A,B25)+SUMIFS(ZALO!B:B,ZALO!A:A,B25)+SUMIFS(FANPAGE!B:B,FANPAGE!A:A,B25)+SUMIFS(TIKTOK!J14:J43,TIKTOK!A14:A43,B25) -> 3 | M25: =IF(L25=0,"0",K25/L25) -> 914784.33 | N25: =K25/C25 -> 0.61473507 | O25: =L25/D25 -> 0.4368 | P25: =K25-C25 -> -1719932.7 | Q25: =L25-D25 -> -3.8681319 | R25: =SUMIFS('DS Shoppe (đã xác nhận)'!H:H,'DS Shoppe (đã xác nhận)'!A:A,B25) -> 1 | S25: =SUMIFS('DS Shoppe (đã xác nhận)'!I:I,'DS Shoppe (đã xác nhận)'!A:A,B25) -> 926091 | T25: =SUMIFS('DS Shoppe (đã xác nhận)'!J:J,'DS Shoppe (đã xác nhận)'!A:A,B25) -> 0 | U25: =SUMIFS('DS Shoppe (đã xác nhận)'!K:K,'DS Shoppe (đã xác nhận)'!A:A,B25) -> 0
B26: =B25+1 -> 46063 | C26: =SUMIFS(TARGET!E:E,TARGET!D:D,B26) -> 4464285.7 | D26: =C26/$D$13 -> 6.8681319 | E26: =SUMIFS(ZALO!C:C,ZALO!A:A,B26) -> 0 | F26: =SUMIFS(WEB!C:C,WEB!A:A,B26) -> 0 | G26: =SUMIFS(FANPAGE!C:C,FANPAGE!A:A,B26) -> 0 | H26: =SUMIFS(LAZADA!B:B,LAZADA!A:A,B26) -> 0 | I26: =SUMIFS('DS Shoppe (đã xác nhận)'!B:B,'DS Shoppe (đã xác nhận)'!A:A,B26) -> 5177368 | J26: =SUMIFS(TIKTOK!B:B,TIKTOK!A:A,B26) -> 0 | K26: =SUM(E26:J26) -> 5177368 | L26: =SUMIFS('DS Shoppe (đã xác nhận)'!C:C,'DS Shoppe (đã xác nhận)'!A:A,B26)+SUMIFS(LAZADA!E:E,LAZADA!A:A,B26)+SUMIFS(WEB!B:B,WEB!A:A,B26)+SUMIFS(ZALO!B:B,ZALO!A:A,B26)+SUMIFS(FANPAGE!B:B,FANPAGE!A:A,B26)+SUMIFS(TIKTOK!J15:J44,TIKTOK!A15:A44,B26) -> 6 | M26: =IF(L26=0,"0",K26/L26) -> 862894.67 | N26: =K26/C26 -> 1.1597304 | O26: =L26/D26 -> 0.8736 | P26: =K26-C26 -> 713082.29 | Q26: =L26-D26 -> -0.86813187 | R26: =SUMIFS('DS Shoppe (đã xác nhận)'!H:H,'DS Shoppe (đã xác nhận)'!A:A,B26) -> 0 | S26: =SUMIFS('DS Shoppe (đã xác nhận)'!I:I,'DS Shoppe (đã xác nhận)'!A:A,B26) -> 0 | T26: =SUMIFS('DS Shoppe (đã xác nhận)'!J:J,'DS Shoppe (đã xác nhận)'!A:A,B26) -> 1 | U26: =SUMIFS('DS Shoppe (đã xác nhận)'!K:K,'DS Shoppe (đã xác nhận)'!A:A,B26) -> 724000
B27: =B26+1 -> 46064 | C27: =SUMIFS(TARGET!E:E,TARGET!D:D,B27) -> 4464285.7 | D27: =C27/$D$13 -> 6.8681319 | E27: =SUMIFS(ZALO!C:C,ZALO!A:A,B27) -> 0 | F27: =SUMIFS(WEB!C:C,WEB!A:A,B27) -> 0 | G27: =SUMIFS(FANPAGE!C:C,FANPAGE!A:A,B27) -> 0 | H27: =SUMIFS(LAZADA!B:B,LAZADA!A:A,B27) -> 0 | I27: =SUMIFS('DS Shoppe (đã xác nhận)'!B:B,'DS Shoppe (đã xác nhận)'!A:A,B27) -> 1951880 | J27: =SUMIFS(TIKTOK!B:B,TIKTOK!A:A,B27) -> 0 | K27: =SUM(E27:J27) -> 1951880 | L27: =SUMIFS('DS Shoppe (đã xác nhận)'!C:C,'DS Shoppe (đã xác nhận)'!A:A,B27)+SUMIFS(LAZADA!E:E,LAZADA!A:A,B27)+SUMIFS(WEB!B:B,WEB!A:A,B27)+SUMIFS(ZALO!B:B,ZALO!A:A,B27)+SUMIFS(FANPAGE!B:B,FANPAGE!A:A,B27)+SUMIFS(TIKTOK!J16:J45,TIKTOK!A16:A45,B27) -> 2 | M27: =IF(L27=0,"0",K27/L27) -> 975940 | N27: =K27/C27 -> 0.43722112 | O27: =L27/D27 -> 0.2912 | P27: =K27-C27 -> -2512405.7 | Q27: =L27-D27 -> -4.8681319 | R27: =SUMIFS('DS Shoppe (đã xác nhận)'!H:H,'DS Shoppe (đã xác nhận)'!A:A,B27) -> 0 | S27: =SUMIFS('DS Shoppe (đã xác nhận)'!I:I,'DS Shoppe (đã xác nhận)'!A:A,B27) -> 0 | T27: =SUMIFS('DS Shoppe (đã xác nhận)'!J:J,'DS Shoppe (đã xác nhận)'!A:A,B27) -> 0 | U27: =SUMIFS('DS Shoppe (đã xác nhận)'!K:K,'DS Shoppe (đã xác nhận)'!A:A,B27) -> 0
B28: =B27+1 -> 46065 | C28: =SUMIFS(TARGET!E:E,TARGET!D:D,B28) -> 4464285.7 | D28: =C28/$D$13 -> 6.8681319 | E28: =SUMIFS(ZALO!C:C,ZALO!A:A,B28) -> 0 | F28: =SUMIFS(WEB!C:C,WEB!A:A,B28) -> 0 | G28: =SUMIFS(FANPAGE!C:C,FANPAGE!A:A,B28) -> 0 | H28: =SUMIFS(LAZADA!B:B,LAZADA!A:A,B28) -> 0 | I28: =SUMIFS('DS Shoppe (đã xác nhận)'!B:B,'DS Shoppe (đã xác nhận)'!A:A,B28) -> 3446276 | J28: =SUMIFS(TIKTOK!B:B,TIKTOK!A:A,B28) -> 0 | K28: =SUM(E28:J28) -> 3446276 | L28: =SUMIFS('DS Shoppe (đã xác nhận)'!C:C,'DS Shoppe (đã xác nhận)'!A:A,B28)+SUMIFS(LAZADA!E:E,LAZADA!A:A,B28)+SUMIFS(WEB!B:B,WEB!A:A,B28)+SUMIFS(ZALO!B:B,ZALO!A:A,B28)+SUMIFS(FANPAGE!B:B,FANPAGE!A:A,B28) -> 2 | M28: =IF(L28=0,"0",K28/L28) -> 1723138 | N28: =K28/C28 -> 0.77196582 | O28: =L28/D28 -> 0.2912 | P28: =K28-C28 -> -1018009.7 | Q28: =L28-D28 -> -4.8681319 | R28: =SUMIFS('DS Shoppe (đã xác nhận)'!H:H,'DS Shoppe (đã xác nhận)'!A:A,B28) -> 1 | S28: =SUMIFS('DS Shoppe (đã xác nhận)'!I:I,'DS Shoppe (đã xác nhận)'!A:A,B28) -> 2019600 | T28: =SUMIFS('DS Shoppe (đã xác nhận)'!J:J,'DS Shoppe (đã xác nhận)'!A:A,B28) -> 0 | U28: =SUMIFS('DS Shoppe (đã xác nhận)'!K:K,'DS Shoppe (đã xác nhận)'!A:A,B28) -> 0
B29: =B28+1 -> 46066 | C29: =SUMIFS(TARGET!E:E,TARGET!D:D,B29) -> 4464285.7 | D29: =C29/$D$13 -> 6.8681319 | E29: =SUMIFS(ZALO!C:C,ZALO!A:A,B29) -> 1278000 | F29: =SUMIFS(WEB!C:C,WEB!A:A,B29) -> 0 | G29: =SUMIFS(FANPAGE!C:C,FANPAGE!A:A,B29) -> 0 | H29: =SUMIFS(LAZADA!B:B,LAZADA!A:A,B29) -> 0 | I29: =SUMIFS('DS Shoppe (đã xác nhận)'!B:B,'DS Shoppe (đã xác nhận)'!A:A,B29) -> 0 | J29: =SUMIFS(TIKTOK!B:B,TIKTOK!A:A,B29) -> 1456380 | K29: =SUM(E29:J29) -> 2734380 | L29: =SUMIFS('DS Shoppe (đã xác nhận)'!C:C,'DS Shoppe (đã xác nhận)'!A:A,B29)+SUMIFS(LAZADA!E:E,LAZADA!A:A,B29)+SUMIFS(WEB!B:B,WEB!A:A,B29)+SUMIFS(ZALO!B:B,ZALO!A:A,B29)+SUMIFS(FANPAGE!B:B,FANPAGE!A:A,B29) -> 1 | M29: =IF(L29=0,"0",K29/L29) -> 2734380 | N29: =K29/C29 -> 0.61250112 | O29: =L29/D29 -> 0.1456 | P29: =K29-C29 -> -1729905.7 | Q29: =L29-D29 -> -5.8681319 | R29: =SUMIFS('DS Shoppe (đã xác nhận)'!H:H,'DS Shoppe (đã xác nhận)'!A:A,B29) -> 0 | S29: =SUMIFS('DS Shoppe (đã xác nhận)'!I:I,'DS Shoppe (đã xác nhận)'!A:A,B29) -> 0 | T29: =SUMIFS('DS Shoppe (đã xác nhận)'!J:J,'DS Shoppe (đã xác nhận)'!A:A,B29) -> 0 | U29: =SUMIFS('DS Shoppe (đã xác nhận)'!K:K,'DS Shoppe (đã xác nhận)'!A:A,B29) -> 0
B30: =B29+1 -> 46067 | C30: =SUMIFS(TARGET!E:E,TARGET!D:D,B30) -> 4464285.7 | D30: =C30/$D$13 -> 6.8681319 | E30: =SUMIFS(ZALO!C:C,ZALO!A:A,B30) -> 0 | F30: =SUMIFS(WEB!C:C,WEB!A:A,B30) -> 0 | G30: =SUMIFS(FANPAGE!C:C,FANPAGE!A:A,B30) -> 0 | H30: =SUMIFS(LAZADA!B:B,LAZADA!A:A,B30) -> 0 | I30: =SUMIFS('DS Shoppe (đã xác nhận)'!B:B,'DS Shoppe (đã xác nhận)'!A:A,B30) -> 2613091 | J30: =SUMIFS(TIKTOK!B:B,TIKTOK!A:A,B30) -> 0 | K30: =SUM(E30:J30) -> 2613091 | L30: =SUMIFS('DS Shoppe (đã xác nhận)'!C:C,'DS Shoppe (đã xác nhận)'!A:A,B30)+SUMIFS(LAZADA!E:E,LAZADA!A:A,B30)+SUMIFS(WEB!B:B,WEB!A:A,B30)+SUMIFS(ZALO!B:B,ZALO!A:A,B30)+SUMIFS(FANPAGE!B:B,FANPAGE!A:A,B30) -> 2 | M30: =IF(L30=0,"0",K30/L30) -> 1306545.5 | N30: =K30/C30 -> 0.58533238 | O30: =L30/D30 -> 0.2912 | P30: =K30-C30 -> -1851194.7 | Q30: =L30-D30 -> -4.8681319 | R30: =SUMIFS('DS Shoppe (đã xác nhận)'!H:H,'DS Shoppe (đã xác nhận)'!A:A,B30) -> 0 | S30: =SUMIFS('DS Shoppe (đã xác nhận)'!I:I,'DS Shoppe (đã xác nhận)'!A:A,B30) -> 0 | T30: =SUMIFS('DS Shoppe (đã xác nhận)'!J:J,'DS Shoppe (đã xác nhận)'!A:A,B30) -> 0 | U30: =SUMIFS('DS Shoppe (đã xác nhận)'!K:K,'DS Shoppe (đã xác nhận)'!A:A,B30) -> 0
B31: =B30+1 -> 46068 | C31: =SUMIFS(TARGET!E:E,TARGET!D:D,B31) -> 4464285.7 | D31: =C31/$D$13 -> 6.8681319 | E31: =SUMIFS(ZALO!C:C,ZALO!A:A,B31) -> 0 | F31: =SUMIFS(WEB!C:C,WEB!A:A,B31) -> 0 | G31: =SUMIFS(FANPAGE!C:C,FANPAGE!A:A,B31) -> 0 | H31: =SUMIFS(LAZADA!B:B,LAZADA!A:A,B31) -> 0 | I31: =SUMIFS('DS Shoppe (đã xác nhận)'!B:B,'DS Shoppe (đã xác nhận)'!A:A,B31) -> 0 | J31: =SUMIFS(TIKTOK!B:B,TIKTOK!A:A,B31) -> 0 | K31: =SUM(E31:J31) -> 0 | L31: =SUMIFS('DS Shoppe (đã xác nhận)'!C:C,'DS Shoppe (đã xác nhận)'!A:A,B31)+SUMIFS(LAZADA!E:E,LAZADA!A:A,B31)+SUMIFS(WEB!B:B,WEB!A:A,B31)+SUMIFS(ZALO!B:B,ZALO!A:A,B31)+SUMIFS(FANPAGE!B:B,FANPAGE!A:A,B31) -> 0 | M31: =IF(L31=0,"0",K31/L31) -> 0 | N31: =K31/C31 -> 0 | O31: =L31/D31 -> 0 | P31: =K31-C31 -> -4464285.7 | Q31: =L31-D31 -> -6.8681319 | R31: =SUMIFS('DS Shoppe (đã xác nhận)'!H:H,'DS Shoppe (đã xác nhận)'!A:A,B31) -> 2 | S31: =SUMIFS('DS Shoppe (đã xác nhận)'!I:I,'DS Shoppe (đã xác nhận)'!A:A,B31) -> 1243900 | T31: =SUMIFS('DS Shoppe (đã xác nhận)'!J:J,'DS Shoppe (đã xác nhận)'!A:A,B31) -> 0 | U31: =SUMIFS('DS Shoppe (đã xác nhận)'!K:K,'DS Shoppe (đã xác nhận)'!A:A,B31) -> 0
B32: =B31+1 -> 46069 | C32: =SUMIFS(TARGET!E:E,TARGET!D:D,B32) -> 4464285.7 | D32: =C32/$D$13 -> 6.8681319 | E32: =SUMIFS(ZALO!C:C,ZALO!A:A,B32) -> 0 | F32: =SUMIFS(WEB!C:C,WEB!A:A,B32) -> 0 | G32: =SUMIFS(FANPAGE!C:C,FANPAGE!A:A,B32) -> 0 | H32: =SUMIFS(LAZADA!B:B,LAZADA!A:A,B32) -> 0 | I32: =SUMIFS('DS Shoppe (đã xác nhận)'!B:B,'DS Shoppe (đã xác nhận)'!A:A,B32) -> 926091 | J32: =SUMIFS(TIKTOK!B:B,TIKTOK!A:A,B32) -> 0 | K32: =SUM(E32:J32) -> 926091 | L32: =SUMIFS('DS Shoppe (đã xác nhận)'!C:C,'DS Shoppe (đã xác nhận)'!A:A,B32)+SUMIFS(LAZADA!E:E,LAZADA!A:A,B32)+SUMIFS(WEB!B:B,WEB!A:A,B32)+SUMIFS(ZALO!B:B,ZALO!A:A,B32)+SUMIFS(FANPAGE!B:B,FANPAGE!A:A,B32) -> 1 | M32: =IF(L32=0,"0",K32/L32) -> 926091 | N32: =K32/C32 -> 0.20744438 | O32: =L32/D32 -> 0.1456 | P32: =K32-C32 -> -3538194.7 | Q32: =L32-D32 -> -5.8681319 | R32: =SUMIFS('DS Shoppe (đã xác nhận)'!H:H,'DS Shoppe (đã xác nhận)'!A:A,B32) -> 0 | S32: =SUMIFS('DS Shoppe (đã xác nhận)'!I:I,'DS Shoppe (đã xác nhận)'!A:A,B32) -> 0 | T32: =SUMIFS('DS Shoppe (đã xác nhận)'!J:J,'DS Shoppe (đã xác nhận)'!A:A,B32) -> 0 | U32: =SUMIFS('DS Shoppe (đã xác nhận)'!K:K,'DS Shoppe (đã xác nhận)'!A:A,B32) -> 0
B33: =B32+1 -> 46070 | C33: =SUMIFS(TARGET!E:E,TARGET!D:D,B33) -> 4464285.7 | D33: =C33/$D$13 -> 6.8681319 | E33: =SUMIFS(ZALO!C:C,ZALO!A:A,B33) -> 0 | F33: =SUMIFS(WEB!C:C,WEB!A:A,B33) -> 0 | G33: =SUMIFS(FANPAGE!C:C,FANPAGE!A:A,B33) -> 0 | H33: =SUMIFS(LAZADA!B:B,LAZADA!A:A,B33) -> 0 | I33: =SUMIFS('DS Shoppe (đã xác nhận)'!B:B,'DS Shoppe (đã xác nhận)'!A:A,B33) -> 0 | J33: =SUMIFS(TIKTOK!B:B,TIKTOK!A:A,B33) -> 0 | K33: =SUM(E33:J33) -> 0 | L33: =SUMIFS('DS Shoppe (đã xác nhận)'!C:C,'DS Shoppe (đã xác nhận)'!A:A,B33)+SUMIFS(LAZADA!E:E,LAZADA!A:A,B33)+SUMIFS(WEB!B:B,WEB!A:A,B33)+SUMIFS(ZALO!B:B,ZALO!A:A,B33)+SUMIFS(FANPAGE!B:B,FANPAGE!A:A,B33) -> 0 | M33: =IF(L33=0,"0",K33/L33) -> 0 | N33: =K33/C33 -> 0 | O33: =L33/D33 -> 0 | P33: =K33-C33 -> -4464285.7 | Q33: =L33-D33 -> -6.8681319 | R33: =SUMIFS('DS Shoppe (đã xác nhận)'!H:H,'DS Shoppe (đã xác nhận)'!A:A,B33) -> 0 | S33: =SUMIFS('DS Shoppe (đã xác nhận)'!I:I,'DS Shoppe (đã xác nhận)'!A:A,B33) -> 0 | T33: =SUMIFS('DS Shoppe (đã xác nhận)'!J:J,'DS Shoppe (đã xác nhận)'!A:A,B33) -> 0 | U33: =SUMIFS('DS Shoppe (đã xác nhận)'!K:K,'DS Shoppe (đã xác nhận)'!A:A,B33) -> 0
B34: =B33+1 -> 46071 | C34: =SUMIFS(TARGET!E:E,TARGET!D:D,B34) -> 4464285.7 | D34: =C34/$D$13 -> 6.8681319 | E34: =SUMIFS(ZALO!C:C,ZALO!A:A,B34) -> 0 | F34: =SUMIFS(WEB!C:C,WEB!A:A,B34) -> 0 | G34: =SUMIFS(FANPAGE!C:C,FANPAGE!A:A,B34) -> 0 | H34: =SUMIFS(LAZADA!B:B,LAZADA!A:A,B34) -> 0 | I34: =SUMIFS('DS Shoppe (đã xác nhận)'!B:B,'DS Shoppe (đã xác nhận)'!A:A,B34) -> 977061 | J34: =SUMIFS(TIKTOK!B:B,TIKTOK!A:A,B34) -> 0 | K34: =SUM(E34:J34) -> 977061 | L34: =SUMIFS('DS Shoppe (đã xác nhận)'!C:C,'DS Shoppe (đã xác nhận)'!A:A,B34)+SUMIFS(LAZADA!E:E,LAZADA!A:A,B34)+SUMIFS(WEB!B:B,WEB!A:A,B34)+SUMIFS(ZALO!B:B,ZALO!A:A,B34)+SUMIFS(FANPAGE!B:B,FANPAGE!A:A,B34) -> 2 | M34: =IF(L34=0,"0",K34/L34) -> 488530.5 | N34: =K34/C34 -> 0.21886166 | O34: =L34/D34 -> 0.2912 | P34: =K34-C34 -> -3487224.7 | Q34: =L34-D34 -> -4.8681319 | R34: =SUMIFS('DS Shoppe (đã xác nhận)'!H:H,'DS Shoppe (đã xác nhận)'!A:A,B34) -> 0 | S34: =SUMIFS('DS Shoppe (đã xác nhận)'!I:I,'DS Shoppe (đã xác nhận)'!A:A,B34) -> 0 | T34: =SUMIFS('DS Shoppe (đã xác nhận)'!J:J,'DS Shoppe (đã xác nhận)'!A:A,B34) -> 0 | U34: =SUMIFS('DS Shoppe (đã xác nhận)'!K:K,'DS Shoppe (đã xác nhận)'!A:A,B34) -> 0
B35: =B34+1 -> 46072 | C35: =SUMIFS(TARGET!E:E,TARGET!D:D,B35) -> 4464285.7 | D35: =C35/$D$13 -> 6.8681319 | E35: =SUMIFS(ZALO!C:C,ZALO!A:A,B35) -> 0 | F35: =SUMIFS(WEB!C:C,WEB!A:A,B35) -> 0 | G35: =SUMIFS(FANPAGE!C:C,FANPAGE!A:A,B35) -> 0 | H35: =SUMIFS(LAZADA!B:B,LAZADA!A:A,B35) -> 0 | I35: =SUMIFS('DS Shoppe (đã xác nhận)'!B:B,'DS Shoppe (đã xác nhận)'!A:A,B35) -> 1009800 | J35: =SUMIFS(TIKTOK!B:B,TIKTOK!A:A,B35) -> 0 | K35: =SUM(E35:J35) -> 1009800 | L35: =SUMIFS('DS Shoppe (đã xác nhận)'!C:C,'DS Shoppe (đã xác nhận)'!A:A,B35)+SUMIFS(LAZADA!E:E,LAZADA!A:A,B35)+SUMIFS(WEB!B:B,WEB!A:A,B35)+SUMIFS(ZALO!B:B,ZALO!A:A,B35)+SUMIFS(FANPAGE!B:B,FANPAGE!A:A,B35) -> 1 | M35: =IF(L35=0,"0",K35/L35) -> 1009800 | N35: =K35/C35 -> 0.2261952 | O35: =L35/D35 -> 0.1456 | P35: =K35-C35 -> -3454485.7 | Q35: =L35-D35 -> -5.8681319 | R35: =SUMIFS('DS Shoppe (đã xác nhận)'!H:H,'DS Shoppe (đã xác nhận)'!A:A,B35) -> 2 | S35: =SUMIFS('DS Shoppe (đã xác nhận)'!I:I,'DS Shoppe (đã xác nhận)'!A:A,B35) -> 1408252 | T35: =SUMIFS('DS Shoppe (đã xác nhận)'!J:J,'DS Shoppe (đã xác nhận)'!A:A,B35) -> 0 | U35: =SUMIFS('DS Shoppe (đã xác nhận)'!K:K,'DS Shoppe (đã xác nhận)'!A:A,B35) -> 0
B36: =B35+1 -> 46073 | C36: =SUMIFS(TARGET!E:E,TARGET!D:D,B36) -> 4464285.7 | D36: =C36/$D$13 -> 6.8681319 | E36: =SUMIFS(ZALO!C:C,ZALO!A:A,B36) -> 0 | F36: =SUMIFS(WEB!C:C,WEB!A:A,B36) -> 0 | G36: =SUMIFS(FANPAGE!C:C,FANPAGE!A:A,B36) -> 0 | H36: =SUMIFS(LAZADA!B:B,LAZADA!A:A,B36) -> 0 | I36: =SUMIFS('DS Shoppe (đã xác nhận)'!B:B,'DS Shoppe (đã xác nhận)'!A:A,B36) -> 1009800 | J36: =SUMIFS(TIKTOK!B:B,TIKTOK!A:A,B36) -> 0 | K36: =SUM(E36:J36) -> 1009800 | L36: =SUMIFS('DS Shoppe (đã xác nhận)'!C:C,'DS Shoppe (đã xác nhận)'!A:A,B36)+SUMIFS(LAZADA!E:E,LAZADA!A:A,B36)+SUMIFS(WEB!B:B,WEB!A:A,B36)+SUMIFS(ZALO!B:B,ZALO!A:A,B36)+SUMIFS(FANPAGE!B:B,FANPAGE!A:A,B36) -> 1 | M36: =IF(L36=0,"0",K36/L36) -> 1009800 | N36: =K36/C36 -> 0.2261952 | O36: =L36/D36 -> 0.1456 | P36: =K36-C36 -> -3454485.7 | Q36: =L36-D36 -> -5.8681319 | R36: =SUMIFS('DS Shoppe (đã xác nhận)'!H:H,'DS Shoppe (đã xác nhận)'!A:A,B36) -> 2 | S36: =SUMIFS('DS Shoppe (đã xác nhận)'!I:I,'DS Shoppe (đã xác nhận)'!A:A,B36) -> 2778273 | T36: =SUMIFS('DS Shoppe (đã xác nhận)'!J:J,'DS Shoppe (đã xác nhận)'!A:A,B36) -> 0 | U36: =SUMIFS('DS Shoppe (đã xác nhận)'!K:K,'DS Shoppe (đã xác nhận)'!A:A,B36) -> 0
B37: =B36+1 -> 46074 | C37: =SUMIFS(TARGET!E:E,TARGET!D:D,B37) -> 4464285.7 | D37: =C37/$D$13 -> 6.8681319 | E37: =SUMIFS(ZALO!C:C,ZALO!A:A,B37) -> 0 | F37: =SUMIFS(WEB!C:C,WEB!A:A,B37) -> 0 | G37: =SUMIFS(FANPAGE!C:C,FANPAGE!A:A,B37) -> 0 | H37: =SUMIFS(LAZADA!B:B,LAZADA!A:A,B37) -> 0 | I37: =SUMIFS('DS Shoppe (đã xác nhận)'!B:B,'DS Shoppe (đã xác nhận)'!A:A,B37) -> 1852182 | J37: =SUMIFS(TIKTOK!B:B,TIKTOK!A:A,B37) -> 0 | K37: =SUM(E37:J37) -> 1852182 | L37: =SUMIFS('DS Shoppe (đã xác nhận)'!C:C,'DS Shoppe (đã xác nhận)'!A:A,B37)+SUMIFS(LAZADA!E:E,LAZADA!A:A,B37)+SUMIFS(WEB!B:B,WEB!A:A,B37)+SUMIFS(ZALO!B:B,ZALO!A:A,B37)+SUMIFS(FANPAGE!B:B,FANPAGE!A:A,B37) -> 1 | M37: =IF(L37=0,"0",K37/L37) -> 1852182 | N37: =K37/C37 -> 0.41488877 | O37: =L37/D37 -> 0.1456 | P37: =K37-C37 -> -2612103.7 | Q37: =L37-D37 -> -5.8681319 | R37: =SUMIFS('DS Shoppe (đã xác nhận)'!H:H,'DS Shoppe (đã xác nhận)'!A:A,B37) -> 0 | S37: =SUMIFS('DS Shoppe (đã xác nhận)'!I:I,'DS Shoppe (đã xác nhận)'!A:A,B37) -> 0 | T37: =SUMIFS('DS Shoppe (đã xác nhận)'!J:J,'DS Shoppe (đã xác nhận)'!A:A,B37) -> 0 | U37: =SUMIFS('DS Shoppe (đã xác nhận)'!K:K,'DS Shoppe (đã xác nhận)'!A:A,B37) -> 0
B38: =B37+1 -> 46075 | C38: =SUMIFS(TARGET!E:E,TARGET!D:D,B38) -> 4464285.7 | D38: =C38/$D$13 -> 6.8681319 | E38: =SUMIFS(ZALO!C:C,ZALO!A:A,B38) -> 0 | F38: =SUMIFS(WEB!C:C,WEB!A:A,B38) -> 0 | G38: =SUMIFS(FANPAGE!C:C,FANPAGE!A:A,B38) -> 0 | H38: =SUMIFS(LAZADA!B:B,LAZADA!A:A,B38) -> 0 | I38: =SUMIFS('DS Shoppe (đã xác nhận)'!B:B,'DS Shoppe (đã xác nhận)'!A:A,B38) -> 2261140 | J38: =SUMIFS(TIKTOK!B:B,TIKTOK!A:A,B38) -> 0 | K38: =SUM(E38:J38) -> 2261140 | L38: =SUMIFS('DS Shoppe (đã xác nhận)'!C:C,'DS Shoppe (đã xác nhận)'!A:A,B38)+SUMIFS(LAZADA!E:E,LAZADA!A:A,B38)+SUMIFS(WEB!B:B,WEB!A:A,B38)+SUMIFS(ZALO!B:B,ZALO!A:A,B38)+SUMIFS(FANPAGE!B:B,FANPAGE!A:A,B38) -> 3 | M38: =IF(L38=0,"0",K38/L38) -> 753713.33 | N38: =K38/C38 -> 0.50649536 | O38: =L38/D38 -> 0.4368 | P38: =K38-C38 -> -2203145.7 | Q38: =L38-D38 -> -3.8681319 | R38: =SUMIFS('DS Shoppe (đã xác nhận)'!H:H,'DS Shoppe (đã xác nhận)'!A:A,B38) -> 0 | S38: =SUMIFS('DS Shoppe (đã xác nhận)'!I:I,'DS Shoppe (đã xác nhận)'!A:A,B38) -> 0 | T38: =SUMIFS('DS Shoppe (đã xác nhận)'!J:J,'DS Shoppe (đã xác nhận)'!A:A,B38) -> 0 | U38: =SUMIFS('DS Shoppe (đã xác nhận)'!K:K,'DS Shoppe (đã xác nhận)'!A:A,B38) -> 0
B39: =B38+1 -> 46076 | C39: =SUMIFS(TARGET!E:E,TARGET!D:D,B39) -> 4464285.7 | D39: =C39/$D$13 -> 6.8681319 | E39: =SUMIFS(ZALO!C:C,ZALO!A:A,B39) -> 829000 | F39: =SUMIFS(WEB!C:C,WEB!A:A,B39) -> 0 | G39: =SUMIFS(FANPAGE!C:C,FANPAGE!A:A,B39) -> 0 | H39: =SUMIFS(LAZADA!B:B,LAZADA!A:A,B39) -> 0 | I39: =SUMIFS('DS Shoppe (đã xác nhận)'!B:B,'DS Shoppe (đã xác nhận)'!A:A,B39) -> 4351400 | J39: =SUMIFS(TIKTOK!B:B,TIKTOK!A:A,B39) -> 0 | K39: =SUM(E39:J39) -> 5180400 | L39: =SUMIFS('DS Shoppe (đã xác nhận)'!C:C,'DS Shoppe (đã xác nhận)'!A:A,B39)+SUMIFS(LAZADA!E:E,LAZADA!A:A,B39)+SUMIFS(WEB!B:B,WEB!A:A,B39)+SUMIFS(ZALO!B:B,ZALO!A:A,B39)+SUMIFS(FANPAGE!B:B,FANPAGE!A:A,B39) -> 5 | M39: =IF(L39=0,"0",K39/L39) -> 1036080 | N39: =K39/C39 -> 1.1604096 | O39: =L39/D39 -> 0.728 | P39: =K39-C39 -> 716114.29 | Q39: =L39-D39 -> -1.8681319 | R39: =SUMIFS('DS Shoppe (đã xác nhận)'!H:H,'DS Shoppe (đã xác nhận)'!A:A,B39) -> 1 | S39: =SUMIFS('DS Shoppe (đã xác nhận)'!I:I,'DS Shoppe (đã xác nhận)'!A:A,B39) -> 2778276 | T39: =SUMIFS('DS Shoppe (đã xác nhận)'!J:J,'DS Shoppe (đã xác nhận)'!A:A,B39) -> 0 | U39: =SUMIFS('DS Shoppe (đã xác nhận)'!K:K,'DS Shoppe (đã xác nhận)'!A:A,B39) -> 0
... B44: =B43+1 -> 46081 | C44: =SUMIFS(TARGET!E:E,TARGET!D:D,B44) -> 4464285.7 | D44: =C44/$D$13 -> 6.8681319 | E44: =SUMIFS(ZALO!C:C,ZALO!A:A,B44) -> 0 | F44: =SUMIFS(WEB!C:C,WEB!A:A,B44) -> 0 | G44: =SUMIFS(FANPAGE!C:C,FANPAGE!A:A,B44) -> 0 | H44: =SUMIFS(LAZADA!B:B,LAZADA!A:A,B44) -> 0 | I44: =SUMIFS('DS Shoppe (đã xác nhận)'!B:B,'DS Shoppe (đã xác nhận)'!A:A,B44) -> 1836900 | J44: =SUMIFS(TIKTOK!B:B,TIKTOK!A:A,B44) -> 0 | K44: =SUM(E44:J44) -> 1836900 | L44: =SUMIFS('DS Shoppe (đã xác nhận)'!C:C,'DS Shoppe (đã xác nhận)'!A:A,B44)+SUMIFS(LAZADA!E:E,LAZADA!A:A,B44)+SUMIFS(WEB!B:B,WEB!A:A,B44)+SUMIFS(ZALO!B:B,ZALO!A:A,B44)+SUMIFS(FANPAGE!B:B,FANPAGE!A:A,B44) -> 1 | M44: =IF(L44=0,"0",K44/L44) -> 1836900 | N44: =K44/C44 -> 0.4114656 | O44: =L44/D44 -> 0.1456 | P44: =K44-C44 -> -2627385.7 | Q44: =L44-D44 -> -5.8681319 | R44: =SUMIFS('DS Shoppe (đã xác nhận)'!H:H,'DS Shoppe (đã xác nhận)'!A:A,B44) -> 0 | S44: =SUMIFS('DS Shoppe (đã xác nhận)'!I:I,'DS Shoppe (đã xác nhận)'!A:A,B44) -> 0 | T44: =SUMIFS('DS Shoppe (đã xác nhận)'!J:J,'DS Shoppe (đã xác nhận)'!A:A,B44) -> 0 | U44: =SUMIFS('DS Shoppe (đã xác nhận)'!K:K,'DS Shoppe (đã xác nhận)'!A:A,B44) -> 0

Sheet ADS SHOPEE
A1: Báo cáo quảng cáo trả theo CPC - Shopee Việt Nam
A2: Tên đăng nhập | B2: healthybeauty.officialstore
A3: Tên gian hàng | B3: DƯỢC PHẨM HEALTHY BEAUTY
A4: Mã Người bán | B4: 227240948
A5: Thời gian tạo báo cáo | B5: 45843.419
A6: Khoảng thời gian | B6: 01/06/2025 - 30/06/2025
W7: =SUM(W9:W26) -> 19452000 | Y7: =SUM(Y9:Y26) -> 3427031
A8: Thứ tự | B8: Tên quảng cáo | C8: Trạng thái | D8: Loại quảng cáo | E8: Mã sản phẩm | F8: Cài đặt Đối tượng | G8: Nội dung quảng cáo | H8: Phương thức đấu thầu | I8: Vị trí | J8: Ngày bắt đầu | K8: Ngày kết thúc | L8: Số lượt xem | M8: Số lượt click | N8: Tỷ Lệ Click | O8: Lượt chuyển đổi | P8: Lượt chuyển đổi trực tiếp | Q8: Tỷ lệ chuyển đổi | R8: Tỷ lệ chuyển đổi trực tiếp | S8: Chi phí cho mỗi lượt chuyển đổi | T8: Chi phí cho mỗi lượt chuyển đổi trực tiếp | U8: Sản phẩm đã bán | V8: Sản phẩm đã bán trực tiếp | W8: GMV | X8: GMV trực tiếp | Y8: Chi phí | Z8: ROAS | AA8: ROAS trực tiếp | AB8: ACOS | AC8: ACOS trực tiếp | AD8: Lượt xem Sản phẩm | AE8: Lượt clicks Sản phẩm | AF8: Tỷ lệ Click Sản phẩm | AG8: THÁNG
A9: 1 | B9: Auto shop | C9: Đang diễn ra | D9: Quảng cáo Shop | E9: - | F9: - | G9: Mặc định | H9: Giá thầu Tự động | I9: - | J9: 45784 | K9: Không giới hạn | L9: 6833 | M9: 1230 | N9: 18.00% | O9: 8 | P9: 6 | Q9: 0.65% | R9: 0.49% | S9: 91377.65 | T9: 121836.9 | U9: 8 | V9: 6 | W9: 5848000 | X9: 5246000 | Y9: 731021 | Z9: 8 | AA9: 7.18 | AB9: 12.50% | AC9: 13.93% | AD9: 20786 | AE9: 137 | AF9: 0.66% | AG9: 6
A10: 2 | B10: Viên Uống Giúp Chống Nắng Trắng Da Mờ Nám HB GLUTA WHITE + [4] | C10: Đang diễn ra | D10: Quảng cáo Sản phẩm | E10: 8782633181 | F10: - | G10: Tối ưu Sáng tạo đã được tắt | H10: Tối đa Doanh thu Tùy chỉnh ROAS | I10: Tất cả | J10: 45660 | K10: Không giới hạn | L10: 37018 | M10: 162 | N10: 0.44% | O10: 2 | P10: 2 | Q10: 1.23% | R10: 1.23% | S10: 438594.1 | T10: 438594.1 | U10: 2 | V10: 2 | W10: 2970000 | X10: 2970000 | Y10: 877188 | Z10: 3.39 | AA10: 3.39 | AB10: 29.53% | AC10: 29.53% | AD10: - | AE10: - | AF10: - | AG10: 6
A11: 3 | B11: Viên Uống Đông Trùng Hạ Thảo Bồi Bổ Khí Huyết HB CORDY EXTRACT [4] | C11: Đang diễn ra | D11: Quảng cáo Sản phẩm | E11: 5219966803 | F11: - | G11: Tối ưu Sáng tạo đã được bật | H11: Tối đa Doanh thu Tùy chỉnh ROAS | I11: Tất cả | J11: 45660 | K11: Không giới hạn | L11: 9756 | M11: 52 | N11: 0.53% | O11: 1 | P11: 1 | Q11: 1.92% | R11: 1.92% | S11: 277324.8 | T11: 277324.8 | U11: 1 | V11: 1 | W11: 731000 | X11: 731000 | Y11: 277325 | Z11: 2.64 | AA11: 2.64 | AB11: 37.94% | AC11: 37.94% | AD11: - | AE11: - | AF11: - | AG11: 6
A12: 4 | B12: Viên uống giúp tái tạo và nuôi dưỡng mô sụn - HB Glucollagen 7 in 1 [6] | C12: Đang diễn ra | D12: Quảng cáo Sản phẩm | E12: 25666719442 | F12: - | G12: Tối ưu Sáng tạo đã được tắt | H12: Tối đa Doanh thu Tùy chỉnh ROAS | I12: Tất cả | J12: 45833 | K12: Không giới hạn | L12: 4525 | M12: 43 | N12: 0.95% | O12: 4 | P12: 4 | Q12: 9.30% | R12: 9.30% | S12: 52036.55 | T12: 52036.55 | U12: 4 | V12: 4 | W12: 2430000 | X12: 2430000 | Y12: 208146 | Z12: 11.67 | AA12: 11.67 | AB12: 8.57% | AC12: 8.57% | AD12: - | AE12: - | AF12: - | AG12: 6
A13: 5 | B13: Viên uống HB Glucosamine 3 in 1 60 viên - 200 viên [5] | C13: Đang diễn ra | D13: Quảng cáo Sản phẩm | E13: 24867481840 | F13: Đối tượng Tự động | G13: Tối ưu Sáng tạo đã được tắt | H13: Giá thầu Thủ công | I13: Tìm kiếm | J13: 45785 | K13: Không giới hạn | L13: 1600 | M13: 25 | N13: 1.56% | O13: 1 | P13: 1 | Q13: 4.00% | R13: 4.00% | S13: 240000 | T13: 240000 | U13: 1 | V13: 1 | W13: 286000 | X13: 286000 | Y13: 240000 | Z13: 1.19 | AA13: 1.19 | AB13: 83.92% | AC13: 83.92% | AD13: - | AE13: - | AF13: - | AG13: 6
A14: 6 | B14: Viên uống HB GutCare (30 - 60 viên) hỗ trợ giảm triệu chứng đau khớp | C14: Đang diễn ra | D14: Quảng cáo Sản phẩm | E14: 22657955668 | F14: - | G14: Tối ưu Sáng tạo đã được tắt | H14: Tối đa Doanh thu Tùy chỉnh ROAS | I14: Tất cả | J14: 45660 | K14: Không giới hạn | L14: 1320 | M14: 9 | N14: 0.68% | O14: 0 | P14: 0 | Q14: 0.00% | R14: 0.00% | S14: 0 | T14: 0 | U14: 0 | V14: 0 | W14: 0 | X14: 0 | Y14: 1235 | Z14: 0 | AA14: 0 | AB14: 0.00% | AC14: 0.00% | AD14: - | AE14: - | AF14: - | AG14: 6
A15: 7 | B15: Viên Uống Giảm Gãy Rụng và Đen Tóc HB Black Hair Healthy Beauty [11] | C15: Đang diễn ra | D15: Quảng cáo Sản phẩm | E15: 5519393895 | F15: Đối tượng Tự động | G15: Tối ưu Sáng tạo đã được tắt | H15: Giá thầu Thủ công | I15: Tìm kiếm | J15: 45821 | K15: Không giới hạn | L15: 981 | M15: 19 | N15: 1.94% | O15: 2 | P15: 1 | Q15: 10.53% | R15: 5.26% | S15: 37328.79 | T15: 74657.57 | U15: 2 | V15: 1 | W15: 1246000 | X15: 856000 | Y15: 74658 | Z15: 16.69 | AA15: 11.47 | AB15: 5.99% | AC15: 8.72% | AD15: - | AE15: - | AF15: - | AG15: 6
A16: 8 | B16: Khẩu Trang Y Tế Kháng Khuẩn HB Medical Mask Cao Cấp Healthy Beauty 1 Hộp 50 cái [5] | C16: Đang diễn ra | D16: Quảng cáo Sản phẩm | E16: 5158911395 | F16: - | G16: Tối ưu Sáng tạo đã được bật | H16: Tối đa Doanh thu Tùy chỉnh ROAS | I16: Tất cả | J16: 45831 | K16: Không giới hạn | L16: 778 | M16: 24 | N16: 3.08% | O16: 0 | P16: 0 | Q16: 0.00% | R16: 0.00% | S16: 0 | T16: 0 | U16: 0 | V16: 0 | W16: 0 | X16: 0 | Y16: 45848 | Z16: 0 | AA16: 0 | AB16: 0.00% | AC16: 0.00% | AD16: - | AE16: - | AF16: - | AG16: 6
A17: 9 | B17: Viên Uống Giảm Gãy Rụng và Đen Tóc HB Black Hair Healthy Beauty [10] | C17: Đang diễn ra | D17: Quảng cáo Sản phẩm | E17: 5519393895 | F17: Đối tượng Tự động | G17: Tối ưu Sáng tạo đã được bật | H17: Giá thầu Thủ công | I17: Tìm kiếm | J17: 45821 | K17: Không giới hạn | L17: 506 | M17: 7 | N17: 1.38% | O17: 0 | P17: 0 | Q17: 0.00% | R17: 0.00% | S17: 0 | T17: 0 | U17: 0 | V17: 0 | W17: 0 | X17: 0 | Y17: 27852 | Z17: 0 | AA17: 0 | AB17: 0.00% | AC17: 0.00% | AD17: - | AE17: - | AF17: - | AG17: 6
A18: 10 | B18: Viên Uống Giảm Gãy Rụng và Đen Tóc HB Black Hair Healthy Beauty [9] | C18: Tạm dừng | D18: Quảng cáo Sản phẩm | E18: 5519393895 | F18: - | G18: Tối ưu Sáng tạo đã được bật | H18: Tối đa Doanh thu Tùy chỉnh ROAS | I18: Tất cả | J18: 45813 | K18: Không giới hạn | L18: 14810 | M18: 70 | N18: 0.47% | O18: 0 | P18: 0 | Q18: 0.00% | R18: 0.00% | S18: 0 | T18: 0 | U18: 0 | V18: 0 | W18: 0 | X18: 0 | Y18: 338540 | Z18: 0 | AA18: 0 | AB18: 0.00% | AC18: 0.00% | AD18: - | AE18: - | AF18: - | AG18: 6
A19: 11 | B19: Viên uống giúp tái tạo và nuôi dưỡng mô sụn - HB Glucollagen 7 in 1 [3] | C19: Tạm dừng | D19: Quảng cáo Sản phẩm | E19: 25666719442 | F19: - | G19: Tối ưu Sáng tạo đã được tắt | H19: Tối đa Doanh thu Tùy chỉnh ROAS | I19: Tất cả | J19: 45660 | K19: Không giới hạn | L19: 14075 | M19: 72 | N19: 0.51% | O19: 2 | P19: 0 | Q19: 2.78% | R19: 0.00% | S19: 204723.2 | T19: 0 | U19: 2 | V19: 0 | W19: 676000 | X19: 0 | Y19: 409446 | Z19: 1.65 | AA19: 0 | AB19: 60.57% | AC19: 0.00% | AD19: - | AE19: - | AF19: - | AG19: 6
A20: 12 | B20: Viên uống giúp tái tạo và nuôi dưỡng mô sụn - HB Glucollagen 7 in 1 [5] | C20: Tạm dừng | D20: Quảng cáo Sản phẩm | E20: 25666719442 | F20: Đối tượng Tự động | G20: Tối ưu Sáng tạo đã được tắt | H20: Giá thầu Thủ công | I20: Tìm kiếm | J20: 45821 | K20: Không giới hạn | L20: 1755 | M20: 38 | N20: 2.17% | O20: 6 | P20: 6 | Q20: 15.79% | R20: 15.79% | S20: 26858.19 | T20: 26858.19 | U20: 7 | V20: 7 | W20: 5265000 | X20: 5265000 | Y20: 161149 | Z20: 32.67 | AA20: 32.67 | AB20: 3.06% | AC20: 3.06% | AD20: - | AE20: - | AF20: - | AG20: 6
A21: 13 | B21: Viên uống giúp tái tạo và nuôi dưỡng mô sụn - HB Glucollagen 7 in 1 [4] | C21: Tạm dừng | D21: Quảng cáo Sản phẩm | E21: 25666719442 | F21: Đối tượng Tự động | G21: Tối ưu Sáng tạo đã được tắt | H21: Giá thầu Thủ công | I21: Tìm kiếm | J21: 45821 | K21: Không giới hạn | L21: 276 | M21: 3 | N21: 1.09% | O21: 0 | P21: 0 | Q21: 0.00% | R21: 0.00% | S21: 0 | T21: 0 | U21: 0 | V21: 0 | W21: 0 | X21: 0 | Y21: 15000 | Z21: 0 | AA21: 0 | AB21: 0.00% | AC21: 0.00% | AD21: - | AE21: - | AF21: - | AG21: 6
A22: 14 | B22: Viên uống HB Glucosamine 3 in 1 60 viên - 200 viên [6] | C22: Tạm dừng | D22: Quảng cáo Sản phẩm | E22: 24867481840 | F22: - | G22: Tối ưu Sáng tạo đã được bật | H22: Tối đa Doanh thu Tối ưu ROAS bởi Hệ thống | I22: Tất cả | J22: 45812 | K22: Không giới hạn | L22: 46 | M22: 0 | N22: 0.00% | O22: 0 | P22: 0 | Q22: 0.00% | R22: 0.00% | S22: 0 | T22: 0 | U22: 0 | V22: 0 | W22: 0 | X22: 0 | Y22: 0 | Z22: 0 | AA22: 0 | AB22: 0.00% | AC22: 0.00% | AD22: - | AE22: - | AF22: - | AG22: 6
A23: 15 | B23: Viên uống HB Arginmilk Plus 60 viên [4] | C23: Tạm dừng | D23: Quảng cáo Sản phẩm | E23: 24867724627 | F23: Đối tượng Tự động | G23: Tối ưu Sáng tạo đã được tắt | H23: Giá thầu Thủ công | I23: Tìm kiếm | J23: 45785 | K23: Không giới hạn | L23: 10 | M23: 1 | N23: 10.00% | O23: 0 | P23: 0 | Q23: 0.00% | R23: 0.00% | S23: 0 | T23: 0 | U23: 0 | V23: 0 | W23: 0 | X23: 0 | Y23: 19623 | Z23: 0 | AA23: 0 | AB23: 0.00% | AC23: 0.00% | AD23: - | AE23: - | AF23: - | AG23: 6
A24: 16 | B24: Khẩu Trang Y Tế Kháng Khuẩn HB Medical Mask Cao Cấp Healthy Beauty 1 Hộp 50 cái [4] | C24: Tạm dừng | D24: Quảng cáo Sản phẩm | E24: 5158911395 | F24: Đối tượng Tự động | G24: Tối ưu Sáng tạo đã được tắt | H24: Giá thầu Thủ công | I24: Tìm kiếm | J24: 45785 | K24: Không giới hạn | L24: 8 | M24: 0 | N24: 0.00% | O24: 0 | P24: 0 | Q24: 0.00% | R24: 0.00% | S24: 0 | T24: 0 | U24: 0 | V24: 0 | W24: 0 | X24: 0 | Y24: 0 | Z24: 0 | AA24: 0 | AB24: 0.00% | AC24: 0.00% | AD24: - | AE24: - | AF24: - | AG24: 6
A25: 17 | B25: Viên Uống Healthy Beauty Omega 3,6,9 Từ Dầu Hạt Lanh 100 Viên & 200 Viên [3] | C25: Tạm dừng | D25: Quảng cáo Sản phẩm | E25: 3127515400 | F25: - | G25: Tối ưu Sáng tạo đã được tắt | H25: Tối đa Doanh thu Tối ưu ROAS bởi Hệ thống | I25: Tất cả | J25: 45729 | K25: Không giới hạn | L25: 5 | M25: 0 | N25: 0.00% | O25: 0 | P25: 0 | Q25: 0.00% | R25: 0.00% | S25: 0 | T25: 0 | U25: 0 | V25: 0 | W25: 0 | X25: 0 | Y25: 0 | Z25: 0 | AA25: 0 | AB25: 0.00% | AC25: 0.00% | AD25: - | AE25: - | AF25: - | AG25: 6
A26: 18 | B26: Viên Uống Giảm Gãy Rụng và Đen Tóc HB Black Hair Healthy Beauty [8] | C26: Tạm dừng | D26: Quảng cáo Sản phẩm | E26: 5519393895 | F26: Đối tượng Tự động | G26: Tối ưu Sáng tạo đã được bật | H26: Giá thầu Thủ công | I26: Tìm kiếm | J26: 45785 | K26: Không giới hạn | L26: 1 | M26: 0 | N26: 0.00% | O26: 0 | P26: 0 | Q26: 0.00% | R26: 0.00% | S26: 0 | T26: 0 | U26: 0 | V26: 0 | W26: 0 | X26: 0 | Y26: 0 | Z26: 0 | AA26: 0 | AB26: 0.00% | AC26: 0.00% | AD26: - | AE26: - | AF26: - | AG26: 6
A32: Báo cáo quảng cáo trả theo CPC - Shopee Việt Nam
A33: Tên đăng nhập | B33: healthybeauty.officialstore
A34: Tên gian hàng | B34: DƯỢC PHẨM HEALTHY BEAUTY
A35: Mã Người bán | B35: 227240948
A36: Thời gian tạo báo cáo | B36: 45869.374
A37: Khoảng thời gian | B37: 01/07/2025 - 31/07/2025
W38: =SUM(W40:W51) -> 24481980 | Y38: =SUM(Y40:Y51) -> 5821526
A39: Thứ tự | B39: Tên quảng cáo | C39: Trạng thái | D39: Loại quảng cáo | E39: Mã sản phẩm | F39: Cài đặt Đối tượng | G39: Nội dung quảng cáo | H39: Phương thức đấu thầu | I39: Vị trí | J39: Ngày bắt đầu | K39: Ngày kết thúc | L39: Số lượt xem | M39: Số lượt click | N39: Tỷ Lệ Click | O39: Lượt chuyển đổi | P39: Lượt chuyển đổi trực tiếp | Q39: Tỷ lệ chuyển đổi | R39: Tỷ lệ chuyển đổi trực tiếp | S39: Chi phí cho mỗi lượt chuyển đổi | T39: Chi phí cho mỗi lượt chuyển đổi trực tiếp | U39: Sản phẩm đã bán | V39: Sản phẩm đã bán trực tiếp | W39: GMV | X39: GMV trực tiếp | Y39: Chi phí | Z39: ROAS | AA39: ROAS trực tiếp | AB39: ACOS | AC39: ACOS trực tiếp | AD39: Lượt xem Sản phẩm | AE39: Lượt clicks Sản phẩm | AF39: Tỷ lệ Click Sản phẩm | AG39: THÁNG
A40: 1 | B40: Auto shop | C40: Đang diễn ra | D40: Quảng cáo Shop | E40: - | F40: - | G40: Mặc định | H40: Giá thầu Tự động | I40: - | J40: 45784 | K40: Không giới hạn | L40: 7366 | M40: 1250 | N40: 16.97% | O40: 9 | P40: 9 | Q40: 0.72% | R40: 0.72% | S40: 118048.2 | T40: 118048.2 | U40: 10 | V40: 10 | W40: 5927080 | X40: 5927080 | Y40: 1062433 | Z40: 5.58 | AA40: 5.58 | AB40: 17.93% | AC40: 17.93% | AD40: 22518 | AE40: 141 | AF40: 0.63% | AG40: 7
A41: 2 | B41: Viên uống giúp tái tạo và nuôi dưỡng mô sụn - HB Glucollagen 7 in 1 [6] | C41: Đang diễn ra | D41: Quảng cáo Sản phẩm | E41: 25666719442 | F41: - | G41: Tối ưu Sáng tạo đã được tắt | H41: Tối đa Doanh thu Tùy chỉnh ROAS | I41: Tất cả | J41: 45833 | K41: Không giới hạn | L41: 27652 | M41: 273 | N41: 0.99% | O41: 8 | P41: 7 | Q41: 2.93% | R41: 2.56% | S41: 262211.7 | T41: 299670.5 | U41: 10 | V41: 9 | W41: 8911000 | X41: 8055000 | Y41: 2097693 | Z41: 4.25 | AA41: 3.84 | AB41: 23.54% | AC41: 26.04% | AD41: - | AE41: - | AF41: - | AG41: 7
A42: 3 | B42: Viên Uống Giúp Chống Nắng Trắng Da Mờ Nám HB GLUTA WHITE + [4] | C42: Đang diễn ra | D42: Quảng cáo Sản phẩm | E42: 8782633181 | F42: - | G42: Tối ưu Sáng tạo đã được tắt | H42: Tối đa Doanh thu Tùy chỉnh ROAS | I42: Tất cả | J42: 45660 | K42: Không giới hạn | L42: 9775 | M42: 51 | N42: 0.52% | O42: 1 | P42: 1 | Q42: 1.96% | R42: 1.96% | S42: 209051 | T42: 209051 | U42: 1 | V42: 1 | W42: 1485000 | X42: 1485000 | Y42: 209051 | Z42: 45664 | AA42: 45664 | AB42: 14.08% | AC42: 14.08% | AD42: - | AE42: - | AF42: - | AG42: 7
A43: 4 | B43: Viên Uống Giảm Gãy Rụng và Đen Tóc HB Black Hair Healthy Beauty [12] | C43: Đang diễn ra | D43: Quảng cáo Sản phẩm | E43: 5519393895 | F43: - | G43: Tối ưu Sáng tạo đã được tắt | H43: Tối đa Doanh thu Tùy chỉnh ROAS | I43: Tất cả | J43: 45849 | K43: Không giới hạn | L43: 9274 | M43: 131 | N43: 1.41% | O43: 3 | P43: 3 | Q43: 2.29% | R43: 2.29% | S43: 271978.8 | T43: 271978.8 | U43: 3 | V43: 3 | W43: 1693900 | X43: 1693900 | Y43: 815937 | Z43: 45871 | AA43: 45871 | AB43: 48.17% | AC43: 48.17% | AD43: - | AE43: - | AF43: - | AG43: 7
A44: 5 | B44: Viên uống HB GutCare (30 - 60 viên) hỗ trợ giảm triệu chứng đau khớp | C44: Đang diễn ra | D44: Quảng cáo Sản phẩm | E44: 22657955668 | F44: - | G44: Tối ưu Sáng tạo đã được tắt | H44: Tối đa Doanh thu Tùy chỉnh ROAS | I44: Tất cả | J44: 45660 | K44: Không giới hạn | L44: 7631 | M44: 68 | N44: 0.89% | O44: 3 | P44: 2 | Q44: 4.41% | R44: 2.94% | S44: 148959.1 | T44: 223438.7 | U44: 4 | V44: 2 | W44: 1904000 | X44: 1272000 | Y44: 446877 | Z44: 4.26 | AA44: 2.85 | AB44: 23.47% | AC44: 35.13% | AD44: - | AE44: - | AF44: - | AG44: 7
A45: 6 | B45: Khẩu Trang Y Tế Kháng Khuẩn HB Medical Mask Cao Cấp Healthy Beauty 1 Hộp 50 cái [5] | C45: Đang diễn ra | D45: Quảng cáo Sản phẩm | E45: 5158911395 | F45: - | G45: Tối ưu Sáng tạo đã được bật | H45: Tối đa Doanh thu Tùy chỉnh ROAS | I45: Tất cả | J45: 45831 | K45: Không giới hạn | L45: 4167 | M45: 92 | N45: 2.21% | O45: 8 | P45: 8 | Q45: 8.70% | R45: 8.70% | S45: 39475.6 | T45: 39475.6 | U45: 17 | V45: 17 | W45: 1020000 | X45: 1020000 | Y45: 315805 | Z45: 3.23 | AA45: 3.23 | AB45: 30.96% | AC45: 30.96% | AD45: - | AE45: - | AF45: - | AG45: 7
...

Sheet DS Shoppe (đã xác nhận)
A1: Ngày | B1: Tổng doanh số (VND) | C1: Tổng số đơn hàng | D1: Doanh số trên mỗi đơn hàng | E1: Tổng số lượt xem sản phẩm | F1: Số lượt truy cập | G1: Tỷ lệ chuyển đổi (theo số đơn được đặt) | H1: Đơn đã hủy | I1: Doanh số đơn hủy | J1: Đơn đã hoàn trả / hoàn tiền | K1: Doanh số các đơn Trả hàng/Hoàn tiền | L1: số người mua | M1: số người mua mới | N1: số người mua hiện tại | O1: số người mua tiềm năng | P1: Tỉ lệ quay lại của người mua | Q1: THÁNG
A2: 01-08-2025-31-08-2025 | B2: 47713575 | C2: 67 | D2: 712142.91 | E2: 1821 | F2: 2951 | G2: 0.0368 | H2: 8 | I2: 6452176 | J2: 0 | K2: 0 | L2: 58 | M2: 38 | N2: 20 | O2: 150 | P2: 0.1552
A4: Ngày | B4: Tổng doanh số (VND) | C4: Tổng số đơn hàng | D4: Doanh số trên mỗi đơn hàng | E4: Tổng số lượt xem sản phẩm | F4: Số lượt truy cập | G4: Tỷ lệ chuyển đổi (theo Đơn đã xác nhận) | H4: Đơn đã hủy | I4: Doanh số đơn hủy | J4: Đơn đã hoàn trả / hoàn tiền | K4: Doanh số các đơn Trả hàng/Hoàn tiền | L4: số người mua | M4: số người mua mới | N4: số người mua hiện tại | O4: số người mua tiềm năng | P4: Tỉ lệ quay lại của người mua | Q4: THÁNG
A5: 45870 | B5: 93299 | C5: 1 | D5: 93299 | E5: 49 | F5: 63 | G5: 0.0204 | H5: 0 | I5: 0 | J5: 0 | K5: 0 | L5: 1 | M5: 1 | N5: 0 | O5: 6 | P5: 0 | Q5: =MONTH(A5) -> 8
A6: 45871 | B6: 1651000 | C6: 2 | D6: 825500 | E6: 39 | F6: 87 | G6: 0.0513 | H6: 0 | I6: 0 | J6: 0 | K6: 0 | L6: 2 | M6: 1 | N6: 1 | O6: 4 | P6: 0 | Q6: =MONTH(A6) -> 8
A7: 45872 | B7: 0 | C7: 0 | D7: 0 | E7: 42 | F7: 95 | G7: 0 | H7: 0 | I7: 0 | J7: 0 | K7: 0 | L7: 0 | M7: 0 | N7: 0 | O7: 11 | P7: 0 | Q7: =MONTH(A7) -> 8
A8: 45873 | B8: 1852550 | C8: 2 | D8: 926275 | E8: 53 | F8: 82 | G8: 0.0377 | H8: 1 | I8: 1045800 | J8: 0 | K8: 0 | L8: 2 | M8: 0 | N8: 2 | O8: 4 | P8: 0 | Q8: =MONTH(A8) -> 8
A9: 45874 | B9: 0 | C9: 0 | D9: 0 | E9: 39 | F9: 82 | G9: 0 | H9: 0 | I9: 0 | J9: 0 | K9: 0 | L9: 0 | M9: 0 | N9: 0 | O9: 4 | P9: 0 | Q9: =MONTH(A9) -> 8
A10: 45875 | B10: 1136080 | C10: 2 | D10: 568040 | E10: 33 | F10: 65 | G10: 0.0606 | H10: 0 | I10: 0 | J10: 0 | K10: 0 | L10: 2 | M10: 1 | N10: 1 | O10: 5 | P10: 0 | Q10: =MONTH(A10) -> 8
A11: 45876 | B11: 0 | C11: 0 | D11: 0 | E11: 53 | F11: 94 | G11: 0 | H11: 0 | I11: 0 | J11: 0 | K11: 0 | L11: 0 | M11: 0 | N11: 0 | O11: 9 | P11: 0 | Q11: =MONTH(A11) -> 8
A12: 45877 | B12: 10797560 | C12: 13 | D12: 830581.54 | E12: 80 | F12: 112 | G12: 0.1625 | H12: 1 | I12: 727600 | J12: 0 | K12: 0 | L12: 12 | M12: 5 | N12: 7 | O12: 4 | P12: 0.0833 | Q12: =MONTH(A12) -> 8
A13: 45878 | B13: 914800 | C13: 2 | D13: 457400 | E13: 53 | F13: 146 | G13: 0.0377 | H13: 0 | I13: 0 | J13: 0 | K13: 0 | L13: 2 | M13: 1 | N13: 1 | O13: 4 | P13: 0 | Q13: =MONTH(A13) -> 8
A14: 45879 | B14: 461980 | C14: 3 | D14: 153993.33 | E14: 46 | F14: 40 | G14: 0.0652 | H14: 0 | I14: 0 | J14: 0 | K14: 0 | L14: 2 | M14: 2 | N14: 0 | O14: 7 | P14: 0.5 | Q14: =MONTH(A14) -> 8
A15: 45880 | B15: 2380250 | C15: 3 | D15: 793416.67 | E15: 47 | F15: 44 | G15: 0.0638 | H15: 1 | I15: 695200 | J15: 0 | K15: 0 | L15: 3 | M15: 3 | N15: 0 | O15: 11 | P15: 0 | Q15: =MONTH(A15) -> 8
A16: 45881 | B16: 704000 | C16: 1 | D16: 704000 | E16: 37 | F16: 42 | G16: 0.027 | H16: 0 | I16: 0 | J16: 0 | K16: 0 | L16: 1 | M16: 1 | N16: 0 | O16: 12 | P16: 0 | Q16: =MONTH(A16) -> 8
... A35: 45900 | B35: 0 | C35: 0 | D35: 0 | E35: 60 | F35: 111 | G35: 0 | H35: 0 | I35: 0 | J35: 0 | K35: 0 | L35: 0 | M35: 0 | N35: 0 | O35: 4 | P35: 0 | Q35: =MONTH(A35) -> 8
A38: Ngày | B38: Tổng doanh số (VND) | C38: Tổng số đơn hàng | D38: Doanh số trên mỗi đơn hàng | E38: Tổng số lượt xem sản phẩm | F38: Số lượt truy cập | G38: Tỷ lệ chuyển đổi (theo số đơn được đặt) | H38: Đơn đã hủy | I38: Doanh số đơn hủy | J38: Đơn đã hoàn trả / hoàn tiền | K38: Doanh số các đơn Trả hàng/Hoàn tiền | L38: số người mua | M38: số người mua mới | N38: số người mua hiện tại | O38: số người mua tiềm năng | P38: Tỉ lệ quay lại của người mua
A39: 01-09-2025-25-09-2025 | B39: =SUM(B42:B75) -> 127157603 | C39: =SUM(C42:C75) -> 191 | D39: =SUM(D42:D75) -> 42415707 | E39: =SUM(E42:E75) -> 6393 | F39: =SUM(F42:F75) -> 36834 | G39: =SUM(G42:G75) -> 2.2677 | H39: =SUM(H42:H75) -> 53 | I39: =SUM(I42:I75) -> 42182229 | ... P39: =SUM(P42:P75) -> 5.5304
A41: Ngày | B41: Tổng doanh số (VND) | C41: Tổng số đơn hàng | D41: Doanh số trên mỗi đơn hàng | E41: Lượt nhấp vào sản phẩm | F41: Số lượt truy cập | G41: Tỷ lệ chuyển đổi đơn hàng | H41: Đơn đã hủy | I41: Doanh số đơn hủy | J41: Đơn đã hoàn trả / hoàn tiền | K41: Doanh số các đơn Trả hàng/Hoàn tiền | L41: số người mua | M41: số người mua mới | N41: số người mua hiện tại | O41: số người mua tiềm năng | P41: Tỉ lệ quay lại của người mua | Q41: THÁNG
A42: 45901 | B42: =R42-I42 -> 4281650 | C42: 5 | D42: 900230 | E42: 107 | F42: 140 | G42: 0.0467 | H42: 1 | I42: 219500 | J42: 0 | K42: 0 | L42: 5 | M42: 3 | N42: 2 | O42: 14 | P42: 0 | Q42: =MONTH(A42) -> 9 | R42: 4501150 | S42: 5
A43: 45902 | B43: =R43-I43 -> 1780500 | C43: 3 | D43: 593500 | E43: 79 | F43: 122 | G43: 0.038 | H43: 0 | I43: 0 | J43: 0 | K43: 0 | L43: 3 | M43: 2 | N43: 1 | O43: 10 | P43: 0 | Q43: =MONTH(A43) -> 9 | R43: 1780500 | S43: 3
A44: 45903 | B44: =R44-I44 -> 0 | C44: 1 | D44: 827200 | E44: 100 | F44: 131 | G44: 0.01 | H44: 1 | I44: 827200 | J44: 0 | K44: 0 | L44: 1 | M44: 1 | N44: 0 | O44: 9 | P44: 0 | Q44: =MONTH(A44) -> 9 | R44: 827200 | S44: 1
A45: 45904 | B45: =R45-I45 -> 1194720 | C45: 3 | D45: 398240 | E45: 128 | F45: 183 | G45: 0.0234 | H45: 0 | I45: 0 | J45: 0 | K45: 0 | L45: 3 | M45: 2 | N45: 1 | O45: 18 | P45: 0 | Q45: =MONTH(A45) -> 9 | R45: 1194720 | S45: 3
A46: 45905 | B46: =R46-I46 -> 1583200 | C46: 3 | D46: 620924 | E46: 152 | F46: 156 | G46: 0.0197 | H46: 1 | I46: 279572 | J46: 0 | K46: 0 | L46: 3 | M46: 2 | N46: 1 | O46: 9 | P46: 0 | Q46: =MONTH(A46) -> 9 | R46: 1862772 | S46: 3
A47: 45906 | B47: =R47-I47 -> 277743 | C47: 1 | D47: 277743 | E47: 120 | F47: 166 | G47: 0.0083 | H47: 0 | I47: 0 | J47: 0 | K47: 0 | L47: 1 | M47: 0 | N47: 1 | O47: 13 | P47: 0 | Q47: =MONTH(A47) -> 9 | R47: 277743 | S47: 1
A48: 45907 | B48: =R48-I48 -> 245064 | C48: 2 | D48: 381531.5 | E48: 132 | F48: 154 | G48: 0.0152 | H48: 1 | I48: 517999 | J48: 0 | K48: 0 | L48: 2 | M48: 1 | N48: 1 | O48: 13 | P48: 0 | Q48: =MONTH(A48) -> 9 | R48: 763063 | S48: 2
A49: 45908 | B49: =R49-I49 -> 0 | C49: 1 | D49: 883575 | E49: 145 | F49: 245 | G49: 0.0069 | H49: 1 | I49: 883575 | J49: 0 | K49: 0 | L49: 1 | M49: 0 | N49: 1 | O49: 12 | P49: 0 | Q49: =MONTH(A49) -> 9 | R49: 883575 | S49: 1
A50: 45909 | B50: =R50-I50 -> 11305684 | C50: 17 | D50: 729506.71 | E50: 183 | F50: 645 | G50: 0.0929 | H50: 1 | I50: 1095930 | J50: 1 | K50: 0 | L50: 16 | M50: 8 | N50: 8 | O50: 15 | P50: 0.0625 | Q50: =MONTH(A50) -> 9 | R50: 12401614 | S50: 17
A51: 45910 | B51: =R51-I51 -> 4824140 | C51: 7 | D51: 689162.86 | E51: 107 | F51: 110 | G51: 0.0654 | H51: 0 | I51: 0 | J51: 0 | K51: 0 | L51: 6 | M51: 6 | N51: 0 | O51: 9 | P51: 0.1667 | Q51: =MONTH(A51) -> 9 | R51: 4824140 | S51: 7
A52: 45911 | B52: =R52-I52 -> 2116600 | C52: 2 | D52: 1058300 | E52: 114 | F52: 227 | G52: 0.0175 | H52: 0 | I52: 0 | J52: 0 | K52: 0 | L52: 2 | M52: 1 | N52: 1 | O52: 12 | P52: 0 | Q52: =MONTH(A52) -> 9 | R52: 2116600 | S52: 2
A53: 45912 | B53: =R53-I53 -> 2514900 | C53: 2 | D53: 1257450 | E53: 72 | F53: 154 | G53: 0.0278 | H53: 0 | I53: 0 | J53: 1 | K53: 0 | L53: 2 | M53: 1 | N53: 1 | O53: 9 | P53: 0 | Q53: =MONTH(A53) -> 9 | R53: 2514900 | S53: 2
... A71: 45930 | B71: =R71-I71 -> 1333911 | C71: 2 | D71: 666955.5 | E71: 149 | F71: 232 | G71: 0.0134 | H71: 0 | I71: 0 | J71: 0 | K71: 0 | L71: 2 | M71: 1 | N71: 1 | O71: 18 | P71: 0 | Q71: =MONTH(A71) -> 9 | R71: 1333911 | S71: 2
Q72: =MONTH(A72) -> 12
A73: Ngày | B73: Tổng doanh số (VND) | C73: Tổng số đơn hàng | D73: Doanh số trên mỗi đơn hàng | E73: Tổng số lượt xem sản phẩm | F73: Số lượt truy cập | G73: Tỷ lệ chuyển đổi (theo số đơn được đặt) | H73: Đơn đã hủy | I73: Doanh số đơn hủy | J73: Đơn đã hoàn trả / hoàn tiền | K73: Doanh số các đơn Trả hàng/Hoàn tiền | L73: số người mua | M73: số người mua mới | N73: số người mua hiện tại | O73: số người mua tiềm năng | P73: Tỉ lệ quay lại của người mua
B74: =SUM(B77:B110) -> 58260779 | C74: =SUM(C77:C110) -> 83 | D74: =SUM(D77:D110) -> 21985057 | E74: =SUM(E77:E110) -> 2896 | F74: =SUM(F77:F110) -> 20505 | G74: =SUM(G77:G110) -> 1.3479 | H74: =SUM(H77:H110) -> 37 | I74: =SUM(I77:I110) -> 28442973 | ... P74: =SUM(P77:P110) -> 3.8012
A76: Ngày | B76: Tổng doanh số (VND) | C76: Tổng số đơn hàng | D76: Doanh số trên mỗi đơn hàng | E76: Lượt nhấp vào sản phẩm | F76: Số lượt truy cập | G76: Tỷ lệ chuyển đổi đơn hàng | H76: Đơn đã hủy | I76: Doanh số đơn hủy | J76: Đơn đã hoàn trả / hoàn tiền | K76: Doanh số các đơn Trả hàng/Hoàn tiền | L76: số người mua | M76: số người mua mới | N76: số người mua hiện tại | O76: số người mua tiềm năng | P76: Tỉ lệ quay lại của người mua | Q76: THÁNG
A77: 45931 | B77: =R77-I77 -> 852390 | C77: =S77-H77 -> 1 | D77: 823095 | E77: 83 | F77: 154 | G77: 0.0241 | H77: 1 | I77: 793800 | J77: 0 | K77: 0 | L77: 2 | M77: 1 | N77: 1 | O77: 13 | P77: 0 | Q77: =MONTH(A77) -> 10 | R77: 1646190 | S77: 2
A78: 45932 | B78: =R78-I78 -> 3072476 | C78: =S78-H78 -> 2 | D78: 1547012.8 | E78: 33 | F78: 131 | G78: 0.1212 | H78: 2 | I78: 3115575 | J78: 0 | K78: 0 | L78: 3 | M78: 3 | N78: 0 | O78: 4 | P78: 0.3333 | Q78: =MONTH(A78) -> 10 | R78: 6188051 | S78: 4
A79: 45933 | B79: =R79-I79 -> 702240 | C79: =S79-H79 -> 1 | D79: 702240 | E79: 34 | F79: 164 | G79: 0.0294 | H79: 0 | I79: 0 | J79: 0 | K79: 0 | L79: 1 | M79: 1 | N79: 0 | O79: 4 | P79: 0 | Q79: =MONTH(A79) -> 10 | R79: 702240 | S79: 1
A80: 45934 | B80: =R80-I80 -> 1430817 | C80: =S80-H80 -> 2 | D80: 715408.5 | E80: 48 | F80: 84 | G80: 0.0417 | H80: 0 | I80: 0 | J80: 0 | K80: 0 | L80: 2 | M80: 1 | N80: 1 | O80: 5 | P80: 0 | Q80: =MONTH(A80) -> 10 | R80: 1430817 | S80: 2
...

Sheet BC TỔNG HỢP THÁNG
B2: BÁO CÁO DOANH SỐ KÊNH ONLINE
B3: Ngày báo cáo: | C3: 45901 | E3: =NOW() -> 46082.138
B5: THÁNG | C5: TARGET | D5: DOANH SỐ | E5: CHI PHÍ ADS | F5: CHÊNH LỆCH | G5: % DS/TARGET | H5: % CHI PHÍ/TARGET
B6: 1 | D6: =SUMIF('DS Shoppe (đã xác nhận)'!Q:Q,B6,'DS Shoppe (đã xác nhận)'!B:B)+SUMIF(LAZADA!S:S,B6,LAZADA!B:B)+SUMIF(WEB!N:N,B6,WEB!C:C)+SUMIF(ZALO!M:M,B6,ZALO!C:C)+SUMIF(FANPAGE!M:M,B6,FANPAGE!C:C) -> 100518008
B7: 2 | D7: =SUMIF('DS Shoppe (đã xác nhận)'!Q:Q,B7,'DS Shoppe (đã xác nhận)'!B:B)+SUMIF(LAZADA!S:S,B7,LAZADA!B:B)+SUMIF(WEB!N:N,B7,WEB!C:C)+SUMIF(ZALO!M:M,B7,ZALO!C:C)+SUMIF(FANPAGE!M:M,B7,FANPAGE!C:C) -> 83066785
B8: 3 | D8: =SUMIF('DS Shoppe (đã xác nhận)'!Q:Q,B8,'DS Shoppe (đã xác nhận)'!B:B)+SUMIF(LAZADA!S:S,B8,LAZADA!B:B)+SUMIF(WEB!N:N,B8,WEB!C:C)+SUMIF(ZALO!M:M,B8,ZALO!C:C)+SUMIF(FANPAGE!M:M,B8,FANPAGE!C:C) -> 0
B9: 4 | D9: =SUMIF('DS Shoppe (đã xác nhận)'!Q:Q,B9,'DS Shoppe (đã xác nhận)'!B:B)+SUMIF(LAZADA!S:S,B9,LAZADA!B:B)+SUMIF(WEB!N:N,B9,WEB!C:C)+SUMIF(ZALO!M:M,B9,ZALO!C:C)+SUMIF(FANPAGE!M:M,B9,FANPAGE!C:C) -> 0
B10: 5 | D10: =SUMIF('DS Shoppe (đã xác nhận)'!Q:Q,B10,'DS Shoppe (đã xác nhận)'!B:B)+SUMIF(LAZADA!S:S,B10,LAZADA!B:B)+SUMIF(WEB!N:N,B10,WEB!C:C)+SUMIF(ZALO!M:M,B10,ZALO!C:C)+SUMIF(FANPAGE!M:M,B10,FANPAGE!C:C) -> 0
B11: 6 | D11: =SUMIF('DS Shoppe (đã xác nhận)'!Q:Q,B11,'DS Shoppe (đã xác nhận)'!B:B)+SUMIF(LAZADA!S:S,B11,LAZADA!B:B)+SUMIF(WEB!N:N,B11,WEB!C:C)+SUMIF(ZALO!M:M,B11,ZALO!C:C)+SUMIF(FANPAGE!M:M,B11,FANPAGE!C:C) -> 0
B12: 7 | D12: =SUMIF('DS Shoppe (đã xác nhận)'!Q:Q,B12,'DS Shoppe (đã xác nhận)'!B:B)+SUMIF(LAZADA!S:S,B12,LAZADA!B:B)+SUMIF(WEB!N:N,B12,WEB!C:C)+SUMIF(ZALO!M:M,B12,ZALO!C:C)+SUMIF(FANPAGE!M:M,B12,FANPAGE!C:C) -> 0
B13: 8 | C13: 100000000 | D13: =SUMIF('DS Shoppe (đã xác nhận)'!Q:Q,B13,'DS Shoppe (đã xác nhận)'!B:B)+SUMIF(LAZADA!S:S,B13,LAZADA!B:B)+SUMIF(WEB!N:N,B13,WEB!C:C)+SUMIF(ZALO!M:M,B13,ZALO!C:C)+SUMIF(FANPAGE!M:M,B13,FANPAGE!C:C) -> 61588731 | E13: =SUMIFS('ADS SHOPEE'!Y:Y,'ADS SHOPEE'!AG:AG,B13) -> 3368692 | F13: =D13-C13 -> -38411269 | G13: =D13/C13-1 -> -0.38411269 | H13: =E13/D13 -> 0.054696565
B14: 9 | C14: 143182134 | D14: =SUMIF('DS Shoppe (đã xác nhận)'!Q:Q,B14,'DS Shoppe (đã xác nhận)'!B:B)+SUMIF(LAZADA!S:S,B14,LAZADA!B:B)+SUMIF(WEB!N:N,B14,WEB!C:C)+SUMIF(ZALO!M:M,B14,ZALO!C:C)+SUMIF(FANPAGE!M:M,B14,FANPAGE!C:C) -> 91815640 | E14: =SUMIFS('ADS SHOPEE'!Y:Y,'ADS SHOPEE'!AG:AG,B14) -> 10589865 | F14: =D14-C14 -> -51366494 | G14: =D14/C14-1 -> -0.35874933 | H14: =E14/D14 -> 0.11533836
B15: 10 | D15: =SUMIF('DS Shoppe (đã xác nhận)'!Q:Q,B15,'DS Shoppe (đã xác nhận)'!B:B)+SUMIF(LAZADA!S:S,B15,LAZADA!B:B)+SUMIF(WEB!N:N,B15,WEB!C:C)+SUMIF(ZALO!M:M,B15,ZALO!C:C)+SUMIF(FANPAGE!M:M,B15,FANPAGE!C:C) -> 95224742 | E15: =SUMIFS('ADS SHOPEE'!Y:Y,'ADS SHOPEE'!AG:AG,B15) -> 4947883 | F15: =D15-C15 -> 95224742 | G15: =D15/C15-1 -> #DIV/0! | H15: =E15/D15 -> 0.051960057
B16: 11 | D16: =SUMIF('DS Shoppe (đã xác nhận)'!Q:Q,B16,'DS Shoppe (đã xác nhận)'!B:B)+SUMIF(LAZADA!S:S,B16,LAZADA!B:B)+SUMIF(WEB!N:N,B16,WEB!C:C)+SUMIF(ZALO!M:M,B16,ZALO!C:C)+SUMIF(FANPAGE!M:M,B16,FANPAGE!C:C) -> 81368273 | E16: =SUMIFS('ADS SHOPEE'!Y:Y,'ADS SHOPEE'!AG:AG,B16) -> 10659302 | F16: =D16-C16 -> 81368273 | G16: =D16/C16-1 -> #DIV/0! | H16: =E16/D16 -> 0.13100072
B17: 12 | D17: =SUMIF('DS Shoppe (đã xác nhận)'!Q:Q,B17,'DS Shoppe (đã xác nhận)'!B:B)+SUMIF(LAZADA!S:S,B17,LAZADA!B:B)+SUMIF(WEB!N:N,B17,WEB!C:C)+SUMIF(ZALO!M:M,B17,ZALO!C:C)+SUMIF(FANPAGE!M:M,B17,FANPAGE!C:C) -> 89895107 | E17: =SUMIFS('ADS SHOPEE'!Y:Y,'ADS SHOPEE'!AG:AG,B17) -> 8399114 | F17: =D17-C17 -> 89895107 | G17: =D17/C17-1 -> #DIV/0! | H17: =E17/D17 -> 0.093432382
