Workbook

Sheet Action Plan
F2: MARKETING MONTHLY SALES REVENUE | L2: Person in charge
B4: Start Date | D4: Due Date | F4: Person Responsible | L4: Quantity | M4: =SUM(M6:M14) -> 20 | N4: =SUM(N6:N14) -> 8 | O4: =N4/M4 -> 0.4 | P4: Ratio
B5: 45748 | C5: 25 | D5: 45777 | L5: Position | M5: Estimated | N5: Actual | O5: Remaining | P5: Person #1 | Q5: Person #2 | R5: Person #3 | S5: Person #4
C6: =NETWORKDAYS.INTL(B5,D5,11) -> 26 | L6: Senior Manager | M6: 1 | N6: 1 | O6: =N6-M6 -> 0 | P6: 1
F7: Sales Revenue (VND) | L7: Junior Executive | M7: 0 | N7: 0 | O7: =N7-M7 -> 0
F8: 500000000 | L8: Digital Marketer | M8: 1 | N8: 1 | O8: =N8-M8 -> 0 | P8: 1
L9: E-Com Operations | M9: 1 | N9: 1 | O9: =N9-M9 -> 0 | P9: 1
F10: Expense Budget (VND) | L10: Media Editor | M10: 1 | N10: 0 | O10: =N10-M10 -> -1
D11: 0.4 | F11: =$D$11*F8 -> 200000000 | L11: Graphic Designer | M11: 1 | N11: 1 | O11: =N11-M11 -> 0 | P11: 1
L12: Fresher AI Officer | M12: 1 | N12: 0 | O12: =N12-M12 -> -1
L13: Sale | M13: 4 | N13: 4 | O13: =N13-M13 -> 0 | P13: 0.35 | Q13: 0.3 | R13: 0.25 | S13: 0.2
A14: I | B14: Expense Budget | L14: Trainee | M14: 10 | N14: 0 | O14: =N14-M14 -> -10
B15: Direct Marketing Platform | C15: Ratio | D15: Expense Budget
B16: TOTAL | C16: =SUM(C17:C24) -> 0.85 | D16: =SUM(D17:D24) -> 170000000
B17: FACEBOOK | C17: 0.05 | D17: =$F$11*C17 -> 10000000
B18: LANDING PAGE | C18: 0.3 | D18: =$F$11*C18 -> 60000000
B19: WEBSITE | C19: 0.05 | D19: =$F$11*C19 -> 10000000
B20: TIKTOK SHOP | C20: 0.1 | D20: =$F$11*C20 -> 20000000
B21: SHOPEE | C21: 0.05 | D21: =$F$11*C21 -> 10000000
B22: ZALO | C22: 0.2 | D22: =$F$11*C22 -> 40000000
B23: BOOKING | C23: 0.05 | D23: =$F$11*C23 -> 10000000
B24: BRANDING | C24: 0.05 | D24: =$F$11*C24 -> 10000000
A26: II | B26: Sales Revenue | E26: DIGITAL | H26: SALE
A27: 45293 | B27: Direct Marketing Platform | C27: Ratio | D27: Sales Revenue | E27: Key Platform | F27: New Customers Data Lead | G27: Actual Customers Data | H27: Key Platform | I27: Sales Estimated | J27: Daily Sales Actual | K27: Estimated Conversiton Rate
B28: TOTAL | C28: =SUM(C29:C34) -> 1 | D28: =SUM(D29:D34) -> 500000000 | E28: =COUNTIF(E29:E34,"TRUE") -> 6 | F28: =SUM(F29:F34) -> 1680 | G28: =SUM(G29:G34) -> 67.2 | H28: =COUNTIF(H29:H34,"TRUE") -> 6 | I28: =SUM(I29:I34) -> 500000000 | J28: =SUM(J29:J34) -> 20000000 | K28: =SUM(K29:K34)/6 -> 0.45833333
B29: FACEBOOK | C29: 0.1 | D29: =$F$8*$C29 -> 50000000 | E29: TRUE | F29: =ROUNDUP((I29/$C$37)/K29,0) -> 313 | G29: =F29/$C$5 -> 12.52 | H29: TRUE | I29: =$F$8*$C29 -> 50000000 | J29: =I29/$C$5 -> 2000000 | K29: 0.2
B30: LANDING PAGE | C30: 0.5 | D30: =$F$8*$C30 -> 250000000 | E30: TRUE | F30: =ROUNDUP((I30/$C$37)/K30,0) -> 348 | G30: =F30/$C$5 -> 13.92 | H30: TRUE | I30: =$F$8*$C30 -> 250000000 | J30: =I30/$C$5 -> 10000000 | K30: 0.9
B31: WEBSITE | C31: 0.1 | D31: =$F$8*$C31 -> 50000000 | E31: TRUE | F31: =ROUNDUP((I31/$C$37)/K31,0) -> 125 | G31: =F31/$C$5 -> 5 | H31: TRUE | I31: =$F$8*$C31 -> 50000000 | J31: =I31/$C$5 -> 2000000 | K31: 0.5
B32: TIKTOK SHOP | C32: 0.1 | D32: =$F$8*$C32 -> 50000000 | E32: TRUE | F32: =ROUNDUP((I32/$C$37)/K32,0) -> 90 | G32: =F32/$C$5 -> 3.6 | H32: TRUE | I32: =$F$8*$C32 -> 50000000 | J32: =I32/$C$5 -> 2000000 | K32: 0.7
B33: SHOPEE | C33: 0.1 | D33: =$F$8*$C33 -> 50000000 | E33: TRUE | F33: =ROUNDUP((I33/$C$37)/K33,0) -> 179 | G33: =F33/$C$5 -> 7.16 | H33: TRUE | I33: =$F$8*$C33 -> 50000000 | J33: =I33/$C$5 -> 2000000 | K33: 0.35
B34: ZALO | C34: 0.1 | D34: =$F$8*$C34 -> 50000000 | E34: TRUE | F34: =ROUNDUP((I34/$C$37)/K34,0) -> 625 | G34: =F34/$C$5 -> 25 | H34: TRUE | I34: =$F$8*$C34 -> 50000000 | J34: =I34/$C$5 -> 2000000 | K34: 0.1
H35: Existing Customers | I35: =J35*$C$5 -> 624.60962 | J35: =(((I34/$C$37)/$C$5)/K34) -> 24.984385 | K35: =J35*K34 -> 2.4984385
C36: ARPU
C37: =$E$39 -> 800500 | D37: đ/ Order/ Customer | E37: PRODUCT | H37: BUNDLE COMBO
A38: 45324 | B38: Products | C38: Ratio | D38: Sales Revenue | E38: Retail Price | F38: Sales Volume | G38: Daily Unit Sales | H38: Combo Price | I38: Sales Volume | J38: Daily Unit Sales | K38: Daily Sales Estimated
B39: TOTAL | C39: =SUM(C40:C47) -> 1 | D39: =SUM(D40:D47) -> 500000000 | E39: =(SUM(E40:E47))/8 -> 800500 | F39: =SUM(F40:F47) -> 571 | G39: =SUM(G40:G47) -> 26 | I39: =SUM(I40:I47) -> 505 | J39: =SUM(J40:J47) -> 23 | K39: =SUM(K40:K47) -> 20000000
B40: BONE & JOINT HEALTH | C40: 0.35 | D40: =$I$28*$C40 -> 175000000 | E40: 945000 | F40: =ROUNDUP(D40/E40,0) -> 186 | G40: =ROUNDUP(F40/$C$5,0) -> 8 | H40: 1000000 | I40: =ROUNDUP(D40/H40,0) -> 175 | J40: =ROUNDUP(I40/$C$5,0) -> 7 | K40: =D40/$C$5 -> 7000000
B41: LIVER, DIGESTION, ALLERGIES | C41: 0.3 | D41: =$I$28*$C41 -> 150000000 | E41: 1260000 | F41: =ROUNDUP(D41/E41,0) -> 120 | G41: =ROUNDUP(F41/$C$5,0) -> 5 | H41: 990000 | I41: =ROUNDUP(D41/H41,0) -> 152 | J41: =ROUNDUP(I41/$C$5,0) -> 7 | K41: =D41/$C$5 -> 6000000
B42: BRAIN & EYE HEALTH | C42: 0.1 | D42: =$I$28*$C42 -> 50000000 | E42: 586000 | F42: =ROUNDUP(D42/E42,0) -> 86 | G42: =ROUNDUP(F42/$C$5,0) -> 4 | H42: 1000000 | I42: =ROUNDUP(D42/H42,0) -> 50 | J42: =ROUNDUP(I42/$C$5,0) -> 2 | K42: =D42/$C$5 -> 2000000
B43: CARDIOVASCULAR HEALTH | C43: 0.08 | D43: =$I$28*$C43 -> 40000000 | E43: 630000 | F43: =ROUNDUP(D43/E43,0) -> 64 | G43: =ROUNDUP(F43/$C$5,0) -> 3 | H43: 990000 | I43: =ROUNDUP(D43/H43,0) -> 41 | J43: =ROUNDUP(I43/$C$5,0) -> 2 | K43: =D43/$C$5 -> 1600000
...

Sheet Dashboard
B2: MARKETING MONTHLY SALES REVENUE DASHBOARD | L2: ='Action Plan'!L2 -> Person in charge
B4: Start Date | D4: Due Date | F4: Person Responsible | L4: ='Action Plan'!L4 -> Quantity | M4: ='Action Plan'!M4 -> 20 | N4: ='Action Plan'!N4 -> 8 | O4: ='Action Plan'!O4 -> 0.4 | P4: ='Action Plan'!P4 -> Ratio
B5: 45748 | C5: ='Action Plan'!C5 -> 25 | D5: 45777 | F5: Mr/Ms: | L5: Position | M5: Estimated | N5: Actual | O5: Remaining | P5: ='Action Plan'!P5 -> Person #1 | Q5: ='Action Plan'!Q5 -> Person #2 | R5: ='Action Plan'!R5 -> Person #3 | S5: ='Action Plan'!S5 -> Person #4
C6: ='Action Plan'!C6 -> 26 | L6: ='Action Plan'!L6 -> Senior Manager | M6: ='Action Plan'!M6 -> 1 | N6: ='Action Plan'!N6 -> 1 | O6: ='Action Plan'!O6 -> 0 | P6: ='Action Plan'!P6 -> 1 | Q6: ='Action Plan'!Q6 -> 0 | R6: ='Action Plan'!R6 -> 0 | S6: ='Action Plan'!S6 -> 0
B7: Sales Revenue (VND) | F7: Actual Sales | J7: Remaining | K7: Ratio | L7: ='Action Plan'!L7 -> Junior Executive | M7: ='Action Plan'!M7 -> 0 | N7: ='Action Plan'!N7 -> 0 | O7: ='Action Plan'!O7 -> 0 | P7: ='Action Plan'!P7 -> 0 | Q7: ='Action Plan'!Q7 -> 0 | R7: ='Action Plan'!R7 -> 0 | S7: ='Action Plan'!S7 -> 0
B8: ='Action Plan'!F8 -> 500000000 | F8: 400000000 | J8: =F8-B8 -> -100000000 | K8: =F8/B8 -> 0.8 | L8: ='Action Plan'!L8 -> Digital Marketer | M8: 1 | N8: ='Action Plan'!N8 -> 1 | O8: ='Action Plan'!O8 -> 0 | P8: ='Action Plan'!P8 -> 1 | Q8: ='Action Plan'!Q8 -> 0 | R8: ='Action Plan'!R8 -> 0 | S8: ='Action Plan'!S8 -> 0
B9: ='Action Plan'!D11 -> 0.4 | F9: =F11/F8 -> 0.11425 | L9: ='Action Plan'!L9 -> E-Com Operations | M9: ='Action Plan'!M9 -> 1 | N9: ='Action Plan'!N9 -> 1 | O9: ='Action Plan'!O9 -> 0 | P9: ='Action Plan'!P9 -> 1 | Q9: ='Action Plan'!Q9 -> 0 | R9: ='Action Plan'!R9 -> 0 | S9: ='Action Plan'!S9 -> 0
B10: Expense Budget (VND) | F10: Actual Budget | J10: Remaining | K10: Ratio | L10: ='Action Plan'!L10 -> Media Editor | M10: ='Action Plan'!M10 -> 1 | N10: ='Action Plan'!N10 -> 0 | O10: ='Action Plan'!O10 -> -1 | P10: ='Action Plan'!P10 -> 0 | Q10: ='Action Plan'!Q10 -> 0 | R10: ='Action Plan'!R10 -> 0 | S10: ='Action Plan'!S10 -> 0
B11: ='Action Plan'!F11 -> 200000000 | F11: =F15 -> 45700000 | J11: =B11-F11 -> 154300000 | K11: =F11/B11 -> 0.2285 | L11: ='Action Plan'!L11 -> Graphic Designer | M11: ='Action Plan'!M11 -> 1 | N11: ='Action Plan'!N11 -> 1 | O11: ='Action Plan'!O11 -> 0 | P11: ='Action Plan'!P11 -> 1 | Q11: ='Action Plan'!Q11 -> 0 | R11: ='Action Plan'!R11 -> 0 | S11: ='Action Plan'!S11 -> 0
L12: ='Action Plan'!L12 -> Fresher AI Officer | M12: ='Action Plan'!M12 -> 1 | N12: ='Action Plan'!N12 -> 0 | O12: ='Action Plan'!O12 -> -1 | P12: ='Action Plan'!P12 -> 0 | Q12: ='Action Plan'!Q12 -> 0 | R12: ='Action Plan'!R12 -> 0 | S12: ='Action Plan'!S12 -> 0
A13: I | B13: Expense Budget | L13: ='Action Plan'!L13 -> Sale | M13: ='Action Plan'!M13 -> 4 | N13: ='Action Plan'!N13 -> 4 | O13: ='Action Plan'!O13 -> 0 | P13: ='Action Plan'!P13 -> 0.35 | Q13: ='Action Plan'!Q13 -> 0.3 | R13: ='Action Plan'!R13 -> 0.25 | S13: ='Action Plan'!S13 -> 0.2
B14: Direct Marketing Platform | C14: Expense Ratio | D14: Actual Ratio | E14: Expense Budget | F14: Actual Budget | G14: Remaining | H14: Remaining Ratio | L14: ='Action Plan'!L14 -> Trainee | M14: ='Action Plan'!M14 -> 10 | N14: ='Action Plan'!N14 -> 0 | O14: ='Action Plan'!O14 -> -10 | P14: ='Action Plan'!P14 -> 0 | Q14: ='Action Plan'!Q14 -> 0 | R14: ='Action Plan'!R14 -> 0 | S14: ='Action Plan'!S14 -> 0
B15: TOTAL | C15: =SUM(C16:C23) -> 0.85 | D15: =SUM(D16:D23) -> 1 | E15: =SUM(E16:E23) -> 170000000 | F15: =SUM(F16:F23) -> 45700000 | G15: =SUM(G16:G23) -> 124300000 | H15: =SUM(H16:H23) -> 0.15
B16: ='Action Plan'!B17 -> FACEBOOK | C16: ='Action Plan'!C17 -> 0.05 | D16: =F16/$F$15 -> 0.0065645514 | E16: =$B$11*C16 -> 10000000 | F16: ='Digital Marketer #1'!E9+'E-Com Operations'!E9 -> 300000 | G16: =E16-F16 -> 9700000 | H16: =D16-C16 -> -0.043435449
B17: ='Action Plan'!B18 -> LANDING PAGE | C17: ='Action Plan'!C18 -> 0.3 | D17: =F17/$F$15 -> 0.32822757 | E17: =$B$11*C17 -> 60000000 | F17: ='Digital Marketer #1'!E15+'E-Com Operations'!E15 -> 15000000 | G17: =E17-F17 -> 45000000 | H17: =D17-C17 -> 0.028227571
B18: ='Action Plan'!B19 -> WEBSITE | C18: ='Action Plan'!C19 -> 0.05 | D18: =F18/$F$15 -> 0.078774617 | E18: =$B$11*C18 -> 10000000 | F18: ='Digital Marketer #1'!E21+'E-Com Operations'!E21 -> 3600000 | G18: =E18-F18 -> 6400000 | H18: =D18-C18 -> 0.028774617
B19: ='Action Plan'!B20 -> TIKTOK SHOP | C19: ='Action Plan'!C20 -> 0.1 | D19: =F19/$F$15 -> 0.15973742 | E19: =$B$11*C19 -> 20000000 | F19: ='Digital Marketer #1'!E24+'E-Com Operations'!E24 -> 7300000 | G19: =E19-F19 -> 12700000 | H19: =D19-C19 -> 0.059737418
B20: ='Action Plan'!B21 -> SHOPEE | C20: ='Action Plan'!C21 -> 0.05 | D20: =F20/$F$15 -> 0.13347921 | E20: =$B$11*C20 -> 10000000 | F20: ='Digital Marketer #1'!E25+'E-Com Operations'!E25 -> 6100000 | G20: =E20-F20 -> 3900000 | H20: =D20-C20 -> 0.083479212
B21: ='Action Plan'!B22 -> ZALO | C21: ='Action Plan'!C22 -> 0.2 | D21: =F21/$F$15 -> 0.060175055 | E21: =$B$11*C21 -> 40000000 | F21: ='Digital Marketer #1'!E26+'E-Com Operations'!E26 -> 2750000 | G21: =E21-F21 -> 37250000 | H21: =D21-C21 -> -0.13982495
B22: ='Action Plan'!B23 -> BOOKING | C22: ='Action Plan'!C23 -> 0.05 | D22: =F22/$F$15 -> 0.1345733 | E22: =$B$11*C22 -> 10000000 | F22: ='Digital Marketer #1'!E27+'E-Com Operations'!E27 -> 6150000 | G22: =E22-F22 -> 3850000 | H22: =D22-C22 -> 0.084573304
B23: ='Action Plan'!B24 -> BRANDING | C23: ='Action Plan'!C24 -> 0.05 | D23: =F23/$F$15 -> 0.098468271 | E23: =$B$11*C23 -> 10000000 | F23: ='Digital Marketer #1'!E28+'E-Com Operations'!E28 -> 4500000 | G23: =E23-F23 -> 5500000 | H23: =D23-C23 -> 0.048468271
A24: II | B24: Sales Revenue | J24: SALE | O24: SALE + DIGITAL | S24: DIGITAL
A25: 2.1 | B25: Direct Marketing Platform | C25: Expense Ratio | D25: Actual Ratio | E25: Sales Revenue | F25: Actual Sales | G25: Remaining | H25: Remaining Ratio | I25: Expense Sales | J25: Key Platform | K25: Sales Estimated | L25: Actual Sales | M25: Remaining | N25: Ratio | O25: Estimated Conversiton Rate | P25: Daily Conversiton Rate | Q25: Remaining | R25: Ratio | S25: Key Platform | T25: Data Lead | U25: Daily Data | V25: Remaining | W25: Ratio
B26: TOTAL | C26: =SUM(C27:C32) -> 1 | D26: =SUM(D27:D32) -> 1 | E26: =SUM(E27:E32) -> 500000000 | F26: =SUM(F27:F32) -> 373050000 | G26: =SUM(G27:G32) -> -126950000 | H26: =SUM(H27:H32) -> 1 | I26: =SUM(I27:I32) -> -3077662500 | J26: =COUNTIF(J27:J32,"TRUE") -> 6 | K26: =SUM(K27:K32) -> 500000000 | L26: =SUM(L27:L32) -> 373050000 | M26: =SUM(M27:M32) -> -126950000 | N26: =SUM(N27:N32) -> 1 | O26: =SUM(O27:O32) -> 2.75 | P26: =SUM(P27:P32) -> 9.690121 | Q26: =SUM(Q27:Q32) -> 6.940121 | R26: =SUM(R27:R32) -> 1 | S26: =COUNTIF(S27:S32,"TRUE") -> 6 | T26: =SUM(T27:T32) -> 1680 | U26: =SUM(U27:U32) -> 1335 | V26: =SUM(V27:V32) -> -345 | W26: =SUM(W27:W32) -> 1
B27: ='Action Plan'!B29 -> FACEBOOK | C27: ='Action Plan'!C29 -> 0.1 | D27: =F27/$F$26 -> 0.13697896 | E27: =$B$8*$C27 -> 50000000 | F27: ='Digital Marketer #1'!E49+'E-Com Operations'!E49 -> 51100000 | G27: =F27-E27 -> 1100000 | H27: =G27/$G$26 -> -0.0086648287 | I27: =F27/(TODAY()-$B$5)*($D$5-TODAY()) -> -421575000 | J27: TRUE | K27: =$B$8*$C27 -> 50000000 | L27: =F27 -> 51100000 | M27: =L27-K27 -> 1100000 | N27: =M27/$M$26 -> -0.0086648287 | O27: ='Action Plan'!K29 -> 0.2 | P27: =AVERAGE(F83,F117) -> 2.1876478 | Q27: =P27-O27 -> 1.9876478 | R27: =Q27/$Q$26 -> 0.2863996 | S27: TRUE | T27: =ROUNDUP((K27/$C$34)/O27,0) -> 313 | U27: =F54 -> 372 | V27: =U27-T27 -> 59 | W27: =V27/$V$26 -> -0.17101449
B28: ='Action Plan'!B30 -> LANDING PAGE | C28: ='Action Plan'!C30 -> 0.5 | D28: =F28/$F$26 -> 0.13697896 | E28: =$B$8*$C28 -> 250000000 | F28: ='Digital Marketer #1'!E50+'E-Com Operations'!E50 -> 51100000 | G28: =F28-E28 -> -198900000 | H28: =G28/$G$26 -> 1.5667586 | I28: =F28/(TODAY()-$B$5)*($D$5-TODAY()) -> -421575000 | J28: TRUE | K28: =$B$8*$C28 -> 250000000 | L28: =F28 -> 51100000 | M28: =L28-K28 -> -198900000 | N28: =M28/$M$26 -> 1.5667586 | O28: ='Action Plan'!K30 -> 0.9 | P28: =AVERAGE(F84,F118) -> 1.7017204 | Q28: =P28-O28 -> 0.80172043 | R28: =Q28/$Q$26 -> 0.11551966 | S28: TRUE | T28: =ROUNDUP((K28/$C$34)/O28,0) -> 348 | U28: =F55 -> 341 | V28: =U28-T28 -> -7 | W28: =V28/$V$26 -> 0.020289855
B29: ='Action Plan'!B31 -> WEBSITE | C29: ='Action Plan'!C31 -> 0.1 | D29: =F29/$F$26 -> 0.12893714 | E29: =$B$8*$C29 -> 50000000 | F29: ='Digital Marketer #1'!E51+'E-Com Operations'!E51 -> 48100000 | G29: =F29-E29 -> -1900000 | H29: =G29/$G$26 -> 0.014966522 | I29: =F29/(TODAY()-$B$5)*($D$5-TODAY()) -> -396825000 | J29: TRUE | K29: =$B$8*$C29 -> 50000000 | L29: =F29 -> 48100000 | M29: =L29-K29 -> -1900000 | N29: =M29/$M$26 -> 0.014966522 | O29: ='Action Plan'!K31 -> 0.5 | P29: =AVERAGE(F85,F119) -> 1.0083333 | Q29: =P29-O29 -> 0.50833333 | R29: =Q29/$Q$26 -> 0.073245601 | S29: TRUE | T29: =ROUNDUP((K29/$C$34)/O29,0) -> 125 | U29: =F59 -> 310 | V29: =U29-T29 -> 185 | W29: =V29/$V$26 -> -0.53623188
B30: ='Action Plan'!B32 -> TIKTOK SHOP | C30: ='Action Plan'!C32 -> 0.1 | D30: =F30/$F$26 -> 0.2482241 | E30: =$B$8*$C30 -> 50000000 | F30: ='Digital Marketer #1'!E52+'E-Com Operations'!E52 -> 92600000 | G30: =F30-E30 -> 42600000 | H30: =G30/$G$26 -> -0.33556518 | I30: =F30/(TODAY()-$B$5)*($D$5-TODAY()) -> -763950000 | J30: TRUE | K30: =$B$8*$C30 -> 50000000 | L30: =F30 -> 92600000 | M30: =L30-K30 -> 42600000 | N30: =M30/$M$26 -> -0.33556518 | O30: ='Action Plan'!K32 -> 0.7 | P30: =AVERAGE(F86,F120) -> 1.4866129 | Q30: =P30-O30 -> 0.7866129 | R30: =Q30/$Q$26 -> 0.11334282 | S30: TRUE | T30: =ROUNDUP((K30/$C$34)/O30,0) -> 90 | U30: =F60 -> 188 | V30: =U30-T30 -> 98 | W30: =V30/$V$26 -> -0.28405797
B31: ='Action Plan'!B33 -> SHOPEE | C31: ='Action Plan'!C33 -> 0.1 | D31: =F31/$F$26 -> 0.25224501 | E31: =$B$8*$C31 -> 50000000 | F31: ='Digital Marketer #1'!E53+'E-Com Operations'!E53 -> 94100000 | G31: =F31-E31 -> 44100000 | H31: =G31/$G$26 -> -0.34738086 | I31: =F31/(TODAY()-$B$5)*($D$5-TODAY()) -> -776325000 | J31: TRUE | K31: =$B$8*$C31 -> 50000000 | L31: =F31 -> 94100000 | M31: =L31-K31 -> 44100000 | N31: =M31/$M$26 -> -0.34738086 | O31: ='Action Plan'!K33 -> 0.35 | P31: =AVERAGE(F87,F121) -> 1.165 | Q31: =P31-O31 -> 0.815 | R31: =Q31/$Q$26 -> 0.11743311 | S31: TRUE | T31: =ROUNDUP((K31/$C$34)/O31,0) -> 179 | U31: =F61 -> 62 | V31: =U31-T31 -> -117 | W31: =V31/$V$26 -> 0.33913043
B32: ='Action Plan'!B34 -> ZALO | C32: ='Action Plan'!C34 -> 0.1 | D32: =F32/$F$26 -> 0.09663584 | E32: =$B$8*$C32 -> 50000000 | F32: ='Digital Marketer #1'!E54+'E-Com Operations'!E54 -> 36050000 | G32: =F32-E32 -> -13950000 | H32: =G32/$G$26 -> 0.10988578 | I32: =F32/(TODAY()-$B$5)*($D$5-TODAY()) -> -297412500 | J32: TRUE | K32: =$B$8*$C32 -> 50000000 | L32: =F32 -> 36050000 | M32: =L32-K32 -> -13950000 | N32: =M32/$M$26 -> 0.10988578 | O32: ='Action Plan'!K34 -> 0.1 | P32: =AVERAGE(F88,F122) -> 2.1408065 | Q32: =P32-O32 -> 2.0408065 | R32: =Q32/$Q$26 -> 0.2940592 | S32: TRUE | T32: =ROUNDUP((K32/$C$34)/O32,0) -> 625 | U32: =F62 -> 62 | V32: =U32-T32 -> -563 | W32: =V32/$V$26 -> 1.6318841
C33: Expense | D33: Actual
B34: ARPU | C34: ='Action Plan'!C37 -> 800500 | D34: =F26/(W26*P26) -> 38497971 | I34: PRODUCT | S34: BUNDLE COMBO
A35: 45324 | B35: Products | C35: Expense Ratio | D35: Actual Ratio | E35: Total Sales | F35: Total Actual Sales | G35: Remaining | H35: Remaining Ratio | I35: Retail Price | J35: Push Sale | K35: Quantity | L35: Actual Quantity | M35: Remaining | N35: Ratio | O35: Daily Quantity | P35: Actual Daily Quantity | Q35: Remaining | R35: Ratio | S35: Combo Price | T35: Push Sale | U35: Quantity | V35: Actual Quantity | W35: Remaining | X35: Ratio | Y35: Daily Quantity | Z35: Actual Daily Quantity | AA35: Remaining | AB35: Ratio | AC35: Sales KPI | AD35: Actual Sales | AE35: Remaining | AF35: Ratio
B36: TOTAL | C36: =SUM(C37:C44) -> 1 | D36: =SUM(D37:D44) -> 2.2 | E36: =SUM(E37:E44) -> 500000000 | F36: ='Sale #1'!F50+'Sale #2'!F50+'Sale #3'!F50+'Sale #4'!F50 -> 331700000 | G36: =SUM(G37:G44) -> -168300000 | H36: =SUM(H37:H44) -> 1 | J36: =COUNTIF(J37:J44,"TRUE") -> 8 | K36: =SUM(K37:K44) -> 571 | L36: =SUM(L37:L44) -> 1705 | M36: =SUM(M37:M44) -> 1134 | N36: =SUM(N37:N44) -> 1 | O36: =SUM(O37:O44) -> 26 | P36: =SUM(P37:P44) -> 0 | Q36: =SUM(Q37:Q44) -> -26 | R36: =SUM(R37:R44) -> 1 | T36: =COUNTIF(T37:T42,"TRUE") -> 6 | U36: =SUM(U37:U44) -> 505 | V36: =SUM(V37:V44) -> 2015 | W36: =SUM(W37:W44) -> 1510 | X36: =SUM(X37:X44) -> 1 | Y36: =SUM(Y37:Y44) -> 23 | Z36: =SUM(Z37:Z44) -> 0 | AA36: =SUM(AA37:AA44) -> -23 | AB36: =SUM(AB37:AB44) -> 1 | ... AF36: =SUM(AF37:AF44) -> 0.15754234
B37: ='Action Plan'!B40 -> BONE & JOINT HEALTH | C37: ='Action Plan'!C40 -> 0.35 | D37: 0.6 | E37: =$B$8*$C37 -> 175000000 | F37: ='Sale #1'!F51+'Sale #2'!F51+'Sale #3'!F51+'Sale #4'!F51 -> 40300000 | G37: =F37-E37 -> -134700000 | H37: =G37/$G$36 -> 0.80035651 | I37: ='Action Plan'!E40 -> 945000 | J37: TRUE | K37: =IF(ROUNDUP(E37/I37,0)<>0,ROUNDUP(E37/I37,0),0) -> 186 | L37: ='Sale #1'!D51+'Sale #2'!D51+'Sale #3'!D51+'Sale #4'!D51 -> 93 | M37: =L37-K37 -> -93 | N37: =M37/$M$36 -> -0.082010582 | O37: =ROUNDUP(K37/$C$5,0) -> 8 | P37: ='Sale #1'!J51+'Sale #2'!J51+'Sale #3'!J51+'Sale #4'!J51 -> 0 | Q37: =P37-O37 -> -8 | R37: =Q37/$Q$36 -> 0.30769231 | S37: ='Action Plan'!H40 -> 1000000 | T37: TRUE | U37: =ROUNDUP(E37/S37,0) -> 175 | V37: ='Sale #1'!E51+'Sale #2'!E51+'Sale #3'!E51+'Sale #4'!E51 -> 155 | W37: =V37-U37 -> -20 | X37: =W37/$W$36 -> -0.013245033 | Y37: =ROUNDUP(U37/$C$5,0) -> 7 | Z37: ='Sale #1'!K51+'Sale #2'!K51+'Sale #3'!K51+'Sale #4'!K51 -> 0 | AA37: =Z37-Y37 -> -7 | AB37: =AA37/$AA$36 -> 0.30434783 | AC37: =E37/$C$5 -> 7000000 | AD37: ='Sale #1'!L51+'Sale #2'!L51+'Sale #3'!L51+'Sale #4'!L51 -> 0 | AE37: =AD37-AC37 -> -7000000 | AF37: =AE37/$G$26 -> 0.055139819
B38: ='Action Plan'!B41 -> LIVER, DIGESTION, ALLERGIES | C38: ='Action Plan'!C41 -> 0.3 | D38: 0.2 | E38: =$B$8*$C38 -> 150000000 | F38: ='Sale #1'!F52+'Sale #2'!F52+'Sale #3'!F52+'Sale #4'!F52 -> 40300000 | G38: =F38-E38 -> -109700000 | H38: =G38/$G$36 -> 0.65181224 | I38: ='Action Plan'!E41 -> 1260000 | J38: TRUE | K38: =IF(ROUNDUP(E38/I38,0)<>0,ROUNDUP(E38/I38,0),0) -> 120 | L38: ='Sale #1'!D52+'Sale #2'!D52+'Sale #3'!D52+'Sale #4'!D52 -> 217 | M38: =L38-K38 -> 97 | N38: =M38/$M$36 -> 0.085537919 | O38: =ROUNDUP(K38/$C$5,0) -> 5 | P38: ='Sale #1'!J52+'Sale #2'!J52+'Sale #3'!J52+'Sale #4'!J52 -> 0 | Q38: =P38-O38 -> -5 | R38: =Q38/$Q$36 -> 0.19230769 | S38: ='Action Plan'!H41 -> 990000 | T38: TRUE | U38: =ROUNDUP(E38/S38,0) -> 152 | V38: ='Sale #1'!E52+'Sale #2'!E52+'Sale #3'!E52+'Sale #4'!E52 -> 217 | W38: =V38-U38 -> 65 | X38: =W38/$W$36 -> 0.043046358 | Y38: =ROUNDUP(U38/$C$5,0) -> 7 | Z38: ='Sale #1'!K52+'Sale #2'!K52+'Sale #3'!K52+'Sale #4'!K52 -> 0 | AA38: =Z38-Y38 -> -7 | AB38: =AA38/$AA$36 -> 0.30434783 | AC38: =E38/$C$5 -> 6000000 | AD38: ='Sale #1'!L52+'Sale #2'!L52+'Sale #3'!L52+'Sale #4'!L52 -> 0 | AE38: =AD38-AC38 -> -6000000 | AF38: =AE38/$G$26 -> 0.047262702
B39: ='Action Plan'!B42 -> BRAIN & EYE HEALTH | C39: ='Action Plan'!C42 -> 0.1 | D39: 0.5 | E39: =$B$8*$C39 -> 50000000 | F39: ='Sale #1'!F53+'Sale #2'!F53+'Sale #3'!F53+'Sale #4'!F53 -> 40300000 | G39: =F39-E39 -> -9700000 | H39: =G39/$G$36 -> 0.057635175 | I39: ='Action Plan'!E42 -> 586000 | J39: TRUE | K39: =IF(ROUNDUP(E39/I39,0)<>0,ROUNDUP(E39/I39,0),0) -> 86 | L39: ='Sale #1'!D53+'Sale #2'!D53+'Sale #3'!D53+'Sale #4'!D53 -> 155 | M39: =L39-K39 -> 69 | N39: =M39/$M$36 -> 0.060846561 | O39: =ROUNDUP(K39/$C$5,0) -> 4 | P39: ='Sale #1'!J53+'Sale #2'!J53+'Sale #3'!J53+'Sale #4'!J53 -> 0 | Q39: =P39-O39 -> -4 | R39: =Q39/$Q$36 -> 0.15384615 | S39: ='Action Plan'!H42 -> 1000000 | T39: TRUE | U39: =ROUNDUP(E39/S39,0) -> 50 | V39: ='Sale #1'!E53+'Sale #2'!E53+'Sale #3'!E53+'Sale #4'!E53 -> 217 | W39: =V39-U39 -> 167 | X39: =W39/$W$36 -> 0.11059603 | Y39: =ROUNDUP(U39/$C$5,0) -> 2 | Z39: ='Sale #1'!K53+'Sale #2'!K53+'Sale #3'!K53+'Sale #4'!K53 -> 0 | AA39: =Z39-Y39 -> -2 | AB39: =AA39/$AA$36 -> 0.086956522 | AC39: =E39/$C$5 -> 2000000 | AD39: ='Sale #1'!L53+'Sale #2'!L53+'Sale #3'!L53+'Sale #4'!L53 -> 0 | AE39: =AD39-AC39 -> -2000000 | AF39: =AE39/$G$26 -> 0.015754234
B40: ='Action Plan'!B43 -> CARDIOVASCULAR HEALTH | C40: ='Action Plan'!C43 -> 0.08 | D40: 0.2 | E40: =$B$8*$C40 -> 40000000 | F40: ='Sale #1'!F54+'Sale #2'!F54+'Sale #3'!F54+'Sale #4'!F54 -> 40300000 | G40: =F40-E40 -> 300000 | H40: =G40/$G$36 -> -0.0017825312 | I40: ='Action Plan'!E43 -> 630000 | J40: TRUE | K40: =IF(ROUNDUP(E40/I40,0)<>0,ROUNDUP(E40/I40,0),0) -> 64 | L40: ='Sale #1'!D54+'Sale #2'!D54+'Sale #3'!D54+'Sale #4'!D54 -> 217 | M40: =L40-K40 -> 153 | N40: =M40/$M$36 -> 0.13492063 | O40: =ROUNDUP(K40/$C$5,0) -> 3 | P40: ='Sale #1'!J54+'Sale #2'!J54+'Sale #3'!J54+'Sale #4'!J54 -> 0 | Q40: =P40-O40 -> -3 | R40: =Q40/$Q$36 -> 0.11538462 | S40: ='Action Plan'!H43 -> 990000 | T40: TRUE | U40: =ROUNDUP(E40/S40,0) -> 41 | V40: ='Sale #1'!E54+'Sale #2'!E54+'Sale #3'!E54+'Sale #4'!E54 -> 341 | W40: =V40-U40 -> 300 | X40: =W40/$W$36 -> 0.1986755 | Y40: =ROUNDUP(U40/$C$5,0) -> 2 | Z40: ='Sale #1'!K54+'Sale #2'!K54+'Sale #3'!K54+'Sale #4'!K54 -> 0 | AA40: =Z40-Y40 -> -2 | AB40: =AA40/$AA$36 -> 0.086956522 | AC40: =E40/$C$5 -> 1600000 | AD40: ='Sale #1'!L54+'Sale #2'!L54+'Sale #3'!L54+'Sale #4'!L54 -> 0 | AE40: =AD40-AC40 -> -1600000 | AF40: =AE40/$G$26 -> 0.012603387
B41: ='Action Plan'!B44 -> SKIN, HAIR, AND WEIGHT MANAGEMENT | C41: ='Action Plan'!C44 -> 0.08 | D41: 0.1 | E41: =$B$8*$C41 -> 40000000 | F41: ='Sale #1'!F55+'Sale #2'!F55+'Sale #3'!F55+'Sale #4'!F55 -> 40300000 | G41: =F41-E41 -> 300000 | H41: =G41/$G$36 -> -0.0017825312 | I41: ='Action Plan'!E44 -> 856000 | J41: TRUE | K41: =IF(ROUNDUP(E41/I41,0)<>0,ROUNDUP(E41/I41,0),0) -> 47 | L41: ='Sale #1'!D55+'Sale #2'!D55+'Sale #3'!D55+'Sale #4'!D55 -> 155 | M41: =L41-K41 -> 108 | N41: =M41/$M$36 -> 0.095238095 | O41: =ROUNDUP(K41/$C$5,0) -> 2 | P41: ='Sale #1'!J55+'Sale #2'!J55+'Sale #3'!J55+'Sale #4'!J55 -> 0 | Q41: =P41-O41 -> -2 | R41: =Q41/$Q$36 -> 0.076923077 | S41: ='Action Plan'!H44 -> 1000000 | T41: TRUE | U41: =ROUNDUP(E41/S41,0) -> 40 | V41: ='Sale #1'!E55+'Sale #2'!E55+'Sale #3'!E55+'Sale #4'!E55 -> 279 | W41: =V41-U41 -> 239 | X41: =W41/$W$36 -> 0.15827815 | Y41: =ROUNDUP(U41/$C$5,0) -> 2 | Z41: ='Sale #1'!K55+'Sale #2'!K55+'Sale #3'!K55+'Sale #4'!K55 -> 0 | AA41: =Z41-Y41 -> -2 | AB41: =AA41/$AA$36 -> 0.086956522 | AC41: =E41/$C$5 -> 1600000 | AD41: ='Sale #1'!L55+'Sale #2'!L55+'Sale #3'!L55+'Sale #4'!L55 -> 0 | AE41: =AD41-AC41 -> -1600000 | AF41: =AE41/$G$26 -> 0.012603387
B42: ='Action Plan'!B45 -> HORMONAL HEALTH | C42: ='Action Plan'!C45 -> 0.03 | D42: 0.2 | E42: =$B$8*$C42 -> 15000000 | F42: ='Sale #1'!F56+'Sale #2'!F56+'Sale #3'!F56+'Sale #4'!F56 -> 40300000 | G42: =F42-E42 -> 25300000 | H42: =G42/$G$36 -> -0.1503268 | I42: ='Action Plan'!E45 -> 529000 | J42: TRUE | K42: =IF(ROUNDUP(E42/I42,0)<>0,ROUNDUP(E42/I42,0),0) -> 29 | L42: ='Sale #1'!D56+'Sale #2'!D56+'Sale #3'!D56+'Sale #4'!D56 -> 279 | M42: =L42-K42 -> 250 | N42: =M42/$M$36 -> 0.22045855 | O42: =ROUNDUP(K42/$C$5,0) -> 2 | P42: ='Sale #1'!J56+'Sale #2'!J56+'Sale #3'!J56+'Sale #4'!J56 -> 0 | Q42: =P42-O42 -> -2 | R42: =Q42/$Q$36 -> 0.076923077 | S42: ='Action Plan'!H45 -> 990000 | T42: TRUE | U42: =ROUNDUP(E42/S42,0) -> 16 | V42: ='Sale #1'!E56+'Sale #2'!E56+'Sale #3'!E56+'Sale #4'!E56 -> 217 | W42: =V42-U42 -> 201 | X42: =W42/$W$36 -> 0.13311258 | Y42: =ROUNDUP(U42/$C$5,0) -> 1 | Z42: ='Sale #1'!K56+'Sale #2'!K56+'Sale #3'!K56+'Sale #4'!K56 -> 0 | AA42: =Z42-Y42 -> -1 | AB42: =AA42/$AA$36 -> 0.043478261 | AC42: =E42/$C$5 -> 600000 | AD42: ='Sale #1'!L56+'Sale #2'!L56+'Sale #3'!L56+'Sale #4'!L56 -> 0 | AE42: =AD42-AC42 -> -600000 | AF42: =AE42/$G$26 -> 0.0047262702
...

Sheet Digital Marketer #1
A1: KPIs TRACKING
A2: MONTH | B2: 4 | D2: 1. REPORT IN ORDER WITH LATEST DATE ON TOP. FILL IN BC IN ALL GREEN CELLS (AS ABOVE) 2. FINAL REPORT ON THE SAME DAY BEFORE 5:30 PM 3. ALL APPROVED EXPORT FILES MUST BE SAVED IN THE COMPANY ACCOUNT IN ACCORDANCE WITH THE FOLDER AND FILE NAMING INSTRUCTIONS AS FOLLOWS: HB MARKETING -> LOCATION + NAME -> BY DEPLOYMENT CONTENT -> FILE NAME: TITLE FILE
A3: YEAR | B3: 2025
A4: VND | B4: 1000000
J5: 45748 | K5: =J5+1 -> 45749 | L5: =K5+1 -> 45750 | M5: =L5+1 -> 45751 | N5: =M5+1 -> 45752 | O5: =N5+1 -> 45753 | P5: =O5+1 -> 45754 | Q5: =P5+1 -> 45755 | R5: =Q5+1 -> 45756 | ... AN5: =AM5+1 -> 45778
D6: ESTIMATED | E6: ACTUAL | F6: REMAINING | G6: RATIO | H6: KPIs | I6: TASKS COMPLETED | J6: =IF(WEEKDAY(J5)=1,"CN","T"&WEEKDAY(J5)) -> T3 | K6: =IF(WEEKDAY(K5)=1,"CN","T"&WEEKDAY(K5)) -> T4 | L6: =IF(WEEKDAY(L5)=1,"CN","T"&WEEKDAY(L5)) -> T5 | M6: =IF(WEEKDAY(M5)=1,"CN","T"&WEEKDAY(M5)) -> T6 | N6: =IF(WEEKDAY(N5)=1,"CN","T"&WEEKDAY(N5)) -> T7 | O6: =IF(WEEKDAY(O5)=1,"CN","T"&WEEKDAY(O5)) -> CN | P6: =IF(WEEKDAY(P5)=1,"CN","T"&WEEKDAY(P5)) -> T2 | Q6: =IF(WEEKDAY(Q5)=1,"CN","T"&WEEKDAY(Q5)) -> T3 | ... AN6: =IF(WEEKDAY(AN5)=1,"CN","T"&WEEKDAY(AN5)) -> T5
C7: BUDGET | D7: =Dashboard!E15 -> 170000000 | E7: =E8+'E-Com Operations'!E7 -> 45700000 | F7: =D7-E7 -> 124300000 | G7: =_xlfn.IFS(F7>0,1,F7<=0,D7/E7) -> 1 | H7: =D7/'Action Plan'!$C$6 -> 6538461.5 | I7: =SUMIF($J$5:$AN$5,TODAY(),J7:AN7) -> 0 | J7: =J8 -> 850000 | K7: =K8 -> 900000 | L7: =L8 -> 900000 | M7: =M8 -> 900000 | N7: =N8 -> 900000 | O7: =O8 -> 900000 | P7: =P8 -> 900000 | Q7: =Q8 -> 900000 | ... AN7: =AN8 -> 1100000
C8: BUDGET | D8: =D9+D15+D21+D24+D25+D27+D28+D26 -> 200000000 | E8: =E9+E15+E21+E24+E25+E27+E28+E26 -> 28900000 | F8: =F9+F15+F21+F24+F25+F27+F28+F26 -> 171100000 | G8: =_xlfn.IFS(F8>0,1,F8<=0,D8/E8) -> 1 | H8: =H9+H15+H21+H24+H25+H27+H28+H26 -> 7692307.7 | I8: =I9+I15+I21+I24+I25+I27+I28+I26 -> 0 | J8: =J9+J15+J21+J24+J25+J27+J28+J26 -> 850000 | K8: =K9+K15+K21+K24+K25+K27+K28+K26 -> 900000 | L8: =L9+L15+L21+L24+L25+L27+L28+L26 -> 900000 | M8: =M9+M15+M21+M24+M25+M27+M28+M26 -> 900000 | N8: =N9+N15+N21+N24+N25+N27+N28+N26 -> 900000 | O8: =O9+O15+O21+O24+O25+O27+O28+O26 -> 900000 | ... AN8: =AN9+AN15+AN21+AN24+AN25+AN27+AN28+AN26 -> 1100000
C9: =Dashboard!B16 -> FACEBOOK | D9: =Dashboard!E16*Dashboard!$P$8 -> 10000000 | E9: =SUM(E10:E14) -> 300000 | F9: =D9-E9 -> 9700000 | G9: =_xlfn.IFS(F9>0,1,F9<=0,D9/E9) -> 1 | H9: =D9/'Action Plan'!$C$6 -> 384615.38 | I9: =SUM(I10:I14) -> 0 | J9: =SUM(J10:J14) -> 0 | K9: =SUM(K10:K14) -> 0 | L9: =SUM(L10:L14) -> 0 | M9: =SUM(M10:M14) -> 0 | N9: =SUM(N10:N14) -> 0 | O9: =SUM(O10:O14) -> 0 | P9: =SUM(P10:P14) -> 0 | ... AN9: =SUM(AN10:AN14) -> 0
C10: VISION | D10: =$D$9/5 -> 2000000 | E10: =SUM(J10:AN10) -> 60000 | F10: =D10-E10 -> 1940000 | I10: =SUMIF($J$5:$AN$5,TODAY(),J10:AN10) -> 0 | AL10: 30000 | AM10: 30000 | AN10: 0
C11: BLACKHAIR | D11: =$D$9/5 -> 2000000 | E11: =SUM(J11:AN11) -> 60000 | F11: =D11-E11 -> 1940000 | I11: =SUMIF($J$5:$AN$5,TODAY(),J11:AN11) -> 0 | AL11: 30000 | AM11: 30000 | AN11: 0
C12: GLUTAWHITE | D12: =$D$9/5 -> 2000000 | E12: =SUM(J12:AN12) -> 60000 | F12: =D12-E12 -> 1940000 | I12: =SUMIF($J$5:$AN$5,TODAY(),J12:AN12) -> 0 | AL12: 30000 | AM12: 30000 | AN12: 0
C13: GLUTATHION | D13: =$D$9/5 -> 2000000 | E13: =SUM(J13:AN13) -> 60000 | F13: =D13-E13 -> 1940000 | I13: =SUMIF($J$5:$AN$5,TODAY(),J13:AN13) -> 0 | AL13: 30000 | AM13: 30000 | AN13: 0
C14: CORDY | D14: =$D$9/5 -> 2000000 | E14: =SUM(J14:AN14) -> 60000 | F14: =D14-E14 -> 1940000 | I14: =SUMIF($J$5:$AN$5,TODAY(),J14:AN14) -> 0 | AL14: 30000 | AM14: 30000 | AN14: 0
C15: =Dashboard!B17 -> LANDING PAGE | D15: =Dashboard!E17*Dashboard!$P$8 -> 60000000 | E15: =SUM(E16:E20) -> 15000000 | F15: =D15-E15 -> 45000000 | G15: =_xlfn.IFS(F15>0,1,F15<=0,D15/E15) -> 1 | H15: =D15/'Action Plan'!$C$6 -> 2307692.3 | I15: =SUM(I16:I20) -> 0 | J15: =SUM(J16:J20) -> 500000 | K15: =SUM(K16:K20) -> 500000 | L15: =SUM(L16:L20) -> 500000 | M15: =SUM(M16:M20) -> 500000 | N15: =SUM(N16:N20) -> 500000 | O15: =SUM(O16:O20) -> 500000 | P15: =SUM(P16:P20) -> 500000 | ... AN15: =SUM(AN16:AN20) -> 0
C16: VISION | D16: =$D$15/5 -> 12000000 | E16: =SUM(J16:AN16) -> 3000000 | F16: =D16-E16 -> 9000000 | I16: =SUMIF($J$5:$AN$5,TODAY(),J16:AN16) -> 0 | J16: 100000 | K16: 100000 | L16: 100000 | M16: 100000 | N16: 100000 | O16: 100000 | P16: 100000 | Q16: 100000 | R16: 100000 | S16: 100000 | T16: 100000 | U16: 100000 | V16: 100000 | W16: 100000 | X16: 100000 | Y16: 100000 | Z16: 100000 | AA16: 100000 | AB16: 100000 | AC16: 100000 | AD16: 100000 | AE16: 100000 | AF16: 100000 | AG16: 100000 | AH16: 100000 | AI16: 100000 | AJ16: 100000 | AK16: 100000 | AL16: 100000 | AM16: 100000 | AN16: 0
C17: BLACKHAIR | D17: =$D$15/5 -> 12000000 | E17: =SUM(J17:AN17) -> 3000000 | F17: =D17-E17 -> 9000000 | I17: =SUMIF($J$5:$AN$5,TODAY(),J17:AN17) -> 0 | J17: 100000 | K17: 100000 | L17: 100000 | M17: 100000 | N17: 100000 | O17: 100000 | P17: 100000 | Q17: 100000 | R17: 100000 | S17: 100000 | T17: 100000 | U17: 100000 | V17: 100000 | W17: 100000 | X17: 100000 | Y17: 100000 | Z17: 100000 | AA17: 100000 | AB17: 100000 | AC17: 100000 | AD17: 100000 | AE17: 100000 | AF17: 100000 | AG17: 100000 | AH17: 100000 | AI17: 100000 | AJ17: 100000 | AK17: 100000 | AL17: 100000 | AM17: 100000 | AN17: 0
C18: GLUTAWHITE | D18: =$D$15/5 -> 12000000 | E18: =SUM(J18:AN18) -> 3000000 | F18: =D18-E18 -> 9000000 | I18: =SUMIF($J$5:$AN$5,TODAY(),J18:AN18) -> 0 | J18: 100000 | K18: 100000 | L18: 100000 | M18: 100000 | N18: 100000 | O18: 100000 | P18: 100000 | Q18: 100000 | R18: 100000 | S18: 100000 | T18: 100000 | U18: 100000 | V18: 100000 | W18: 100000 | X18: 100000 | Y18: 100000 | Z18: 100000 | AA18: 100000 | AB18: 100000 | AC18: 100000 | AD18: 100000 | AE18: 100000 | AF18: 100000 | AG18: 100000 | AH18: 100000 | AI18: 100000 | AJ18: 100000 | AK18: 100000 | AL18: 100000 | AM18: 100000 | AN18: 0
C19: GLUTATHION | D19: =$D$15/5 -> 12000000 | E19: =SUM(J19:AN19) -> 3000000 | F19: =D19-E19 -> 9000000 | I19: =SUMIF($J$5:$AN$5,TODAY(),J19:AN19) -> 0 | J19: 100000 | K19: 100000 | L19: 100000 | M19: 100000 | N19: 100000 | O19: 100000 | P19: 100000 | Q19: 100000 | R19: 100000 | S19: 100000 | T19: 100000 | U19: 100000 | V19: 100000 | W19: 100000 | X19: 100000 | Y19: 100000 | Z19: 100000 | AA19: 100000 | AB19: 100000 | AC19: 100000 | AD19: 100000 | AE19: 100000 | AF19: 100000 | AG19: 100000 | AH19: 100000 | AI19: 100000 | AJ19: 100000 | AK19: 100000 | AL19: 100000 | AM19: 100000 | AN19: 0
C20: CORDY | D20: =$D$15/5 -> 12000000 | E20: =SUM(J20:AN20) -> 3000000 | F20: =D20-E20 -> 9000000 | I20: =SUMIF($J$5:$AN$5,TODAY(),J20:AN20) -> 0 | J20: 100000 | K20: 100000 | L20: 100000 | M20: 100000 | N20: 100000 | O20: 100000 | P20: 100000 | Q20: 100000 | R20: 100000 | S20: 100000 | T20: 100000 | U20: 100000 | V20: 100000 | W20: 100000 | X20: 100000 | Y20: 100000 | Z20: 100000 | AA20: 100000 | AB20: 100000 | AC20: 100000 | AD20: 100000 | AE20: 100000 | AF20: 100000 | AG20: 100000 | AH20: 100000 | AI20: 100000 | AJ20: 100000 | AK20: 100000 | AL20: 100000 | AM20: 100000 | AN20: 0
C21: =Dashboard!B18 -> WEBSITE | D21: =Dashboard!E18*Dashboard!$P$8 -> 10000000 | E21: =SUM(E22:E23) -> 3600000 | F21: =D21-E21 -> 6400000 | G21: =_xlfn.IFS(F21>0,1,F21<=0,D21/E21) -> 1 | H21: =D21/'Action Plan'!$C$6 -> 384615.38 | I21: =SUM(I22:I23) -> 0 | J21: =SUM(J22:J23) -> 100000 | K21: =SUM(K22:K23) -> 100000 | L21: =SUM(L22:L23) -> 100000 | M21: =SUM(M22:M23) -> 100000 | N21: =SUM(N22:N23) -> 100000 | O21: =SUM(O22:O23) -> 100000 | P21: =SUM(P22:P23) -> 100000 | ... AN21: =SUM(AN22:AN23) -> 600000
C22: HBPHARMA | D22: =$D$21/2 -> 5000000 | E22: =SUM(J22:AN22) -> 1800000 | F22: =D22-E22 -> 3200000 | H22: =D22/'Action Plan'!$C$6 -> 192307.69 | I22: =SUMIF($J$5:$AN$5,TODAY(),J22:AN22) -> 0 | J22: 50000 | K22: 50000 | L22: 50000 | M22: 50000 | N22: 50000 | O22: 50000 | P22: 50000 | Q22: 50000 | R22: 50000 | S22: 50000 | T22: 50000 | U22: 50000 | V22: 50000 | W22: 50000 | X22: 50000 | Y22: 50000 | Z22: 50000 | AA22: 50000 | AB22: 50000 | AC22: 50000 | AD22: 50000 | AE22: 50000 | AF22: 50000 | AG22: 50000 | AH22: 50000 | AI22: 50000 | AJ22: 50000 | AK22: 50000 | AL22: 50000 | AM22: 50000 | AN22: 300000
C23: HOTLINE | D23: =$D$21/2 -> 5000000 | E23: =SUM(J23:AN23) -> 1800000 | F23: =D23-E23 -> 3200000 | H23: =D23/'Action Plan'!$C$6 -> 192307.69 | I23: =SUMIF($J$5:$AN$5,TODAY(),J23:AN23) -> 0 | J23: 50000 | K23: 50000 | L23: 50000 | M23: 50000 | N23: 50000 | O23: 50000 | P23: 50000 | Q23: 50000 | R23: 50000 | S23: 50000 | T23: 50000 | U23: 50000 | V23: 50000 | W23: 50000 | X23: 50000 | Y23: 50000 | Z23: 50000 | AA23: 50000 | AB23: 50000 | AC23: 50000 | AD23: 50000 | AE23: 50000 | AF23: 50000 | AG23: 50000 | AH23: 50000 | AI23: 50000 | AJ23: 50000 | AK23: 50000 | AL23: 50000 | AM23: 50000 | AN23: 300000
C24: =Dashboard!B19 -> TIKTOK SHOP | D24: =Dashboard!E19*Dashboard!$P$8 -> 20000000 | E24: =SUM(J24:AN24) -> 1200000 | F24: =D24-E24 -> 18800000 | G24: =_xlfn.IFS(F24>0,1,F24<=0,D24/E24) -> 1 | H24: =D24/'Action Plan'!$C$6 -> 769230.77 | I24: =SUMIF($J$5:$AN$5,TODAY(),J24:AN24) -> 0 | J24: 0 | K24: 0 | L24: 0 | M24: 0 | N24: 0 | O24: 0 | P24: 0 | Q24: 0 | R24: 0 | S24: 0 | T24: 0 | U24: 0 | V24: 0 | W24: 0 | X24: 0 | Y24: 0 | Z24: 0 | AA24: 0 | AB24: 0 | AC24: 0 | AD24: 0 | AE24: 0 | AF24: 0 | AG24: 0 | AH24: 0 | AI24: 200000 | AJ24: 200000 | AK24: 200000 | AL24: 200000 | AM24: 200000 | AN24: 200000
C25: =Dashboard!B20 -> SHOPEE | D25: =Dashboard!E20*Dashboard!$P$8 -> 10000000 | E25: =SUM(J25:AN25) -> 0 | F25: =D25-E25 -> 10000000 | G25: =_xlfn.IFS(F25>0,1,F25<=0,D25/E25) -> 1 | H25: =D25/'Action Plan'!$C$6 -> 384615.38 | I25: =SUMIF($J$5:$AN$5,TODAY(),J25:AN25) -> 0 | J25: 0 | K25: 0 | L25: 0 | M25: 0 | N25: 0 | O25: 0 | P25: 0 | Q25: 0 | R25: 0 | S25: 0 | T25: 0 | U25: 0 | V25: 0 | W25: 0 | X25: 0 | Y25: 0 | Z25: 0 | AA25: 0 | AB25: 0 | AC25: 0 | AD25: 0 | AE25: 0 | AF25: 0 | AG25: 0 | AH25: 0 | AI25: 0 | AJ25: 0 | AK25: 0 | AL25: 0 | AM25: 0 | AN25: 0
C26: =Dashboard!B21 -> ZALO | D26: =Dashboard!E21*Dashboard!$P$8 -> 40000000 | E26: =SUM(J26:AN26) -> 2650000 | F26: =D26-E26 -> 37350000 | G26: =_xlfn.IFS(F26>0,1,F26<=0,D26/E26) -> 1 | H26: =D26/'Action Plan'!$C$6 -> 1538461.5 | I26: =SUMIF($J$5:$AN$5,TODAY(),J26:AN26) -> 0 | J26: 100000 | K26: 100000 | L26: 100000 | M26: 100000 | N26: 100000 | O26: 100000 | P26: 100000 | Q26: 100000 | R26: 100000 | S26: 100000 | T26: 100000 | U26: 100000 | V26: 100000 | W26: 100000 | X26: 100000 | Y26: 100000 | Z26: 100000 | AA26: 100000 | AB26: 100000 | AC26: 100000 | AD26: 100000 | AE26: 100000 | AF26: 100000 | AG26: 100000 | AH26: 100000 | AI26: 10000 | AJ26: 10000 | AK26: 10000 | AL26: 10000 | AM26: 10000 | AN26: 100000
C27: =Dashboard!B22 -> BOOKING | D27: =Dashboard!E21*Dashboard!$P$8 -> 40000000 | E27: =SUM(J27:AN27) -> 3150000 | F27: =D27-E27 -> 36850000 | G27: =_xlfn.IFS(F27>0,1,F27<=0,D27/E27) -> 1 | H27: =D27/'Action Plan'!$C$6 -> 1538461.5 | I27: =SUMIF($J$5:$AN$5,TODAY(),J27:AN27) -> 0 | J27: 150000 | K27: 100000 | L27: 100000 | M27: 100000 | N27: 100000 | O27: 100000 | P27: 100000 | Q27: 100000 | R27: 100000 | S27: 100000 | T27: 100000 | U27: 100000 | V27: 100000 | W27: 100000 | X27: 100000 | Y27: 100000 | Z27: 100000 | AA27: 100000 | AB27: 100000 | AC27: 100000 | AD27: 100000 | AE27: 100000 | AF27: 100000 | AG27: 100000 | AH27: 100000 | AI27: 100000 | AJ27: 100000 | AK27: 100000 | AL27: 100000 | AM27: 100000 | AN27: 100000
C28: =Dashboard!B23 -> BRANDING | D28: =Dashboard!E22*Dashboard!$P$8 -> 10000000 | E28: =SUM(J28:AN28) -> 3000000 | F28: =D28-E28 -> 7000000 | G28: =_xlfn.IFS(F28>0,1,F28<=0,D28/E28) -> 1 | H28: =D28/'Action Plan'!$C$6 -> 384615.38 | I28: =SUMIF($J$5:$AN$5,TODAY(),J28:AN28) -> 0 | J28: 0 | K28: 100000 | L28: 100000 | M28: 100000 | N28: 100000 | O28: 100000 | P28: 100000 | Q28: 100000 | R28: 100000 | S28: 100000 | T28: 100000 | U28: 100000 | V28: 100000 | W28: 100000 | X28: 100000 | Y28: 100000 | Z28: 100000 | AA28: 100000 | AB28: 100000 | AC28: 100000 | AD28: 100000 | AE28: 100000 | AF28: 100000 | AG28: 100000 | AH28: 100000 | AI28: 100000 | AJ28: 100000 | AK28: 100000 | AL28: 100000 | AM28: 100000 | AN28: 100000
C29: =Dashboard!K52 -> P2
C30: DATA | D30: =Dashboard!E53 -> 1680 | E30: =Dashboard!F53 -> 1528 | F30: =E30-D30 -> -152 | G30: =_xlfn.IFS(F30>0,1,F30<0,E30/D30,F30=0,0) -> 0.90952381 | H30: =D30/'Action Plan'!$C$6 -> 64.615385 | I30: =SUMIF($J$5:$AN$5,TODAY(),J30:AN30) -> 0 | J30: =J31 -> 36 | K30: =K31 -> 36 | L30: =L31 -> 36 | M30: =M31 -> 36 | N30: =N31 -> 36 | O30: =O31 -> 36 | P30: =P31 -> 36 | Q30: =Q31 -> 36 | ... AN30: =AN31 -> 45
C31: =Dashboard!K53 -> DATA | D31: =Dashboard!M53 -> 1000 | E31: =SUM(E32:E37) -> 1125 | F31: =E31-D31 -> 125 | G31: =_xlfn.IFS(F31>0,1,F31<0,E31/D31,F31=0,0) -> 1 | H31: =D31/'Action Plan'!$C$6 -> 38.461538 | I31: =SUM(I32:I37) -> 0 | J31: =SUM(J32:J37) -> 36 | K31: =SUM(K32:K37) -> 36 | L31: =SUM(L32:L37) -> 36 | M31: =SUM(M32:M37) -> 36 | N31: =SUM(N32:N37) -> 36 | O31: =SUM(O32:O37) -> 36 | P31: =SUM(P32:P37) -> 36 | ... AN31: =SUM(AN32:AN37) -> 45
C32: =Dashboard!K54 -> FACEBOOK | D32: =Dashboard!M54 -> 400 | E32: =SUM(J32:AN32) -> 310 | F32: =E32-D32 -> -90 | G32: =_xlfn.IFS(F32>0,1,F32<0,E32/D32,F32=0,0) -> 0.775 | H32: =D32/'Action Plan'!$C$6 -> 15.384615 | I32: =SUMIF($J$5:$AN$5,TODAY(),J32:AN32) -> 0 | J32: 10 | K32: 10 | L32: 10 | M32: 10 | N32: 10 | O32: 10 | P32: 10 | Q32: 10 | R32: 10 | S32: 10 | T32: 10 | U32: 10 | V32: 10 | W32: 10 | X32: 10 | Y32: 10 | Z32: 10 | AA32: 10 | AB32: 10 | AC32: 10 | AD32: 10 | AE32: 10 | AF32: 10 | AG32: 10 | AH32: 10 | AI32: 10 | AJ32: 10 | AK32: 10 | AL32: 10 | AM32: 10 | AN32: 10
C33: =Dashboard!K55 -> LANDING PAGE | D33: =Dashboard!M55 -> 300 | E33: =SUM(J33:AN33) -> 310 | F33: =E33-D33 -> 10 | G33: =_xlfn.IFS(F33>0,1,F33<0,E33/D33,F33=0,0) -> 1 | H33: =D33/'Action Plan'!$C$6 -> 11.538462 | I33: =SUMIF($J$5:$AN$5,TODAY(),J33:AN33) -> 0 | J33: 10 | K33: 10 | L33: 10 | M33: 10 | N33: 10 | O33: 10 | P33: 10 | Q33: 10 | R33: 10 | S33: 10 | T33: 10 | U33: 10 | V33: 10 | W33: 10 | X33: 10 | Y33: 10 | Z33: 10 | AA33: 10 | AB33: 10 | AC33: 10 | AD33: 10 | AE33: 10 | AF33: 10 | AG33: 10 | AH33: 10 | AI33: 10 | AJ33: 10 | AK33: 10 | AL33: 10 | AM33: 10 | AN33: 10
C34: =Dashboard!K56 -> WEBSITE | D34: =Dashboard!M56 -> 100 | E34: =SUM(J34:AN34) -> 40 | F34: =E34-D34 -> -60 | G34: =_xlfn.IFS(F34>0,1,F34<0,E34/D34,F34=0,0) -> 0.4 | H34: =D34/'Action Plan'!$C$6 -> 3.8461538 | I34: =SUMIF($J$5:$AN$5,TODAY(),J34:AN34) -> 0 | J34: 1 | K34: 1 | L34: 1 | M34: 1 | N34: 1 | O34: 1 | P34: 1 | Q34: 1 | R34: 1 | S34: 1 | T34: 1 | U34: 1 | V34: 1 | W34: 1 | X34: 1 | Y34: 1 | Z34: 1 | AA34: 1 | AB34: 1 | AC34: 1 | AD34: 1 | AE34: 1 | AF34: 1 | AG34: 1 | AH34: 1 | AI34: 1 | AJ34: 1 | AK34: 1 | AL34: 1 | AM34: 1 | AN34: 10
C35: =Dashboard!K57 -> TIKTOKSHOP | D35: =Dashboard!M57 -> 50 | E35: =SUM(J35:AN35) -> 155 | F35: =E35-D35 -> 105 | G35: =_xlfn.IFS(F35>0,1,F35<0,E35/D35,F35=0,0) -> 1 | H35: =D35/'Action Plan'!$C$6 -> 1.9230769 | I35: =SUMIF($J$5:$AN$5,TODAY(),J35:AN35) -> 0 | J35: 5 | K35: 5 | L35: 5 | M35: 5 | N35: 5 | O35: 5 | P35: 5 | Q35: 5 | R35: 5 | S35: 5 | T35: 5 | U35: 5 | V35: 5 | W35: 5 | X35: 5 | Y35: 5 | Z35: 5 | AA35: 5 | AB35: 5 | AC35: 5 | AD35: 5 | AE35: 5 | AF35: 5 | AG35: 5 | AH35: 5 | AI35: 5 | AJ35: 5 | AK35: 5 | AL35: 5 | AM35: 5 | AN35: 5
C36: =Dashboard!K58 -> SHOPPEE | D36: =Dashboard!M58 -> 50 | E36: =SUM(J36:AN36) -> 155 | F36: =E36-D36 -> 105 | G36: =_xlfn.IFS(F36>0,1,F36<0,E36/D36,F36=0,0) -> 1 | H36: =D36/'Action Plan'!$C$6 -> 1.9230769 | I36: =SUMIF($J$5:$AN$5,TODAY(),J36:AN36) -> 0 | J36: 5 | K36: 5 | L36: 5 | M36: 5 | N36: 5 | O36: 5 | P36: 5 | Q36: 5 | R36: 5 | S36: 5 | T36: 5 | U36: 5 | V36: 5 | W36: 5 | X36: 5 | Y36: 5 | Z36: 5 | AA36: 5 | AB36: 5 | AC36: 5 | AD36: 5 | AE36: 5 | AF36: 5 | AG36: 5 | AH36: 5 | AI36: 5 | AJ36: 5 | AK36: 5 | AL36: 5 | AM36: 5 | AN36: 5
C37: =Dashboard!K59 -> ZALO | D37: =Dashboard!M59 -> 100 | E37: =SUM(J37:AN37) -> 155 | F37: =E37-D37 -> 55 | G37: =_xlfn.IFS(F37>0,1,F37<0,E37/D37,F37=0,0) -> 1 | H37: =D37/'Action Plan'!$C$6 -> 3.8461538 | I37: =SUMIF($J$5:$AN$5,TODAY(),J37:AN37) -> 0 | J37: 5 | K37: 5 | L37: 5 | M37: 5 | N37: 5 | O37: 5 | P37: 5 | Q37: 5 | R37: 5 | S37: 5 | T37: 5 | U37: 5 | V37: 5 | W37: 5 | X37: 5 | Y37: 5 | Z37: 5 | AA37: 5 | AB37: 5 | AC37: 5 | AD37: 5 | AE37: 5 | AF37: 5 | AG37: 5 | AH37: 5 | AI37: 5 | AJ37: 5 | AK37: 5 | AL37: 5 | AM37: 5 | AN37: 5
C38: ADS | D38: =Dashboard!E60 -> 70 | E38: =Dashboard!F60 -> 188 | F38: =E38-D38 -> 118 | G38: =_xlfn.IFS(F38>0,1,F38<=0,E38/D38) -> 1 | H38: =D38/'Action Plan'!$C$6 -> 2.6923077 | I38: =SUMIF($J$5:$AN$5,TODAY(),J38:AN38) -> 0 | J38: =J39 -> 5 | K38: =K39 -> 5 | L38: =L39 -> 5 | M38: =M39 -> 5 | N38: =N39 -> 5 | O38: =O39 -> 5 | P38: =P39 -> 5 | Q38: =Q39 -> 5 | ... AN38: =AN39 -> 6
C39: =Dashboard!K60 -> ADS | D39: =Dashboard!M60 -> 30 | E39: =SUM(E40:E45) -> 156 | F39: =E39-D39 -> 126 | G39: =_xlfn.IFS(F39>0,1,F39<=0,E39/D39) -> 1 | H39: =D39/'Action Plan'!$C$6 -> 1.1538462 | I39: =SUM(I40:I45) -> 0 | J39: =SUM(J40:J45) -> 5 | K39: =SUM(K40:K45) -> 5 | L39: =SUM(L40:L45) -> 5 | M39: =SUM(M40:M45) -> 5 | N39: =SUM(N40:N45) -> 5 | O39: =SUM(O40:O45) -> 5 | P39: =SUM(P40:P45) -> 5 | ... AN39: =SUM(AN40:AN45) -> 6
C40: =Dashboard!K61 -> FACEBOOK | D40: =Dashboard!M61 -> 10 | E40: =SUM(J40:AN40) -> 62 | F40: =E40-D40 -> 52 | G40: =_xlfn.IFS(F40>0,1,F40<0,E40/D40,F40=0,0) -> 1 | H40: =D40/'Action Plan'!$C$6 -> 0.38461538 | I40: =SUMIF($J$5:$AN$5,TODAY(),J40:AN40) -> 0 | J40: 2 | K40: 2 | L40: 2 | M40: 2 | N40: 2 | O40: 2 | P40: 2 | Q40: 2 | R40: 2 | S40: 2 | T40: 2 | U40: 2 | V40: 2 | W40: 2 | X40: 2 | Y40: 2 | Z40: 2 | AA40: 2 | AB40: 2 | AC40: 2 | AD40: 2 | AE40: 2 | AF40: 2 | AG40: 2 | AH40: 2 | AI40: 2 | AJ40: 2 | AK40: 2 | AL40: 2 | AM40: 2 | AN40: 2
...

Sheet E-Com Operations
A1: KPIs TRACKING
A2: MONTH | B2: 4 | D2: 1. REPORT IN ORDER WITH LATEST DATE ON TOP. FILL IN BC IN ALL GREEN CELLS (AS ABOVE) 2. FINAL REPORT ON THE SAME DAY BEFORE 5:30 PM 3. ALL APPROVED EXPORT FILES MUST BE SAVED IN THE COMPANY ACCOUNT IN ACCORDANCE WITH THE FOLDER AND FILE NAMING INSTRUCTIONS AS FOLLOWS: HB MARKETING -> LOCATION + NAME -> BY DEPLOYMENT CONTENT -> FILE NAME: TITLE FILE
A3: YEAR | B3: 2025
A4: VND | B4: 1000000
J5: 45748 | K5: =J5+1 -> 45749 | L5: =K5+1 -> 45750 | M5: =L5+1 -> 45751 | N5: =M5+1 -> 45752 | O5: =N5+1 -> 45753 | P5: =O5+1 -> 45754 | Q5: =P5+1 -> 45755 | R5: =Q5+1 -> 45756 | ... AN5: =AM5+1 -> 45778
D6: ESTIMATED | E6: ACTUAL | F6: REMAINING | G6: RATIO | H6: KPIs | I6: TASKS COMPLETED | J6: =IF(WEEKDAY(J5)=1,"CN","T"&WEEKDAY(J5)) -> T3 | K6: =IF(WEEKDAY(K5)=1,"CN","T"&WEEKDAY(K5)) -> T4 | L6: =IF(WEEKDAY(L5)=1,"CN","T"&WEEKDAY(L5)) -> T5 | M6: =IF(WEEKDAY(M5)=1,"CN","T"&WEEKDAY(M5)) -> T6 | N6: =IF(WEEKDAY(N5)=1,"CN","T"&WEEKDAY(N5)) -> T7 | O6: =IF(WEEKDAY(O5)=1,"CN","T"&WEEKDAY(O5)) -> CN | P6: =IF(WEEKDAY(P5)=1,"CN","T"&WEEKDAY(P5)) -> T2 | Q6: =IF(WEEKDAY(Q5)=1,"CN","T"&WEEKDAY(Q5)) -> T3 | ... AN6: =IF(WEEKDAY(AN5)=1,"CN","T"&WEEKDAY(AN5)) -> T5
C7: BUDGET | D7: =Dashboard!E15 -> 170000000 | E7: =E8 -> 16800000 | F7: =D7-E7 -> 153200000 | G7: =_xlfn.IFS(F7>0,1,F7<=0,D7/E7) -> 1 | H7: =D7/'Action Plan'!$C$6 -> 6538461.5 | I7: =SUMIF($J$5:$AN$5,TODAY(),J7:AN7) -> 0 | J7: =J8 -> 550000 | K7: =K8 -> 550000 | L7: =L8 -> 550000 | M7: =M8 -> 550000 | N7: =N8 -> 550000 | O7: =O8 -> 550000 | P7: =P8 -> 550000 | Q7: =Q8 -> 550000 | ... AN7: =AN8 -> 300000
C8: BUDGET | D8: =D9+D15+D21+D24+D25+D27+D28+D26 -> 200000000 | E8: =E9+E15+E21+E24+E25+E26+E27+E28 -> 16800000 | F8: =F9+F15+F21+F24+F25+F26+F27+F28 -> 183200000 | G8: =_xlfn.IFS(F8>0,1,F8<=0,D8/E8) -> 1 | H8: =H9+H15+H21+H24+H25+H27+H28+H26 -> 7692307.7 | I8: =I9+I15+I21+I24+I25+I27+I28+I26 -> 0 | J8: =J9+J15+J21+J24+J25+J27+J28+J26 -> 550000 | K8: =K9+K15+K21+K24+K25+K27+K28+K26 -> 550000 | L8: =L9+L15+L21+L24+L25+L27+L28+L26 -> 550000 | M8: =M9+M15+M21+M24+M25+M27+M28+M26 -> 550000 | N8: =N9+N15+N21+N24+N25+N27+N28+N26 -> 550000 | O8: =O9+O15+O21+O24+O25+O27+O28+O26 -> 550000 | ... AN8: =AN9+AN15+AN21+AN24+AN25+AN27+AN28+AN26 -> 300000
C9: =Dashboard!B16 -> FACEBOOK | D9: =Dashboard!E16*Dashboard!$P$9 -> 10000000 | E9: =SUM(E10:E14) -> 0 | F9: =D9-E9 -> 10000000 | G9: =_xlfn.IFS(F9>0,1,F9<=0,D9/E9) -> 1 | H9: =D9/'Action Plan'!$C$6 -> 384615.38 | I9: =SUM(I10:I14) -> 0 | J9: =SUM(J10:J14) -> 0 | K9: =SUM(K10:K14) -> 0 | L9: =SUM(L10:L14) -> 0 | M9: =SUM(M10:M14) -> 0 | N9: =SUM(N10:N14) -> 0 | O9: =SUM(O10:O14) -> 0 | P9: =SUM(P10:P14) -> 0 | ... AN9: =SUM(AN10:AN14) -> 0
C10: VISION | D10: =$D$9/5 -> 2000000 | E10: =SUM(J10:AN10) -> 0 | F10: =D10-E10 -> 2000000 | I10: =SUMIF($J$5:$AN$5,TODAY(),J10:AN10) -> 0 | J10: 0 | K10: 0 | L10: 0 | M10: 0 | N10: 0 | O10: 0 | P10: 0 | Q10: 0 | R10: 0 | S10: 0 | T10: 0 | U10: 0 | V10: 0 | W10: 0 | X10: 0 | Y10: 0 | Z10: 0 | AA10: 0 | AB10: 0 | AC10: 0 | AD10: 0 | AE10: 0 | AF10: 0 | AG10: 0 | AH10: 0 | AI10: 0 | AJ10: 0 | AK10: 0 | AL10: 0 | AM10: 0 | AN10: 0
C11: BLACKHAIR | D11: =$D$9/5 -> 2000000 | E11: =SUM(J11:AN11) -> 0 | F11: =D11-E11 -> 2000000 | I11: =SUMIF($J$5:$AN$5,TODAY(),J11:AN11) -> 0 | J11: 0 | K11: 0 | L11: 0 | M11: 0 | N11: 0 | O11: 0 | P11: 0 | Q11: 0 | R11: 0 | S11: 0 | T11: 0 | U11: 0 | V11: 0 | W11: 0 | X11: 0 | Y11: 0 | Z11: 0 | AA11: 0 | AB11: 0 | AC11: 0 | AD11: 0 | AE11: 0 | AF11: 0 | AG11: 0 | AH11: 0 | AI11: 0 | AJ11: 0 | AK11: 0 | AL11: 0 | AM11: 0 | AN11: 0
C12: GLUTAWHITE | D12: =$D$9/5 -> 2000000 | E12: =SUM(J12:AN12) -> 0 | F12: =D12-E12 -> 2000000 | I12: =SUMIF($J$5:$AN$5,TODAY(),J12:AN12) -> 0 | J12: 0 | K12: 0 | L12: 0 | M12: 0 | N12: 0 | O12: 0 | P12: 0 | Q12: 0 | R12: 0 | S12: 0 | T12: 0 | U12: 0 | V12: 0 | W12: 0 | X12: 0 | Y12: 0 | Z12: 0 | AA12: 0 | AB12: 0 | AC12: 0 | AD12: 0 | AE12: 0 | AF12: 0 | AG12: 0 | AH12: 0 | AI12: 0 | AJ12: 0 | AK12: 0 | AL12: 0 | AM12: 0 | AN12: 0
C13: GLUTATHION | D13: =$D$9/5 -> 2000000 | E13: =SUM(J13:AN13) -> 0 | F13: =D13-E13 -> 2000000 | I13: =SUMIF($J$5:$AN$5,TODAY(),J13:AN13) -> 0 | J13: 0 | K13: 0 | L13: 0 | M13: 0 | N13: 0 | O13: 0 | P13: 0 | Q13: 0 | R13: 0 | S13: 0 | T13: 0 | U13: 0 | V13: 0 | W13: 0 | X13: 0 | Y13: 0 | Z13: 0 | AA13: 0 | AB13: 0 | AC13: 0 | AD13: 0 | AE13: 0 | AF13: 0 | AG13: 0 | AH13: 0 | AI13: 0 | AJ13: 0 | AK13: 0 | AL13: 0 | AM13: 0 | AN13: 0
C14: CORDY | D14: =$D$9/5 -> 2000000 | E14: =SUM(J14:AN14) -> 0 | F14: =D14-E14 -> 2000000 | I14: =SUMIF($J$5:$AN$5,TODAY(),J14:AN14) -> 0 | J14: 0 | K14: 0 | L14: 0 | M14: 0 | N14: 0 | O14: 0 | P14: 0 | Q14: 0 | R14: 0 | S14: 0 | T14: 0 | U14: 0 | V14: 0 | W14: 0 | X14: 0 | Y14: 0 | Z14: 0 | AA14: 0 | AB14: 0 | AC14: 0 | AD14: 0 | AE14: 0 | AF14: 0 | AG14: 0 | AH14: 0 | AI14: 0 | AJ14: 0 | AK14: 0 | AL14: 0 | AM14: 0 | AN14: 0
C15: =Dashboard!B17 -> LANDING PAGE | D15: =Dashboard!E17*Dashboard!$P$9 -> 60000000 | E15: =SUM(E16:E20) -> 0 | F15: =D15-E15 -> 60000000 | G15: =_xlfn.IFS(F15>0,1,F15<=0,D15/E15) -> 1 | H15: =D15/'Action Plan'!$C$6 -> 2307692.3 | I15: =SUM(I16:I20) -> 0 | J15: =SUM(J16:J20) -> 0 | K15: =SUM(K16:K20) -> 0 | L15: =SUM(L16:L20) -> 0 | M15: =SUM(M16:M20) -> 0 | N15: =SUM(N16:N20) -> 0 | O15: =SUM(O16:O20) -> 0 | P15: =SUM(P16:P20) -> 0 | ... AN15: =SUM(AN16:AN20) -> 0
C16: VISION | D16: =$D$15/8 -> 7500000 | E16: =SUM(J16:AN16) -> 0 | F16: =D16-E16 -> 7500000 | I16: =SUMIF($J$5:$AN$5,TODAY(),J16:AN16) -> 0 | J16: 0 | K16: 0 | L16: 0 | M16: 0 | N16: 0 | O16: 0 | P16: 0 | Q16: 0 | R16: 0 | S16: 0 | T16: 0 | U16: 0 | V16: 0 | W16: 0 | X16: 0 | Y16: 0 | Z16: 0 | AA16: 0 | AB16: 0 | AC16: 0 | AD16: 0 | AE16: 0 | AF16: 0 | AG16: 0 | AH16: 0 | AI16: 0 | AJ16: 0 | AK16: 0 | AL16: 0 | AM16: 0 | AN16: 0
C17: BLACKHAIR | D17: =$D$15/8 -> 7500000 | E17: =SUM(J17:AN17) -> 0 | F17: =D17-E17 -> 7500000 | I17: =SUMIF($J$5:$AN$5,TODAY(),J17:AN17) -> 0 | J17: 0 | K17: 0 | L17: 0 | M17: 0 | N17: 0 | O17: 0 | P17: 0 | Q17: 0 | R17: 0 | S17: 0 | T17: 0 | U17: 0 | V17: 0 | W17: 0 | X17: 0 | Y17: 0 | Z17: 0 | AA17: 0 | AB17: 0 | AC17: 0 | AD17: 0 | AE17: 0 | AF17: 0 | AG17: 0 | AH17: 0 | AI17: 0 | AJ17: 0 | AK17: 0 | AL17: 0 | AM17: 0 | AN17: 0
C18: GLUTAWHITE | D18: =$D$15/8 -> 7500000 | E18: =SUM(J18:AN18) -> 0 | F18: =D18-E18 -> 7500000 | I18: =SUMIF($J$5:$AN$5,TODAY(),J18:AN18) -> 0 | J18: 0 | K18: 0 | L18: 0 | M18: 0 | N18: 0 | O18: 0 | P18: 0 | Q18: 0 | R18: 0 | S18: 0 | T18: 0 | U18: 0 | V18: 0 | W18: 0 | X18: 0 | Y18: 0 | Z18: 0 | AA18: 0 | AB18: 0 | AC18: 0 | AD18: 0 | AE18: 0 | AF18: 0 | AG18: 0 | AH18: 0 | AI18: 0 | AJ18: 0 | AK18: 0 | AL18: 0 | AM18: 0 | AN18: 0
C19: GLUTATHION | D19: =$D$15/8 -> 7500000 | E19: =SUM(J19:AN19) -> 0 | F19: =D19-E19 -> 7500000 | I19: =SUMIF($J$5:$AN$5,TODAY(),J19:AN19) -> 0 | J19: 0 | K19: 0 | L19: 0 | M19: 0 | N19: 0 | O19: 0 | P19: 0 | Q19: 0 | R19: 0 | S19: 0 | T19: 0 | U19: 0 | V19: 0 | W19: 0 | X19: 0 | Y19: 0 | Z19: 0 | AA19: 0 | AB19: 0 | AC19: 0 | AD19: 0 | AE19: 0 | AF19: 0 | AG19: 0 | AH19: 0 | AI19: 0 | AJ19: 0 | AK19: 0 | AL19: 0 | AM19: 0 | AN19: 0
C20: CORDY | D20: =$D$15/8 -> 7500000 | E20: =SUM(J20:AN20) -> 0 | F20: =D20-E20 -> 7500000 | I20: =SUMIF($J$5:$AN$5,TODAY(),J20:AN20) -> 0 | J20: 0 | K20: 0 | L20: 0 | M20: 0 | N20: 0 | O20: 0 | P20: 0 | Q20: 0 | R20: 0 | S20: 0 | T20: 0 | U20: 0 | V20: 0 | W20: 0 | X20: 0 | Y20: 0 | Z20: 0 | AA20: 0 | AB20: 0 | AC20: 0 | AD20: 0 | AE20: 0 | AF20: 0 | AG20: 0 | AH20: 0 | AI20: 0 | AJ20: 0 | AK20: 0 | AL20: 0 | AM20: 0 | AN20: 0
C21: =Dashboard!B18 -> WEBSITE | D21: =Dashboard!E18*Dashboard!$P$9 -> 10000000 | E21: =SUM(E22:E23) -> 0 | F21: =D21-E21 -> 10000000 | G21: =_xlfn.IFS(F21>0,1,F21<=0,D21/E21) -> 1 | H21: =D21/'Action Plan'!$C$6 -> 384615.38 | I21: =SUM(I22:I23) -> 0 | J21: =SUM(J22:J23) -> 0 | K21: =SUM(K22:K23) -> 0 | L21: =SUM(L22:L23) -> 0 | M21: =SUM(M22:M23) -> 0 | N21: =SUM(N22:N23) -> 0 | O21: =SUM(O22:O23) -> 0 | P21: =SUM(P22:P23) -> 0 | ... AN21: =SUM(AN22:AN23) -> 0
C22: HBPHARMA | D22: =$D$21/6 -> 1666666.7 | E22: =SUM(J22:AN22) -> 0 | F22: =D22-E22 -> 1666666.7 | H22: =D22/'Action Plan'!$C$6 -> 64102.564 | I22: =SUMIF($J$5:$AN$5,TODAY(),J22:AN22) -> 0 | J22: 0 | K22: 0 | L22: 0 | M22: 0 | N22: 0 | O22: 0 | P22: 0 | Q22: 0 | R22: 0 | S22: 0 | T22: 0 | U22: 0 | V22: 0 | W22: 0 | X22: 0 | Y22: 0 | Z22: 0 | AA22: 0 | AB22: 0 | AC22: 0 | AD22: 0 | AE22: 0 | AF22: 0 | AG22: 0 | AH22: 0 | AI22: 0 | AJ22: 0 | AK22: 0 | AL22: 0 | AM22: 0 | AN22: 0
C23: HOTLINE | D23: =$D$21/6 -> 1666666.7 | E23: =SUM(J23:AN23) -> 0 | F23: =D23-E23 -> 1666666.7 | H23: =D23/'Action Plan'!$C$6 -> 64102.564 | I23: =SUMIF($J$5:$AN$5,TODAY(),J23:AN23) -> 0 | J23: 0 | K23: 0 | L23: 0 | M23: 0 | N23: 0 | O23: 0 | P23: 0 | Q23: 0 | R23: 0 | S23: 0 | T23: 0 | U23: 0 | V23: 0 | W23: 0 | X23: 0 | Y23: 0 | Z23: 0 | AA23: 0 | AB23: 0 | AC23: 0 | AD23: 0 | AE23: 0 | AF23: 0 | AG23: 0 | AH23: 0 | AI23: 0 | AJ23: 0 | AK23: 0 | AL23: 0 | AM23: 0 | AN23: 0
C24: =Dashboard!B19 -> TIKTOK SHOP | D24: =Dashboard!E19*Dashboard!$P$9 -> 20000000 | E24: =SUM(J24:AN24) -> 6100000 | F24: =D24-E24 -> 13900000 | G24: =_xlfn.IFS(F24>0,1,F24<=0,D24/E24) -> 1 | H24: =D24/'Action Plan'!$C$6 -> 769230.77 | I24: =SUMIF($J$5:$AN$5,TODAY(),J24:AN24) -> 0 | J24: 200000 | K24: 200000 | L24: 200000 | M24: 200000 | N24: 200000 | O24: 200000 | P24: 200000 | Q24: 200000 | R24: 200000 | S24: 200000 | T24: 200000 | U24: 200000 | V24: 200000 | W24: 200000 | X24: 200000 | Y24: 200000 | Z24: 200000 | AA24: 200000 | AB24: 200000 | AC24: 200000 | AD24: 200000 | AE24: 200000 | AF24: 200000 | AG24: 200000 | AH24: 200000 | AI24: 200000 | AJ24: 200000 | AK24: 200000 | AL24: 200000 | AM24: 200000 | AN24: 100000
C25: =Dashboard!B20 -> SHOPEE | D25: =Dashboard!E20*Dashboard!$P$8 -> 10000000 | E25: =SUM(J25:AN25) -> 6100000 | F25: =D25-E25 -> 3900000 | G25: =_xlfn.IFS(F25>0,1,F25<=0,D25/E25) -> 1 | H25: =D25/'Action Plan'!$C$6 -> 384615.38 | I25: =SUMIF($J$5:$AN$5,TODAY(),J25:AN25) -> 0 | J25: 200000 | K25: 200000 | L25: 200000 | M25: 200000 | N25: 200000 | O25: 200000 | P25: 200000 | Q25: 200000 | R25: 200000 | S25: 200000 | T25: 200000 | U25: 200000 | V25: 200000 | W25: 200000 | X25: 200000 | Y25: 200000 | Z25: 200000 | AA25: 200000 | AB25: 200000 | AC25: 200000 | AD25: 200000 | AE25: 200000 | AF25: 200000 | AG25: 200000 | AH25: 200000 | AI25: 200000 | AJ25: 200000 | AK25: 200000 | AL25: 200000 | AM25: 200000 | AN25: 100000
C26: =Dashboard!B21 -> ZALO | D26: =Dashboard!E21*Dashboard!$P$9 -> 40000000 | E26: =SUM(J26:AN26) -> 100000 | F26: =D26-E26 -> 39900000 | G26: =_xlfn.IFS(F26>0,1,F26<=0,D26/E26) -> 1 | H26: =D26/'Action Plan'!$C$6 -> 1538461.5 | I26: =SUMIF($J$5:$AN$5,TODAY(),J26:AN26) -> 0 | J26: 0 | K26: 0 | L26: 0 | M26: 0 | N26: 0 | O26: 0 | P26: 0 | Q26: 0 | R26: 0 | S26: 0 | T26: 0 | U26: 0 | V26: 0 | W26: 0 | X26: 0 | Y26: 0 | Z26: 0 | AA26: 0 | AB26: 0 | AC26: 0 | AD26: 0 | AE26: 0 | AF26: 0 | AG26: 0 | AH26: 0 | AI26: 0 | AJ26: 0 | AK26: 0 | AL26: 0 | AM26: 0 | AN26: 100000
C27: =Dashboard!B22 -> BOOKING | D27: =Dashboard!E21*Dashboard!$P$9 -> 40000000 | E27: =SUM(J27:AN27) -> 3000000 | F27: =D27-E27 -> 37000000 | G27: =_xlfn.IFS(F27>0,1,F27<=0,D27/E27) -> 1 | H27: =D27/'Action Plan'!$C$6 -> 1538461.5 | I27: =SUMIF($J$5:$AN$5,TODAY(),J27:AN27) -> 0 | J27: 100000 | K27: 100000 | L27: 100000 | M27: 100000 | N27: 100000 | O27: 100000 | P27: 100000 | Q27: 100000 | R27: 100000 | S27: 100000 | T27: 100000 | U27: 100000 | V27: 100000 | W27: 100000 | X27: 100000 | Y27: 100000 | Z27: 100000 | AA27: 100000 | AB27: 100000 | AC27: 100000 | AD27: 100000 | AE27: 100000 | AF27: 100000 | AG27: 100000 | AH27: 100000 | AI27: 100000 | AJ27: 100000 | AK27: 100000 | AL27: 100000 | AM27: 100000 | AN27: 0
C28: =Dashboard!B23 -> BRANDING | D28: =Dashboard!E22*Dashboard!$P$9 -> 10000000 | E28: =SUM(J28:AN28) -> 1500000 | F28: =D28-E28 -> 8500000 | G28: =_xlfn.IFS(F28>0,1,F28<=0,D28/E28) -> 1 | H28: =D28/'Action Plan'!$C$6 -> 384615.38 | I28: =SUMIF($J$5:$AN$5,TODAY(),J28:AN28) -> 0 | J28: 50000 | K28: 50000 | L28: 50000 | M28: 50000 | N28: 50000 | O28: 50000 | P28: 50000 | Q28: 50000 | R28: 50000 | S28: 50000 | T28: 50000 | U28: 50000 | V28: 50000 | W28: 50000 | X28: 50000 | Y28: 50000 | Z28: 50000 | AA28: 50000 | AB28: 50000 | AC28: 50000 | AD28: 50000 | AE28: 50000 | AF28: 50000 | AG28: 50000 | AH28: 50000 | AI28: 50000 | AJ28: 50000 | AK28: 50000 | AL28: 50000 | AM28: 50000 | AN28: 0
C29: =Dashboard!K52 -> P2
C30: DATA | D30: =Dashboard!E53 -> 1680 | E30: =Dashboard!F53 -> 1528 | F30: =E30-D30 -> -152 | G30: =_xlfn.IFS(F30>0,1,F30<0,E30/D30,F30=0,0) -> 0.90952381 | H30: =D30/'Action Plan'!$C$6 -> 64.615385 | I30: =SUMIF($J$5:$AN$5,TODAY(),J30:AN30) -> 0 | J30: =J31 -> 13 | K30: =K31 -> 13 | L30: =L31 -> 13 | M30: =M31 -> 13 | N30: =N31 -> 13 | O30: =O31 -> 13 | P30: =P31 -> 13 | Q30: =Q31 -> 13 | ... AN30: =AN31 -> 13
C31: =Dashboard!K53 -> DATA | D31: =Dashboard!U53 -> 572 | E31: =SUM(E32:E37) -> 403 | F31: =E31-D31 -> -169 | G31: =_xlfn.IFS(F31>0,1,F31<0,E31/D31,F31=0,0) -> 0.70454545 | H31: =D31/'Action Plan'!$C$6 -> 22 | I31: =SUM(I32:I37) -> 0 | J31: =SUM(J32:J37) -> 13 | K31: =SUM(K32:K37) -> 13 | L31: =SUM(L32:L37) -> 13 | M31: =SUM(M32:M37) -> 13 | N31: =SUM(N32:N37) -> 13 | O31: =SUM(O32:O37) -> 13 | P31: =SUM(P32:P37) -> 13 | ... AN31: =SUM(AN32:AN37) -> 13
C32: =Dashboard!K54 -> FACEBOOK | D32: =Dashboard!U54 -> -87 | E32: =SUM(J32:AN32) -> 62 | F32: =E32-D32 -> 149 | G32: =_xlfn.IFS(F32>0,1,F32<0,E32/D32,F32=0,0) -> 1 | H32: =D32/'Action Plan'!$C$6 -> -3.3461538 | I32: =SUMIF($J$5:$AN$5,TODAY(),J32:AN32) -> 0 | J32: 2 | K32: 2 | L32: 2 | M32: 2 | N32: 2 | O32: 2 | P32: 2 | Q32: 2 | R32: 2 | S32: 2 | T32: 2 | U32: 2 | V32: 2 | W32: 2 | X32: 2 | Y32: 2 | Z32: 2 | AA32: 2 | AB32: 2 | AC32: 2 | AD32: 2 | AE32: 2 | AF32: 2 | AG32: 2 | AH32: 2 | AI32: 2 | AJ32: 2 | AK32: 2 | AL32: 2 | AM32: 2 | AN32: 2
C33: =Dashboard!K55 -> LANDING PAGE | D33: =Dashboard!U55 -> 48 | E33: =SUM(J33:AN33) -> 31 | F33: =E33-D33 -> -17 | G33: =_xlfn.IFS(F33>0,1,F33<0,E33/D33,F33=0,0) -> 0.64583333 | H33: =D33/'Action Plan'!$C$6 -> 1.8461538 | I33: =SUMIF($J$5:$AN$5,TODAY(),J33:AN33) -> 0 | J33: 1 | K33: 1 | L33: 1 | M33: 1 | N33: 1 | O33: 1 | P33: 1 | Q33: 1 | R33: 1 | S33: 1 | T33: 1 | U33: 1 | V33: 1 | W33: 1 | X33: 1 | Y33: 1 | Z33: 1 | AA33: 1 | AB33: 1 | AC33: 1 | AD33: 1 | AE33: 1 | AF33: 1 | AG33: 1 | AH33: 1 | AI33: 1 | AJ33: 1 | AK33: 1 | AL33: 1 | AM33: 1 | AN33: 1
C34: =Dashboard!K56 -> WEBSITE | D34: =Dashboard!U56 -> 25 | E34: =SUM(J34:AN34) -> 31 | F34: =E34-D34 -> 6 | G34: =_xlfn.IFS(F34>0,1,F34<0,E34/D34,F34=0,0) -> 1 | H34: =D34/'Action Plan'!$C$6 -> 0.96153846 | I34: =SUMIF($J$5:$AN$5,TODAY(),J34:AN34) -> 0 | J34: 1 | K34: 1 | L34: 1 | M34: 1 | N34: 1 | O34: 1 | P34: 1 | Q34: 1 | R34: 1 | S34: 1 | T34: 1 | U34: 1 | V34: 1 | W34: 1 | X34: 1 | Y34: 1 | Z34: 1 | AA34: 1 | AB34: 1 | AC34: 1 | AD34: 1 | AE34: 1 | AF34: 1 | AG34: 1 | AH34: 1 | AI34: 1 | AJ34: 1 | AK34: 1 | AL34: 1 | AM34: 1 | AN34: 1
C35: =Dashboard!K57 -> TIKTOKSHOP | D35: =Dashboard!U57 -> 263 | E35: =SUM(J35:AN35) -> 0 | F35: =E35-D35 -> -263 | G35: =_xlfn.IFS(F35>0,1,F35<0,E35/D35,F35=0,0) -> 0 | H35: =D35/'Action Plan'!$C$6 -> 10.115385 | I35: =SUMIF($J$5:$AN$5,TODAY(),J35:AN35) -> 0 | J35: 0 | K35: 0 | L35: 0 | M35: 0 | N35: 0 | O35: 0 | P35: 0 | Q35: 0 | R35: 0 | S35: 0 | T35: 0 | U35: 0 | V35: 0 | W35: 0 | X35: 0 | Y35: 0 | Z35: 0 | AA35: 0 | AB35: 0 | AC35: 0 | AD35: 0 | AE35: 0 | AF35: 0 | AG35: 0 | AH35: 0 | AI35: 0 | AJ35: 0 | AK35: 0 | AL35: 0 | AM35: 0 | AN35: 0
C36: =Dashboard!K58 -> SHOPPEE | D36: =Dashboard!U58 -> 298 | E36: =SUM(J36:AN36) -> 124 | F36: =E36-D36 -> -174 | G36: =_xlfn.IFS(F36>0,1,F36<0,E36/D36,F36=0,0) -> 0.41610738 | H36: =D36/'Action Plan'!$C$6 -> 11.461538 | I36: =SUMIF($J$5:$AN$5,TODAY(),J36:AN36) -> 0 | J36: 4 | K36: 4 | L36: 4 | M36: 4 | N36: 4 | O36: 4 | P36: 4 | Q36: 4 | R36: 4 | S36: 4 | T36: 4 | U36: 4 | V36: 4 | W36: 4 | X36: 4 | Y36: 4 | Z36: 4 | AA36: 4 | AB36: 4 | AC36: 4 | AD36: 4 | AE36: 4 | AF36: 4 | AG36: 4 | AH36: 4 | AI36: 4 | AJ36: 4 | AK36: 4 | AL36: 4 | AM36: 4 | AN36: 4
C37: =Dashboard!K59 -> ZALO | D37: =Dashboard!U59 -> 25 | E37: =SUM(J37:AN37) -> 155 | F37: =E37-D37 -> 130 | G37: =_xlfn.IFS(F37>0,1,F37<0,E37/D37,F37=0,0) -> 1 | H37: =D37/'Action Plan'!$C$6 -> 0.96153846 | I37: =SUMIF($J$5:$AN$5,TODAY(),J37:AN37) -> 0 | J37: 5 | K37: 5 | L37: 5 | M37: 5 | N37: 5 | O37: 5 | P37: 5 | Q37: 5 | R37: 5 | S37: 5 | T37: 5 | U37: 5 | V37: 5 | W37: 5 | X37: 5 | Y37: 5 | Z37: 5 | AA37: 5 | AB37: 5 | AC37: 5 | AD37: 5 | AE37: 5 | AF37: 5 | AG37: 5 | AH37: 5 | AI37: 5 | AJ37: 5 | AK37: 5 | AL37: 5 | AM37: 5 | AN37: 5
