Workbook
Name ACTIVITIES_OVERVIEW: #REF!
Name Application: #REF!
Name Category: #REF!
Name Frequency: #REF!
Name GERMAN_BUND: #REF!
Name GERMAN_INFLATION: #REF!
Name RATE: #REF!
Name Things: '[1]Dropdown lists'!#REF!
Name US_INFLATION: #REF!
Name US_RISK_FREE_RATE: #REF!

Sheet Work Schedule
A1: WORK SCHEDULE | C1: 45992 | D1: Marketing Dept
A2: WEEK 1 | B2: Person | C2: =CHOOSE(COLUMN()-COLUMN($C$2)+1, "Monday","Tuesday","Wednesday","Thursday","Friday","Saturday","Sunday") -> Monday | D2: Tuesday | E2: Wednesday | F2: Thursday | G2: Friday | H2: Saturday | I2: Sunday
C3: {=_xlfn.SEQUENCE(1,7,$C$1-WEEKDAY($C$1,2)+1,1)} -> 45992 | D3: 45993 | E3: 45994 | F3: 45995 | G3: 45996 | H3: 45997 | I3: 45998
B4: Tuyen Nguyen | C4: 08:30 - 18:00 | D4: 08:30 - 18:00 | E4: 08:30 - 18:00 | F4: 08:30 - 18:00 | G4: 08:30 - 18:00 | H4: 08:30 - 18:00
B5: Tan Nguyen | C5: 08:00 - 17:00 | D5: 08:00 - 17:00 | E5: 08:00 - 17:00 | F5: 08:00 - 17:00 | G5: 08:00 - 17:00 | H5: 08:00 - 17:00
B6: Hung Lu | C6: 08:00 - 17:00 | D6: 08:00 - 17:00 | E6: 08:00 - 17:00 | F6: 08:00 - 17:00 | G6: 08:00 - 17:00 | H6: 08:00 - 17:00
B7: Person #4 | C7: 08:00 - 17:30 | D7: 08:00 - 17:30 | E7: 08:00 - 17:30 | F7: 08:00 - 17:30 | G7: 08:00 - 17:30 | H7: 08:00 - 17:30
A9: WEEK 2 | B9: Person | C9: =CHOOSE(COLUMN()-COLUMN($C$2)+1, "Monday","Tuesday","Wednesday","Thursday","Friday","Saturday","Sunday") -> Monday | D9: Tuesday | E9: Wednesday | F9: Thursday | G9: Friday | H9: Saturday | I9: Sunday
C10: {=_xlfn.SEQUENCE(1,7,$C$1-WEEKDAY($C$1,2)+1+7,1)} -> 45999 | D10: 46000 | E10: 46001 | F10: 46002 | G10: 46003 | H10: 46004 | I10: 46005
B11: Tuyen Nguyen | C11: 08:30 - 18:00 | D11: 08:30 - 18:00 | E11: 08:30 - 18:00 | F11: 08:30 - 18:00 | G11: 08:30 - 18:00 | H11: 08:30 - 18:00
B12: Tan Nguyen | C12: 08:00 - 17:00 | D12: 08:00 - 17:00 | E12: 08:00 - 17:00 | F12: 08:00 - 17:00 | G12: 08:00 - 17:00 | H12: 08:00 - 17:00
B13: Hung Lu | C13: 08:00 - 17:00 | D13: 08:00 - 17:00 | E13: 08:00 - 17:00 | F13: 08:00 - 17:00 | G13: 08:00 - 17:00 | H13: 08:00 - 17:00
B14: Person #4 | C14: 08:00 - 17:30 | D14: 08:00 - 17:30 | E14: 08:00 - 17:30 | F14: 08:00 - 17:30 | G14: 08:00 - 17:30 | H14: 08:00 - 17:30
A16: WEEK 3 | B16: Person | C16: =CHOOSE(COLUMN()-COLUMN($C$2)+1, "Monday","Tuesday","Wednesday","Thursday","Friday","Saturday","Sunday") -> Monday | D16: Tuesday | E16: Wednesday | F16: Thursday | G16: Friday | H16: Saturday | I16: Sunday
C17: {=_xlfn.SEQUENCE(1,7,$C$1-WEEKDAY($C$1,2)+1+14,1)} -> 46006 | D17: 46007 | E17: 46008 | F17: 46009 | G17: 46010 | H17: 46011 | I17: 46012
B18: Tuyen Nguyen | C18: 08:30 - 18:00 | D18: 08:30 - 18:00 | E18: 08:30 - 18:00 | F18: 08:30 - 18:00 | G18: 08:30 - 18:00 | H18: 08:30 - 18:00
B19: Tan Nguyen | C19: 08:00 - 17:00 | D19: 08:00 - 17:00 | E19: 08:00 - 17:00 | F19: 08:00 - 17:00 | G19: 08:00 - 17:00 | H19: 08:00 - 17:00
B20: Hung Lu | C20: 08:00 - 17:00 | D20: 08:00 - 17:00 | E20: 08:00 - 17:00 | F20: 08:00 - 17:00 | G20: 08:00 - 17:00 | H20: 08:00 - 17:00
B21: Person #4 | C21: 08:00 - 17:30 | D21: 08:00 - 17:30 | E21: 08:00 - 17:30 | F21: 08:00 - 17:30 | G21: 08:00 - 17:30 | H21: 08:00 - 17:30
A23: WEEK 4 | B23: Person | C23: =CHOOSE(COLUMN()-COLUMN($C$2)+1, "Monday","Tuesday","Wednesday","Thursday","Friday","Saturday","Sunday") -> Monday | D23: Tuesday | E23: Wednesday | F23: Thursday | G23: Friday | H23: Saturday | I23: Sunday
C24: {=_xlfn.SEQUENCE(1,7,$C$1-WEEKDAY($C$1,2)+1+21,1)} -> 46013 | D24: 46014 | E24: 46015 | F24: 46016 | G24: 46017 | H24: 46018 | I24: 46019
B25: Tuyen Nguyen | C25: 08:30 - 18:00 | D25: 08:30 - 18:00 | E25: 08:30 - 18:00 | F25: 08:30 - 18:00 | G25: 08:30 - 18:00 | H25: 08:30 - 18:00
B26: Tan Nguyen | C26: 08:00 - 17:00 | D26: 08:00 - 17:00 | E26: 08:00 - 17:00 | F26: 08:00 - 17:00 | G26: 08:00 - 17:00 | H26: 08:00 - 17:00
B27: Hung Lu | C27: 08:00 - 17:00 | D27: 08:00 - 17:00 | E27: 08:00 - 17:00 | F27: 08:00 - 17:00 | G27: 08:00 - 17:00 | H27: 08:00 - 17:00
B28: Person #4 | C28: 08:00 - 17:30 | D28: 08:00 - 17:30 | E28: 08:00 - 17:30 | F28: 08:00 - 17:30 | G28: 08:00 - 17:30 | H28: 08:00 - 17:30
A30: WEEK 5 | B30: Person | C30: =CHOOSE(COLUMN()-COLUMN($C$2)+1, "Monday","Tuesday","Wednesday","Thursday","Friday","Saturday","Sunday") -> Monday | D30: Tuesday | E30: Wednesday | F30: Thursday | G30: Friday | H30: Saturday | I30: Sunday
C31: {=_xlfn.SEQUENCE(1,7,$C$1-WEEKDAY($C$1,2)+1+28,1)} -> 46020 | D31: 46021 | E31: 46022 | F31: 46023 | G31: 46024 | H31: 46025 | I31: 46026
B32: Tuyen Nguyen | C32: 08:30 - 18:00 | D32: 08:30 - 18:00 | E32: 08:30 - 18:00 | F32: 08:30 - 18:00 | G32: 08:30 - 18:00 | H32: 08:30 - 18:00
B33: Tan Nguyen | C33: 08:00 - 17:00 | D33: 08:00 - 17:00 | E33: 08:00 - 17:00 | F33: 08:00 - 17:00 | G33: 08:00 - 17:00 | H33: 08:00 - 17:00
B34: Hung Lu | C34: 08:00 - 17:00 | D34: 08:00 - 17:00 | E34: 08:00 - 17:00 | F34: 08:00 - 17:00 | G34: 08:00 - 17:00 | H34: 08:00 - 17:00
B35: Person #4 | C35: 08:00 - 17:30 | D35: 08:00 - 17:30 | E35: 08:00 - 17:30 | F35: 08:00 - 17:30 | G35: 08:00 - 17:30 | H35: 08:00 - 17:30

Sheet Marketing Executive
A1: WORK SCHEDULE | C1: 45992 | D1: ='Work Schedule'!B4 -> Tuyen Nguyen | E1: Marketing Executive
A2: WEEK 1 | B2: Person | C2: =CHOOSE(COLUMN()-COLUMN($C$2)+1, "Monday","Tuesday","Wednesday","Thursday","Friday","Saturday","Sunday") -> Monday | D2: =CHOOSE(COLUMN()-COLUMN($C$2)+1, "Monday","Tuesday","Wednesday","Thursday","Friday","Saturday","Sunday") -> Tuesday | E2: =CHOOSE(COLUMN()-COLUMN($C$2)+1, "Monday","Tuesday","Wednesday","Thursday","Friday","Saturday","Sunday") -> Wednesday | F2: =CHOOSE(COLUMN()-COLUMN($C$2)+1, "Monday","Tuesday","Wednesday","Thursday","Friday","Saturday","Sunday") -> Thursday | G2: =CHOOSE(COLUMN()-COLUMN($C$2)+1, "Monday","Tuesday","Wednesday","Thursday","Friday","Saturday","Sunday") -> Friday | H2: =CHOOSE(COLUMN()-COLUMN($C$2)+1, "Monday","Tuesday","Wednesday","Thursday","Friday","Saturday","Sunday") -> Saturday | I2: =CHOOSE(COLUMN()-COLUMN($C$2)+1, "Monday","Tuesday","Wednesday","Thursday","Friday","Saturday","Sunday") -> Sunday
B3: =$D$1 -> Tuyen Nguyen | C3: {=_xlfn.SEQUENCE(1,7,$C$1-WEEKDAY($C$1,2)+1,1)} -> 45992 | D3: 45993 | E3: 45994 | F3: 45995 | G3: 45996 | H3: 45997 | I3: 45998
B4: =$E$1 -> Marketing Executive | C4: 08:30 - 18:00 | D4: 08:30 - 18:00 | E4: 08:30 - 18:00 | F4: 08:30 - 18:00 | G4: 08:30 - 18:00 | H4: 08:30 - 18:00
B5: Task #1 | C5: ABC | D5: 123
B6: Task #2 | C6: XYZ
B7: Task #3
B8: Task #4
B9: Task #5
B10: Task #6
B11: Task #7
A13: WEEK 2 | B13: Person | C13: =CHOOSE(COLUMN()-COLUMN($C$2)+1, "Monday","Tuesday","Wednesday","Thursday","Friday","Saturday","Sunday") -> Monday | D13: Tuesday | E13: Wednesday | F13: Thursday | G13: Friday | H13: Saturday | I13: Sunday
B14: =$D$1 -> Tuyen Nguyen | C14: {=_xlfn.SEQUENCE(1,7,$C$1-WEEKDAY($C$1,2)+1+7,1)} -> 45999 | D14: 46000 | E14: 46001 | F14: 46002 | G14: 46003 | H14: 46004 | I14: 46005
B15: =$E$1 -> Marketing Executive | C15: 08:30 - 18:00 | D15: 08:30 - 18:00 | E15: 08:30 - 18:00 | F15: 08:30 - 18:00 | G15: 08:30 - 18:00 | H15: 08:30 - 18:00
B16: Task #1
B17: Task #2
B18: Task #3
B19: Task #4
B20: Task #5
B21: Task #6
B22: Task #7
A24: WEEK 3 | B24: Person | C24: =CHOOSE(COLUMN()-COLUMN($C$2)+1, "Monday","Tuesday","Wednesday","Thursday","Friday","Saturday","Sunday") -> Monday | D24: Tuesday | E24: Wednesday | F24: Thursday | G24: Friday | H24: Saturday | I24: Sunday
B25: =$D$1 -> Tuyen Nguyen | C25: {=_xlfn.SEQUENCE(1,7,$C$1-WEEKDAY($C$1,2)+1+14,1)} -> 46006 | D25: 46007 | E25: 46008 | F25: 46009 | G25: 46010 | H25: 46011 | I25: 46012
B26: =$E$1 -> Marketing Executive | C26: 08:30 - 18:00 | D26: 08:30 - 18:00 | E26: 08:30 - 18:00 | F26: 08:30 - 18:00 | G26: 08:30 - 18:00 | H26: 08:30 - 18:00
B27: Task #1
B28: Task #2
B29: Task #3
B30: Task #4
B31: Task #5
B32: Task #6
B33: Task #7
A35: WEEK 4 | B35: Person | C35: =CHOOSE(COLUMN()-COLUMN($C$2)+1, "Monday","Tuesday","Wednesday","Thursday","Friday","Saturday","Sunday") -> Monday | D35: Tuesday | E35: Wednesday | F35: Thursday | G35: Friday | H35: Saturday | I35: Sunday
B36: =$D$1 -> Tuyen Nguyen | C36: {=_xlfn.SEQUENCE(1,7,$C$1-WEEKDAY($C$1,2)+1+21,1)} -> 46013 | D36: 46014 | E36: 46015 | F36: 46016 | G36: 46017 | H36: 46018 | I36: 46019
B37: =$E$1 -> Marketing Executive | C37: 08:30 - 18:00 | D37: 08:30 - 18:00 | E37: 08:30 - 18:00 | F37: 08:30 - 18:00 | G37: 08:30 - 18:00 | H37: 08:30 - 18:00
B38: Task #1
B39: Task #2
B40: Task #3
B41: Task #4
B42: Task #5
B43: Task #6
...

Sheet Content Marketer
A1: WORK SCHEDULE | C1: 45992 | D1: ='Work Schedule'!B5 -> Tan Nguyen | E1: Content Marketer
A2: WEEK 1 | B2: Person | C2: =CHOOSE(COLUMN()-COLUMN($C$2)+1, "Monday","Tuesday","Wednesday","Thursday","Friday","Saturday","Sunday") -> Monday | D2: =CHOOSE(COLUMN()-COLUMN($C$2)+1, "Monday","Tuesday","Wednesday","Thursday","Friday","Saturday","Sunday") -> Tuesday | E2: =CHOOSE(COLUMN()-COLUMN($C$2)+1, "Monday","Tuesday","Wednesday","Thursday","Friday","Saturday","Sunday") -> Wednesday | F2: =CHOOSE(COLUMN()-COLUMN($C$2)+1, "Monday","Tuesday","Wednesday","Thursday","Friday","Saturday","Sunday") -> Thursday | G2: =CHOOSE(COLUMN()-COLUMN($C$2)+1, "Monday","Tuesday","Wednesday","Thursday","Friday","Saturday","Sunday") -> Friday | H2: =CHOOSE(COLUMN()-COLUMN($C$2)+1, "Monday","Tuesday","Wednesday","Thursday","Friday","Saturday","Sunday") -> Saturday | I2: =CHOOSE(COLUMN()-COLUMN($C$2)+1, "Monday","Tuesday","Wednesday","Thursday","Friday","Saturday","Sunday") -> Sunday
B3: =$D$1 -> Tan Nguyen | C3: {=_xlfn.SEQUENCE(1,7,$C$1-WEEKDAY($C$1,2)+1,1)} -> 45992 | D3: 45993 | E3: 45994 | F3: 45995 | G3: 45996 | H3: 45997 | I3: 45998
B4: =$E$1 -> Content Marketer | C4: 08:30 - 18:00 | D4: 08:30 - 18:00 | E4: 08:30 - 18:00 | F4: 08:30 - 18:00 | G4: 08:30 - 18:00 | H4: 08:30 - 18:00
B5: Task #1 | C5: HHXXH
B6: Task #2 | C6: LKMA
B7: Task #3
B8: Task #4
B9: Task #5
B10: Task #6
B11: Task #7
A13: WEEK 2 | B13: Person | C13: =CHOOSE(COLUMN()-COLUMN($C$2)+1, "Monday","Tuesday","Wednesday","Thursday","Friday","Saturday","Sunday") -> Monday | D13: Tuesday | E13: Wednesday | F13: Thursday | G13: Friday | H13: Saturday | I13: Sunday
B14: =$D$1 -> Tan Nguyen | C14: {=_xlfn.SEQUENCE(1,7,$C$1-WEEKDAY($C$1,2)+1+7,1)} -> 45999 | D14: 46000 | E14: 46001 | F14: 46002 | G14: 46003 | H14: 46004 | I14: 46005
B15: =$E$1 -> Content Marketer | C15: 08:30 - 18:00 | D15: 08:30 - 18:00 | E15: 08:30 - 18:00 | F15: 08:30 - 18:00 | G15: 08:30 - 18:00 | H15: 08:30 - 18:00
B16: Task #1
B17: Task #2
B18: Task #3
B19: Task #4
B20: Task #5
B21: Task #6
B22: Task #7
A24: WEEK 3 | B24: Person | C24: =CHOOSE(COLUMN()-COLUMN($C$2)+1, "Monday","Tuesday","Wednesday","Thursday","Friday","Saturday","Sunday") -> Monday | D24: Tuesday | E24: Wednesday | F24: Thursday | G24: Friday | H24: Saturday | I24: Sunday
B25: =$D$1 -> Tan Nguyen | C25: {=_xlfn.SEQUENCE(1,7,$C$1-WEEKDAY($C$1,2)+1+14,1)} -> 46006 | D25: 46007 | E25: 46008 | F25: 46009 | G25: 46010 | H25: 46011 | I25: 46012
B26: =$E$1 -> Content Marketer | C26: 08:30 - 18:00 | D26: 08:30 - 18:00 | E26: 08:30 - 18:00 | F26: 08:30 - 18:00 | G26: 08:30 - 18:00 | H26: 08:30 - 18:00
B27: Task #1
B28: Task #2
B29: Task #3
B30: Task #4
B31: Task #5
B32: Task #6
B33: Task #7
A35: WEEK 4 | B35: Person | C35: =CHOOSE(COLUMN()-COLUMN($C$2)+1, "Monday","Tuesday","Wednesday","Thursday","Friday","Saturday","Sunday") -> Monday | D35: Tuesday | E35: Wednesday | F35: Thursday | G35: Friday | H35: Saturday | I35: Sunday
B36: =$D$1 -> Tan Nguyen | C36: {=_xlfn.SEQUENCE(1,7,$C$1-WEEKDAY($C$1,2)+1+21,1)} -> 46013 | D36: 46014 | E36: 46015 | F36: 46016 | G36: 46017 | H36: 46018 | I36: 46019
B37: =$E$1 -> Content Marketer | C37: 08:30 - 18:00 | D37: 08:30 - 18:00 | E37: 08:30 - 18:00 | F37: 08:30 - 18:00 | G37: 08:30 - 18:00 | H37: 08:30 - 18:00
B38: Task #1
B39: Task #2
B40: Task #3
B41: Task #4
B42: Task #5
B43: Task #6
...

Sheet Graphic Designer
A1: WORK SCHEDULE | C1: 45992 | D1: ='Work Schedule'!B6 -> Hung Lu | E1: Graphic Designer
A2: WEEK 1 | B2: Person | C2: =CHOOSE(COLUMN()-COLUMN($C$2)+1, "Monday","Tuesday","Wednesday","Thursday","Friday","Saturday","Sunday") -> Monday | D2: =CHOOSE(COLUMN()-COLUMN($C$2)+1, "Monday","Tuesday","Wednesday","Thursday","Friday","Saturday","Sunday") -> Tuesday | E2: =CHOOSE(COLUMN()-COLUMN($C$2)+1, "Monday","Tuesday","Wednesday","Thursday","Friday","Saturday","Sunday") -> Wednesday | F2: =CHOOSE(COLUMN()-COLUMN($C$2)+1, "Monday","Tuesday","Wednesday","Thursday","Friday","Saturday","Sunday") -> Thursday | G2: =CHOOSE(COLUMN()-COLUMN($C$2)+1, "Monday","Tuesday","Wednesday","Thursday","Friday","Saturday","Sunday") -> Friday | H2: =CHOOSE(COLUMN()-COLUMN($C$2)+1, "Monday","Tuesday","Wednesday","Thursday","Friday","Saturday","Sunday") -> Saturday | I2: =CHOOSE(COLUMN()-COLUMN($C$2)+1, "Monday","Tuesday","Wednesday","Thursday","Friday","Saturday","Sunday") -> Sunday
B3: =$D$1 -> Hung Lu | C3: {=_xlfn.SEQUENCE(1,7,$C$1-WEEKDAY($C$1,2)+1,1)} -> 45992 | D3: 45993 | E3: 45994 | F3: 45995 | G3: 45996 | H3: 45997 | I3: 45998
B4: =$E$1 -> Graphic Designer | C4: 08:30 - 18:00 | D4: 08:30 - 18:00 | E4: 08:30 - 18:00 | F4: 08:30 - 18:00 | G4: 08:30 - 18:00 | H4: 08:30 - 18:00
B5: Task #1
B6: Task #2
B7: Task #3
B8: Task #4
B9: Task #5
B10: Task #6
B11: Task #7
A13: WEEK 2 | B13: Person | C13: =CHOOSE(COLUMN()-COLUMN($C$2)+1, "Monday","Tuesday","Wednesday","Thursday","Friday","Saturday","Sunday") -> Monday | D13: Tuesday | E13: Wednesday | F13: Thursday | G13: Friday | H13: Saturday | I13: Sunday
B14: =$D$1 -> Hung Lu | C14: {=_xlfn.SEQUENCE(1,7,$C$1-WEEKDAY($C$1,2)+1+7,1)} -> 45999 | D14: 46000 | E14: 46001 | F14: 46002 | G14: 46003 | H14: 46004 | I14: 46005
B15: =$E$1 -> Graphic Designer | C15: 08:30 - 18:00 | D15: 08:30 - 18:00 | E15: 08:30 - 18:00 | F15: 08:30 - 18:00 | G15: 08:30 - 18:00 | H15: 08:30 - 18:00
B16: Task #1
B17: Task #2
B18: Task #3
B19: Task #4
B20: Task #5
B21: Task #6
B22: Task #7
A24: WEEK 3 | B24: Person | C24: =CHOOSE(COLUMN()-COLUMN($C$2)+1, "Monday","Tuesday","Wednesday","Thursday","Friday","Saturday","Sunday") -> Monday | D24: Tuesday | E24: Wednesday | F24: Thursday | G24: Friday | H24: Saturday | I24: Sunday
B25: =$D$1 -> Hung Lu | C25: {=_xlfn.SEQUENCE(1,7,$C$1-WEEKDAY($C$1,2)+1+14,1)} -> 46006 | D25: 46007 | E25: 46008 | F25: 46009 | G25: 46010 | H25: 46011 | I25: 46012
B26: =$E$1 -> Graphic Designer | C26: 08:30 - 18:00 | D26: 08:30 - 18:00 | E26: 08:30 - 18:00 | F26: 08:30 - 18:00 | G26: 08:30 - 18:00 | H26: 08:30 - 18:00
B27: Task #1
B28: Task #2
B29: Task #3
B30: Task #4
B31: Task #5
B32: Task #6
B33: Task #7
A35: WEEK 4 | B35: Person | C35: =CHOOSE(COLUMN()-COLUMN($C$2)+1, "Monday","Tuesday","Wednesday","Thursday","Friday","Saturday","Sunday") -> Monday | D35: Tuesday | E35: Wednesday | F35: Thursday | G35: Friday | H35: Saturday | I35: Sunday
B36: =$D$1 -> Hung Lu | C36: {=_xlfn.SEQUENCE(1,7,$C$1-WEEKDAY($C$1,2)+1+21,1)} -> 46013 | D36: 46014 | E36: 46015 | F36: 46016 | G36: 46017 | H36: 46018 | I36: 46019
B37: =$E$1 -> Graphic Designer | C37: 08:30 - 18:00 | D37: 08:30 - 18:00 | E37: 08:30 - 18:00 | F37: 08:30 - 18:00 | G37: 08:30 - 18:00 | H37: 08:30 - 18:00
B38: Task #1
B39: Task #2
B40: Task #3
B41: Task #4
B42: Task #5
B43: Task #6
...

Sheet Media Editor
A1: WORK SCHEDULE | C1: 45992 | D1: ='Work Schedule'!B14 -> Person #4 | E1: Media Editor
A2: WEEK 1 | B2: Person | C2: =CHOOSE(COLUMN()-COLUMN($C$2)+1, "Monday","Tuesday","Wednesday","Thursday","Friday","Saturday","Sunday") -> Monday | D2: =CHOOSE(COLUMN()-COLUMN($C$2)+1, "Monday","Tuesday","Wednesday","Thursday","Friday","Saturday","Sunday") -> Tuesday | E2: =CHOOSE(COLUMN()-COLUMN($C$2)+1, "Monday","Tuesday","Wednesday","Thursday","Friday","Saturday","Sunday") -> Wednesday | F2: =CHOOSE(COLUMN()-COLUMN($C$2)+1, "Monday","Tuesday","Wednesday","Thursday","Friday","Saturday","Sunday") -> Thursday | G2: =CHOOSE(COLUMN()-COLUMN($C$2)+1, "Monday","Tuesday","Wednesday","Thursday","Friday","Saturday","Sunday") -> Friday | H2: =CHOOSE(COLUMN()-COLUMN($C$2)+1, "Monday","Tuesday","Wednesday","Thursday","Friday","Saturday","Sunday") -> Saturday | I2: =CHOOSE(COLUMN()-COLUMN($C$2)+1, "Monday","Tuesday","Wednesday","Thursday","Friday","Saturday","Sunday") -> Sunday
B3: =$D$1 -> Person #4 | C3: {=_xlfn.SEQUENCE(1,7,$C$1-WEEKDAY($C$1,2)+1,1)} -> 45992 | D3: 45993 | E3: 45994 | F3: 45995 | G3: 45996 | H3: 45997 | I3: 45998
B4: =$E$1 -> Media Editor | C4: 08:30 - 18:00 | D4: 08:30 - 18:00 | E4: 08:30 - 18:00 | F4: 08:30 - 18:00 | G4: 08:30 - 18:00 | H4: 08:30 - 18:00
B5: Task #1
B6: Task #2
B7: Task #3
B8: Task #4
B9: Task #5
B10: Task #6
B11: Task #7
A13: WEEK 2 | B13: Person | C13: =CHOOSE(COLUMN()-COLUMN($C$2)+1, "Monday","Tuesday","Wednesday","Thursday","Friday","Saturday","Sunday") -> Monday | D13: Tuesday | E13: Wednesday | F13: Thursday | G13: Friday | H13: Saturday | I13: Sunday
B14: =$D$1 -> Person #4 | C14: {=_xlfn.SEQUENCE(1,7,$C$1-WEEKDAY($C$1,2)+1+7,1)} -> 45999 | D14: 46000 | E14: 46001 | F14: 46002 | G14: 46003 | H14: 46004 | I14: 46005
B15: =$E$1 -> Media Editor | C15: 08:30 - 18:00 | D15: 08:30 - 18:00 | E15: 08:30 - 18:00 | F15: 08:30 - 18:00 | G15: 08:30 - 18:00 | H15: 08:30 - 18:00
B16: Task #1
B17: Task #2
B18: Task #3
B19: Task #4
B20: Task #5
B21: Task #6
B22: Task #7
A24: WEEK 3 | B24: Person | C24: =CHOOSE(COLUMN()-COLUMN($C$2)+1, "Monday","Tuesday","Wednesday","Thursday","Friday","Saturday","Sunday") -> Monday | D24: Tuesday | E24: Wednesday | F24: Thursday | G24: Friday | H24: Saturday | I24: Sunday
B25: =$D$1 -> Person #4 | C25: {=_xlfn.SEQUENCE(1,7,$C$1-WEEKDAY($C$1,2)+1+14,1)} -> 46006 | D25: 46007 | E25: 46008 | F25: 46009 | G25: 46010 | H25: 46011 | I25: 46012
B26: =$E$1 -> Media Editor | C26: 08:30 - 18:00 | D26: 08:30 - 18:00 | E26: 08:30 - 18:00 | F26: 08:30 - 18:00 | G26: 08:30 - 18:00 | H26: 08:30 - 18:00
B27: Task #1
B28: Task #2
B29: Task #3
B30: Task #4
B31: Task #5
B32: Task #6
B33: Task #7
A35: WEEK 4 | B35: Person | C35: =CHOOSE(COLUMN()-COLUMN($C$2)+1, "Monday","Tuesday","Wednesday","Thursday","Friday","Saturday","Sunday") -> Monday | D35: Tuesday | E35: Wednesday | F35: Thursday | G35: Friday | H35: Saturday | I35: Sunday
B36: =$D$1 -> Person #4 | C36: {=_xlfn.SEQUENCE(1,7,$C$1-WEEKDAY($C$1,2)+1+21,1)} -> 46013 | D36: 46014 | E36: 46015 | F36: 46016 | G36: 46017 | H36: 46018 | I36: 46019
B37: =$E$1 -> Media Editor | C37: 08:30 - 18:00 | D37: 08:30 - 18:00 | E37: 08:30 - 18:00 | F37: 08:30 - 18:00 | G37: 08:30 - 18:00 | H37: 08:30 - 18:00
B38: Task #1
B39: Task #2
B40: Task #3
B41: Task #4
B42: Task #5
B43: Task #6
...

Sheet Tasks Tracking
A1: TASKS TRACKING
A2: YEAR | B2: 2026 | D2: Do not edit these highlighted cells | H2: {=IFERROR( _xlfn.LET( _xlpm.week,$B$4, _xlpm.dayIndex,INT((ROW()-ROW($H$6))/3)+1, _xlpm.rowDate,3+(_xlpm.week-1)*7, IF(_xlpm.dayIndex>6,"",INDEX('Marketing Executive'!$C:$H,_xlpm.rowDate,_xlpm.dayIndex)) ), "")}
A3: MONTH | B3: 1
A4: WEEK | B4: 1 | C4: Dropdown | D4: Fiil | F4: Dropdown | G4: Dropdown | I4: Fiil | K4: Fiil | L4: Dropdown | M4: Fiil | N4: Fiil | O4: Dropdown
A5: No | B5: Task Name | C5: Priority | D5: Description | E5: Owner | F5: Request | G5: Status | H5: Start Date | I5: Due Date | J5: Days Left | K5: Progress % | L5: Report To | M5: File/ Cloud | N5: Results/ Note | O5: Check
A6: 1 | B6: {=_xlfn.LET( _xlpm.week, $B$4, _xlpm.d, H6, _xlpm.nthTask, COUNTIF($H$6:H6, _xlpm.d), _xlpm.dateHeader, OFFSET('Marketing Executive'!$C$3, (_xlpm.week-1)*11, 0, 1, 7), _xlpm.taskRange, OFFSET('Marketing Executive'!$C$5, (_xlpm.week-1)*11, 0, 7, 7), _xlpm.colIndex, MATCH(_xlpm.d, _xlpm.dateHeader, 0), _xlpm.rawTask, IFERROR(INDEX(_xlpm.taskRange, _xlpm.nthTask, _xlpm.colIndex), ""), IF(OR(_xlpm.rawTask=0, _xlpm.rawTask="0"), "Task Unavailable", _xlpm.rawTask) )} -> ABC | C6: Low | E6: {=_xlfn.LET( _xlpm.week, $B$4, _xlpm.rowPerson, 3 + (_xlpm.week-1)*11, _xlpm.personName, INDEX('Marketing Executive'!$B:$B, _xlpm.rowPerson), IF($B6="", "", _xlpm.personName) )} -> Tuyen Nguyen | F6: Manager | G6: Under Review | H6: {=IFERROR( _xlfn.LET( _xlpm.week, $B$4, _xlpm.pos, ROW()-ROW($H$6), _xlpm.dayIndex, INT(_xlpm.pos/7)+1, _xlpm.rowDate, 3 + (_xlpm.week-1)*11, IF(_xlpm.dayIndex>7,"", INDEX('Marketing Executive'!$C:$I, _xlpm.rowDate, _xlpm.dayIndex)) ), "")} -> 45992 | I6: 46003 | J6: =IF(I6="","",I6-TODAY()) -> 1 | K6: 0.2 | L6: Manager | M6: Google Drive | O6: TRUE
A7: 2 | B7: {=_xlfn.LET( _xlpm.week, $B$4, _xlpm.d, H7, _xlpm.nthTask, COUNTIF($H$6:H7, _xlpm.d), _xlpm.dateHeader, OFFSET('Marketing Executive'!$C$3, (_xlpm.week-1)*11, 0, 1, 7), _xlpm.taskRange, OFFSET('Marketing Executive'!$C$5, (_xlpm.week-1)*11, 0, 7, 7), _xlpm.colIndex, MATCH(_xlpm.d, _xlpm.dateHeader, 0), _xlpm.rawTask, IFERROR(INDEX(_xlpm.taskRange, _xlpm.nthTask, _xlpm.colIndex), ""), IF(OR(_xlpm.rawTask=0, _xlpm.rawTask="0"), "Task Unavailable", _xlpm.rawTask) )} -> XYZ | C7: Medium | E7: {=_xlfn.LET( _xlpm.week, $B$4, _xlpm.rowPerson, 3 + (_xlpm.week-1)*11, _xlpm.personName, INDEX('Marketing Executive'!$B:$B, _xlpm.rowPerson), IF($B7="", "", _xlpm.personName) )} -> Tuyen Nguyen | F7: Colleague | G7: Planned | H7: {=IFERROR( _xlfn.LET( _xlpm.week, $B$4, _xlpm.pos, ROW()-ROW($H$6), _xlpm.dayIndex, INT(_xlpm.pos/7)+1, _xlpm.rowDate, 3 + (_xlpm.week-1)*11, IF(_xlpm.dayIndex>7,"", INDEX('Marketing Executive'!$C:$I, _xlpm.rowDate, _xlpm.dayIndex)) ), "")} -> 45992 | I7: 46004 | J7: =IF(I7="","",I7-TODAY()) -> 2 | L7: Colleague | M7: Cloud Storage | O7: FALSE
A8: 3 | B8: {=_xlfn.LET( _xlpm.week, $B$4, _xlpm.d, H8, _xlpm.nthTask, COUNTIF($H$6:H8, _xlpm.d), _xlpm.dateHeader, OFFSET('Marketing Executive'!$C$3, (_xlpm.week-1)*11, 0, 1, 7), _xlpm.taskRange, OFFSET('Marketing Executive'!$C$5, (_xlpm.week-1)*11, 0, 7, 7), _xlpm.colIndex, MATCH(_xlpm.d, _xlpm.dateHeader, 0), _xlpm.rawTask, IFERROR(INDEX(_xlpm.taskRange, _xlpm.nthTask, _xlpm.colIndex), ""), IF(OR(_xlpm.rawTask=0, _xlpm.rawTask="0"), "Task Unavailable", _xlpm.rawTask) )} -> Task Unavailable | C8: High | E8: {=_xlfn.LET( _xlpm.week, $B$4, _xlpm.rowPerson, 3 + (_xlpm.week-1)*11, _xlpm.personName, INDEX('Marketing Executive'!$B:$B, _xlpm.rowPerson), IF($B8="", "", _xlpm.personName) )} -> Tuyen Nguyen | F8: Boss | G8: In Progress | H8: {=IFERROR( _xlfn.LET( _xlpm.week, $B$4, _xlpm.pos, ROW()-ROW($H$6), _xlpm.dayIndex, INT(_xlpm.pos/7)+1, _xlpm.rowDate, 3 + (_xlpm.week-1)*11, IF(_xlpm.dayIndex>7,"", INDEX('Marketing Executive'!$C:$I, _xlpm.rowDate, _xlpm.dayIndex)) ), "")} -> 45992 | I8: 46009 | J8: =IF(I8="","",I8-TODAY()) -> 7 | L8: Boss | O8: TRUE
A9: 4 | B9: {=_xlfn.LET( _xlpm.week, $B$4, _xlpm.d, H9, _xlpm.nthTask, COUNTIF($H$6:H9, _xlpm.d), _xlpm.dateHeader, OFFSET('Marketing Executive'!$C$3, (_xlpm.week-1)*11, 0, 1, 7), _xlpm.taskRange, OFFSET('Marketing Executive'!$C$5, (_xlpm.week-1)*11, 0, 7, 7), _xlpm.colIndex, MATCH(_xlpm.d, _xlpm.dateHeader, 0), _xlpm.rawTask, IFERROR(INDEX(_xlpm.taskRange, _xlpm.nthTask, _xlpm.colIndex), ""), IF(OR(_xlpm.rawTask=0, _xlpm.rawTask="0"), "Task Unavailable", _xlpm.rawTask) )} -> Task Unavailable | E9: {=_xlfn.LET( _xlpm.week, $B$4, _xlpm.rowPerson, 3 + (_xlpm.week-1)*11, _xlpm.personName, INDEX('Marketing Executive'!$B:$B, _xlpm.rowPerson), IF($B9="", "", _xlpm.personName) )} -> Tuyen Nguyen | G9: Pending | H9: {=IFERROR( _xlfn.LET( _xlpm.week, $B$4, _xlpm.pos, ROW()-ROW($H$6), _xlpm.dayIndex, INT(_xlpm.pos/7)+1, _xlpm.rowDate, 3 + (_xlpm.week-1)*11, IF(_xlpm.dayIndex>7,"", INDEX('Marketing Executive'!$C:$I, _xlpm.rowDate, _xlpm.dayIndex)) ), "")} -> 45992 | J9: =IF(I9="","",I9-TODAY())
A10: 5 | B10: {=_xlfn.LET( _xlpm.week, $B$4, _xlpm.d, H10, _xlpm.nthTask, COUNTIF($H$6:H10, _xlpm.d), _xlpm.dateHeader, OFFSET('Marketing Executive'!$C$3, (_xlpm.week-1)*11, 0, 1, 7), _xlpm.taskRange, OFFSET('Marketing Executive'!$C$5, (_xlpm.week-1)*11, 0, 7, 7), _xlpm.colIndex, MATCH(_xlpm.d, _xlpm.dateHeader, 0), _xlpm.rawTask, IFERROR(INDEX(_xlpm.taskRange, _xlpm.nthTask, _xlpm.colIndex), ""), IF(OR(_xlpm.rawTask=0, _xlpm.rawTask="0"), "Task Unavailable", _xlpm.rawTask) )} -> Task Unavailable | E10: {=_xlfn.LET( _xlpm.week, $B$4, _xlpm.rowPerson, 3 + (_xlpm.week-1)*11, _xlpm.personName, INDEX('Marketing Executive'!$B:$B, _xlpm.rowPerson), IF($B10="", "", _xlpm.personName) )} -> Tuyen Nguyen | G10: Under Review | H10: {=IFERROR( _xlfn.LET( _xlpm.week, $B$4, _xlpm.pos, ROW()-ROW($H$6), _xlpm.dayIndex, INT(_xlpm.pos/7)+1, _xlpm.rowDate, 3 + (_xlpm.week-1)*11, IF(_xlpm.dayIndex>7,"", INDEX('Marketing Executive'!$C:$I, _xlpm.rowDate, _xlpm.dayIndex)) ), "")} -> 45992 | J10: =IF(I10="","",I10-TODAY())
A11: 6 | B11: {=_xlfn.LET( _xlpm.week, $B$4, _xlpm.d, H11, _xlpm.nthTask, COUNTIF($H$6:H11, _xlpm.d), _xlpm.dateHeader, OFFSET('Marketing Executive'!$C$3, (_xlpm.week-1)*11, 0, 1, 7), _xlpm.taskRange, OFFSET('Marketing Executive'!$C$5, (_xlpm.week-1)*11, 0, 7, 7), _xlpm.colIndex, MATCH(_xlpm.d, _xlpm.dateHeader, 0), _xlpm.rawTask, IFERROR(INDEX(_xlpm.taskRange, _xlpm.nthTask, _xlpm.colIndex), ""), IF(OR(_xlpm.rawTask=0, _xlpm.rawTask="0"), "Task Unavailable", _xlpm.rawTask) )} -> Task Unavailable | E11: {=_xlfn.LET( _xlpm.week, $B$4, _xlpm.rowPerson, 3 + (_xlpm.week-1)*11, _xlpm.personName, INDEX('Marketing Executive'!$B:$B, _xlpm.rowPerson), IF($B11="", "", _xlpm.personName) )} -> Tuyen Nguyen | G11: Failed | H11: {=IFERROR( _xlfn.LET( _xlpm.week, $B$4, _xlpm.pos, ROW()-ROW($H$6), _xlpm.dayIndex, INT(_xlpm.pos/7)+1, _xlpm.rowDate, 3 + (_xlpm.week-1)*11, IF(_xlpm.dayIndex>7,"", INDEX('Marketing Executive'!$C:$I, _xlpm.rowDate, _xlpm.dayIndex)) ), "")} -> 45992 | J11: =IF(I11="","",I11-TODAY())
A12: 7 | B12: {=_xlfn.LET( _xlpm.week, $B$4, _xlpm.d, H12, _xlpm.nthTask, COUNTIF($H$6:H12, _xlpm.d), _xlpm.dateHeader, OFFSET('Marketing Executive'!$C$3, (_xlpm.week-1)*11, 0, 1, 7), _xlpm.taskRange, OFFSET('Marketing Executive'!$C$5, (_xlpm.week-1)*11, 0, 7, 7), _xlpm.colIndex, MATCH(_xlpm.d, _xlpm.dateHeader, 0), _xlpm.rawTask, IFERROR(INDEX(_xlpm.taskRange, _xlpm.nthTask, _xlpm.colIndex), ""), IF(OR(_xlpm.rawTask=0, _xlpm.rawTask="0"), "Task Unavailable", _xlpm.rawTask) )} -> Task Unavailable | E12: {=_xlfn.LET( _xlpm.week, $B$4, _xlpm.rowPerson, 3 + (_xlpm.week-1)*11, _xlpm.personName, INDEX('Marketing Executive'!$B:$B, _xlpm.rowPerson), IF($B12="", "", _xlpm.personName) )} -> Tuyen Nguyen | G12: Completed | H12: {=IFERROR( _xlfn.LET( _xlpm.week, $B$4, _xlpm.pos, ROW()-ROW($H$6), _xlpm.dayIndex, INT(_xlpm.pos/7)+1, _xlpm.rowDate, 3 + (_xlpm.week-1)*11, IF(_xlpm.dayIndex>7,"", INDEX('Marketing Executive'!$C:$I, _xlpm.rowDate, _xlpm.dayIndex)) ), "")} -> 45992 | J12: =IF(I12="","",I12-TODAY())
A13: 8 | B13: {=_xlfn.LET( _xlpm.week, $B$4, _xlpm.d, H13, _xlpm.nthTask, COUNTIF($H$6:H13, _xlpm.d), _xlpm.dateHeader, OFFSET('Marketing Executive'!$C$3, (_xlpm.week-1)*11, 0, 1, 7), _xlpm.taskRange, OFFSET('Marketing Executive'!$C$5, (_xlpm.week-1)*11, 0, 7, 7), _xlpm.colIndex, MATCH(_xlpm.d, _xlpm.dateHeader, 0), _xlpm.rawTask, IFERROR(INDEX(_xlpm.taskRange, _xlpm.nthTask, _xlpm.colIndex), ""), IF(OR(_xlpm.rawTask=0, _xlpm.rawTask="0"), "Task Unavailable", _xlpm.rawTask) )} -> 123 | C13: High | E13: {=_xlfn.LET( _xlpm.week, $B$4, _xlpm.rowPerson, 3 + (_xlpm.week-1)*11, _xlpm.personName, INDEX('Marketing Executive'!$B:$B, _xlpm.rowPerson), IF($B13="", "", _xlpm.personName) )} -> Tuyen Nguyen | F13: Boss | G13: Failed | H13: {=IFERROR( _xlfn.LET( _xlpm.week, $B$4, _xlpm.pos, ROW()-ROW($H$6), _xlpm.dayIndex, INT(_xlpm.pos/7)+1, _xlpm.rowDate, 3 + (_xlpm.week-1)*11, IF(_xlpm.dayIndex>7,"", INDEX('Marketing Executive'!$C:$I, _xlpm.rowDate, _xlpm.dayIndex)) ), "")} -> 45993 | I13: 46009 | J13: =IF(I13="","",I13-TODAY()) -> 7 | O13: TRUE
A14: 9 | B14: {=_xlfn.LET( _xlpm.week, $B$4, _xlpm.d, H14, _xlpm.nthTask, COUNTIF($H$6:H14, _xlpm.d), _xlpm.dateHeader, OFFSET('Marketing Executive'!$C$3, (_xlpm.week-1)*11, 0, 1, 7), _xlpm.taskRange, OFFSET('Marketing Executive'!$C$5, (_xlpm.week-1)*11, 0, 7, 7), _xlpm.colIndex, MATCH(_xlpm.d, _xlpm.dateHeader, 0), _xlpm.rawTask, IFERROR(INDEX(_xlpm.taskRange, _xlpm.nthTask, _xlpm.colIndex), ""), IF(OR(_xlpm.rawTask=0, _xlpm.rawTask="0"), "Task Unavailable", _xlpm.rawTask) )} -> Task Unavailable | E14: {=_xlfn.LET( _xlpm.week, $B$4, _xlpm.rowPerson, 3 + (_xlpm.week-1)*11, _xlpm.personName, INDEX('Marketing Executive'!$B:$B, _xlpm.rowPerson), IF($B14="", "", _xlpm.personName) )} -> Tuyen Nguyen | H14: {=IFERROR( _xlfn.LET( _xlpm.week, $B$4, _xlpm.pos, ROW()-ROW($H$6), _xlpm.dayIndex, INT(_xlpm.pos/7)+1, _xlpm.rowDate, 3 + (_xlpm.week-1)*11, IF(_xlpm.dayIndex>7,"", INDEX('Marketing Executive'!$C:$I, _xlpm.rowDate, _xlpm.dayIndex)) ), "")} -> 45993 | J14: =IF(I14="","",I14-TODAY())
A15: 10 | B15: {=_xlfn.LET( _xlpm.week, $B$4, _xlpm.d, H15, _xlpm.nthTask, COUNTIF($H$6:H15, _xlpm.d), _xlpm.dateHeader, OFFSET('Marketing Executive'!$C$3, (_xlpm.week-1)*11, 0, 1, 7), _xlpm.taskRange, OFFSET('Marketing Executive'!$C$5, (_xlpm.week-1)*11, 0, 7, 7), _xlpm.colIndex, MATCH(_xlpm.d, _xlpm.dateHeader, 0), _xlpm.rawTask, IFERROR(INDEX(_xlpm.taskRange, _xlpm.nthTask, _xlpm.colIndex), ""), IF(OR(_xlpm.rawTask=0, _xlpm.rawTask="0"), "Task Unavailable", _xlpm.rawTask) )} -> Task Unavailable | E15: {=_xlfn.LET( _xlpm.week, $B$4, _xlpm.rowPerson, 3 + (_xlpm.week-1)*11, _xlpm.personName, INDEX('Marketing Executive'!$B:$B, _xlpm.rowPerson), IF($B15="", "", _xlpm.personName) )} -> Tuyen Nguyen | H15: {=IFERROR( _xlfn.LET( _xlpm.week, $B$4, _xlpm.pos, ROW()-ROW($H$6), _xlpm.dayIndex, INT(_xlpm.pos/7)+1, _xlpm.rowDate, 3 + (_xlpm.week-1)*11, IF(_xlpm.dayIndex>7,"", INDEX('Marketing Executive'!$C:$I, _xlpm.rowDate, _xlpm.dayIndex)) ), "")} -> 45993 | J15: =IF(I15="","",I15-TODAY())
A16: 11 | B16: {=_xlfn.LET( _xlpm.week, $B$4, _xlpm.d, H16, _xlpm.nthTask, COUNTIF($H$6:H16, _xlpm.d), _xlpm.dateHeader, OFFSET('Marketing Executive'!$C$3, (_xlpm.week-1)*11, 0, 1, 7), _xlpm.taskRange, OFFSET('Marketing Executive'!$C$5, (_xlpm.week-1)*11, 0, 7, 7), _xlpm.colIndex, MATCH(_xlpm.d, _xlpm.dateHeader, 0), _xlpm.rawTask, IFERROR(INDEX(_xlpm.taskRange, _xlpm.nthTask, _xlpm.colIndex), ""), IF(OR(_xlpm.rawTask=0, _xlpm.rawTask="0"), "Task Unavailable", _xlpm.rawTask) )} -> Task Unavailable | E16: {=_xlfn.LET( _xlpm.week, $B$4, _xlpm.rowPerson, 3 + (_xlpm.week-1)*11, _xlpm.personName, INDEX('Marketing Executive'!$B:$B, _xlpm.rowPerson), IF($B16="", "", _xlpm.personName) )} -> Tuyen Nguyen | H16: {=IFERROR( _xlfn.LET( _xlpm.week, $B$4, _xlpm.pos, ROW()-ROW($H$6), _xlpm.dayIndex, INT(_xlpm.pos/7)+1, _xlpm.rowDate, 3 + (_xlpm.week-1)*11, IF(_xlpm.dayIndex>7,"", INDEX('Marketing Executive'!$C:$I, _xlpm.rowDate, _xlpm.dayIndex)) ), "")} -> 45993 | J16: =IF(I16="","",I16-TODAY())
A17: 12 | B17: {=_xlfn.LET( _xlpm.week, $B$4, _xlpm.d, H17, _xlpm.nthTask, COUNTIF($H$6:H17, _xlpm.d), _xlpm.dateHeader, OFFSET('Marketing Executive'!$C$3, (_xlpm.week-1)*11, 0, 1, 7), _xlpm.taskRange, OFFSET('Marketing Executive'!$C$5, (_xlpm.week-1)*11, 0, 7, 7), _xlpm.colIndex, MATCH(_xlpm.d, _xlpm.dateHeader, 0), _xlpm.rawTask, IFERROR(INDEX(_xlpm.taskRange, _xlpm.nthTask, _xlpm.colIndex), ""), IF(OR(_xlpm.rawTask=0, _xlpm.rawTask="0"), "Task Unavailable", _xlpm.rawTask) )} -> Task Unavailable | E17: {=_xlfn.LET( _xlpm.week, $B$4, _xlpm.rowPerson, 3 + (_xlpm.week-1)*11, _xlpm.personName, INDEX('Marketing Executive'!$B:$B, _xlpm.rowPerson), IF($B17="", "", _xlpm.personName) )} -> Tuyen Nguyen | H17: {=IFERROR( _xlfn.LET( _xlpm.week, $B$4, _xlpm.pos, ROW()-ROW($H$6), _xlpm.dayIndex, INT(_xlpm.pos/7)+1, _xlpm.rowDate, 3 + (_xlpm.week-1)*11, IF(_xlpm.dayIndex>7,"", INDEX('Marketing Executive'!$C:$I, _xlpm.rowDate, _xlpm.dayIndex)) ), "")} -> 45993 | J17: =IF(I17="","",I17-TODAY())
A18: 13 | B18: {=_xlfn.LET( _xlpm.week, $B$4, _xlpm.d, H18, _xlpm.nthTask, COUNTIF($H$6:H18, _xlpm.d), _xlpm.dateHeader, OFFSET('Marketing Executive'!$C$3, (_xlpm.week-1)*11, 0, 1, 7), _xlpm.taskRange, OFFSET('Marketing Executive'!$C$5, (_xlpm.week-1)*11, 0, 7, 7), _xlpm.colIndex, MATCH(_xlpm.d, _xlpm.dateHeader, 0), _xlpm.rawTask, IFERROR(INDEX(_xlpm.taskRange, _xlpm.nthTask, _xlpm.colIndex), ""), IF(OR(_xlpm.rawTask=0, _xlpm.rawTask="0"), "Task Unavailable", _xlpm.rawTask) )} -> Task Unavailable | E18: {=_xlfn.LET( _xlpm.week, $B$4, _xlpm.rowPerson, 3 + (_xlpm.week-1)*11, _xlpm.personName, INDEX('Marketing Executive'!$B:$B, _xlpm.rowPerson), IF($B18="", "", _xlpm.personName) )} -> Tuyen Nguyen | H18: {=IFERROR( _xlfn.LET( _xlpm.week, $B$4, _xlpm.pos, ROW()-ROW($H$6), _xlpm.dayIndex, INT(_xlpm.pos/7)+1, _xlpm.rowDate, 3 + (_xlpm.week-1)*11, IF(_xlpm.dayIndex>7,"", INDEX('Marketing Executive'!$C:$I, _xlpm.rowDate, _xlpm.dayIndex)) ), "")} -> 45993 | J18: =IF(I18="","",I18-TODAY())
A19: 14 | B19: {=_xlfn.LET( _xlpm.week, $B$4, _xlpm.d, H19, _xlpm.nthTask, COUNTIF($H$6:H19, _xlpm.d), _xlpm.dateHeader, OFFSET('Marketing Executive'!$C$3, (_xlpm.week-1)*11, 0, 1, 7), _xlpm.taskRange, OFFSET('Marketing Executive'!$C$5, (_xlpm.week-1)*11, 0, 7, 7), _xlpm.colIndex, MATCH(_xlpm.d, _xlpm.dateHeader, 0), _xlpm.rawTask, IFERROR(INDEX(_xlpm.taskRange, _xlpm.nthTask, _xlpm.colIndex), ""), IF(OR(_xlpm.rawTask=0, _xlpm.rawTask="0"), "Task Unavailable", _xlpm.rawTask) )} -> Task Unavailable | E19: {=_xlfn.LET( _xlpm.week, $B$4, _xlpm.rowPerson, 3 + (_xlpm.week-1)*11, _xlpm.personName, INDEX('Marketing Executive'!$B:$B, _xlpm.rowPerson), IF($B19="", "", _xlpm.personName) )} -> Tuyen Nguyen | H19: {=IFERROR( _xlfn.LET( _xlpm.week, $B$4, _xlpm.pos, ROW()-ROW($H$6), _xlpm.dayIndex, INT(_xlpm.pos/7)+1, _xlpm.rowDate, 3 + (_xlpm.week-1)*11, IF(_xlpm.dayIndex>7,"", INDEX('Marketing Executive'!$C:$I, _xlpm.rowDate, _xlpm.dayIndex)) ), "")} -> 45993 | J19: =IF(I19="","",I19-TODAY())
A20: 15 | B20: {=_xlfn.LET( _xlpm.week, $B$4, _xlpm.d, H20, _xlpm.nthTask, COUNTIF($H$6:H20, _xlpm.d), _xlpm.dateHeader, OFFSET('Marketing Executive'!$C$3, (_xlpm.week-1)*11, 0, 1, 7), _xlpm.taskRange, OFFSET('Marketing Executive'!$C$5, (_xlpm.week-1)*11, 0, 7, 7), _xlpm.colIndex, MATCH(_xlpm.d, _xlpm.dateHeader, 0), _xlpm.rawTask, IFERROR(INDEX(_xlpm.taskRange, _xlpm.nthTask, _xlpm.colIndex), ""), IF(OR(_xlpm.rawTask=0, _xlpm.rawTask="0"), "Task Unavailable", _xlpm.rawTask) )} -> Task Unavailable | E20: {=_xlfn.LET( _xlpm.week, $B$4, _xlpm.rowPerson, 3 + (_xlpm.week-1)*11, _xlpm.personName, INDEX('Marketing Executive'!$B:$B, _xlpm.rowPerson), IF($B20="", "", _xlpm.personName) )} -> Tuyen Nguyen | H20: {=IFERROR( _xlfn.LET( _xlpm.week, $B$4, _xlpm.pos, ROW()-ROW($H$6), _xlpm.dayIndex, INT(_xlpm.pos/7)+1, _xlpm.rowDate, 3 + (_xlpm.week-1)*11, IF(_xlpm.dayIndex>7,"", INDEX('Marketing Executive'!$C:$I, _xlpm.rowDate, _xlpm.dayIndex)) ), "")} -> 45994 | J20: =IF(I20="","",I20-TODAY())
A21: 16 | B21: {=_xlfn.LET( _xlpm.week, $B$4, _xlpm.d, H21, _xlpm.nthTask, COUNTIF($H$6:H21, _xlpm.d), _xlpm.dateHeader, OFFSET('Marketing Executive'!$C$3, (_xlpm.week-1)*11, 0, 1, 7), _xlpm.taskRange, OFFSET('Marketing Executive'!$C$5, (_xlpm.week-1)*11, 0, 7, 7), _xlpm.colIndex, MATCH(_xlpm.d, _xlpm.dateHeader, 0), _xlpm.rawTask, IFERROR(INDEX(_xlpm.taskRange, _xlpm.nthTask, _xlpm.colIndex), ""), IF(OR(_xlpm.rawTask=0, _xlpm.rawTask="0"), "Task Unavailable", _xlpm.rawTask) )} -> Task Unavailable | E21: {=_xlfn.LET( _xlpm.week, $B$4, _xlpm.rowPerson, 3 + (_xlpm.week-1)*11, _xlpm.personName, INDEX('Marketing Executive'!$B:$B, _xlpm.rowPerson), IF($B21="", "", _xlpm.personName) )} -> Tuyen Nguyen | H21: {=IFERROR( _xlfn.LET( _xlpm.week, $B$4, _xlpm.pos, ROW()-ROW($H$6), _xlpm.dayIndex, INT(_xlpm.pos/7)+1, _xlpm.rowDate, 3 + (_xlpm.week-1)*11, IF(_xlpm.dayIndex>7,"", INDEX('Marketing Executive'!$C:$I, _xlpm.rowDate, _xlpm.dayIndex)) ), "")} -> 45994 | J21: =IF(I21="","",I21-TODAY())
A22: 17 | B22: {=_xlfn.LET( _xlpm.week, $B$4, _xlpm.d, H22, _xlpm.nthTask, COUNTIF($H$6:H22, _xlpm.d), _xlpm.dateHeader, OFFSET('Marketing Executive'!$C$3, (_xlpm.week-1)*11, 0, 1, 7), _xlpm.taskRange, OFFSET('Marketing Executive'!$C$5, (_xlpm.week-1)*11, 0, 7, 7), _xlpm.colIndex, MATCH(_xlpm.d, _xlpm.dateHeader, 0), _xlpm.rawTask, IFERROR(INDEX(_xlpm.taskRange, _xlpm.nthTask, _xlpm.colIndex), ""), IF(OR(_xlpm.rawTask=0, _xlpm.rawTask="0"), "Task Unavailable", _xlpm.rawTask) )} -> Task Unavailable | E22: {=_xlfn.LET( _xlpm.week, $B$4, _xlpm.rowPerson, 3 + (_xlpm.week-1)*11, _xlpm.personName, INDEX('Marketing Executive'!$B:$B, _xlpm.rowPerson), IF($B22="", "", _xlpm.personName) )} -> Tuyen Nguyen | H22: {=IFERROR( _xlfn.LET( _xlpm.week, $B$4, _xlpm.pos, ROW()-ROW($H$6), _xlpm.dayIndex, INT(_xlpm.pos/7)+1, _xlpm.rowDate, 3 + (_xlpm.week-1)*11, IF(_xlpm.dayIndex>7,"", INDEX('Marketing Executive'!$C:$I, _xlpm.rowDate, _xlpm.dayIndex)) ), "")} -> 45994 | J22: =IF(I22="","",I22-TODAY())
A23: 18 | B23: {=_xlfn.LET( _xlpm.week, $B$4, _xlpm.d, H23, _xlpm.nthTask, COUNTIF($H$6:H23, _xlpm.d), _xlpm.dateHeader, OFFSET('Marketing Executive'!$C$3, (_xlpm.week-1)*11, 0, 1, 7), _xlpm.taskRange, OFFSET('Marketing Executive'!$C$5, (_xlpm.week-1)*11, 0, 7, 7), _xlpm.colIndex, MATCH(_xlpm.d, _xlpm.dateHeader, 0), _xlpm.rawTask, IFERROR(INDEX(_xlpm.taskRange, _xlpm.nthTask, _xlpm.colIndex), ""), IF(OR(_xlpm.rawTask=0, _xlpm.rawTask="0"), "Task Unavailable", _xlpm.rawTask) )} -> Task Unavailable | E23: {=_xlfn.LET( _xlpm.week, $B$4, _xlpm.rowPerson, 3 + (_xlpm.week-1)*11, _xlpm.personName, INDEX('Marketing Executive'!$B:$B, _xlpm.rowPerson), IF($B23="", "", _xlpm.personName) )} -> Tuyen Nguyen | H23: {=IFERROR( _xlfn.LET( _xlpm.week, $B$4, _xlpm.pos, ROW()-ROW($H$6), _xlpm.dayIndex, INT(_xlpm.pos/7)+1, _xlpm.rowDate, 3 + (_xlpm.week-1)*11, IF(_xlpm.dayIndex>7,"", INDEX('Marketing Executive'!$C:$I, _xlpm.rowDate, _xlpm.dayIndex)) ), "")} -> 45994 | J23: =IF(I23="","",I23-TODAY())
A24: 19 | B24: {=_xlfn.LET( _xlpm.week, $B$4, _xlpm.d, H24, _xlpm.nthTask, COUNTIF($H$6:H24, _xlpm.d), _xlpm.dateHeader, OFFSET('Marketing Executive'!$C$3, (_xlpm.week-1)*11, 0, 1, 7), _xlpm.taskRange, OFFSET('Marketing Executive'!$C$5, (_xlpm.week-1)*11, 0, 7, 7), _xlpm.colIndex, MATCH(_xlpm.d, _xlpm.dateHeader, 0), _xlpm.rawTask, IFERROR(INDEX(_xlpm.taskRange, _xlpm.nthTask, _xlpm.colIndex), ""), IF(OR(_xlpm.rawTask=0, _xlpm.rawTask="0"), "Task Unavailable", _xlpm.rawTask) )} -> Task Unavailable | E24: {=_xlfn.LET( _xlpm.week, $B$4, _xlpm.rowPerson, 3 + (_xlpm.week-1)*11, _xlpm.personName, INDEX('Marketing Executive'!$B:$B, _xlpm.rowPerson), IF($B24="", "", _xlpm.personName) )} -> Tuyen Nguyen | H24: {=IFERROR( _xlfn.LET( _xlpm.week, $B$4, _xlpm.pos, ROW()-ROW($H$6), _xlpm.dayIndex, INT(_xlpm.pos/7)+1, _xlpm.rowDate, 3 + (_xlpm.week-1)*11, IF(_xlpm.dayIndex>7,"", INDEX('Marketing Executive'!$C:$I, _xlpm.rowDate, _xlpm.dayIndex)) ), "")} -> 45994 | J24: =IF(I24="","",I24-TODAY())
A25: 20 | B25: {=_xlfn.LET( _xlpm.week, $B$4, _xlpm.d, H25, _xlpm.nthTask, COUNTIF($H$6:H25, _xlpm.d), _xlpm.dateHeader, OFFSET('Marketing Executive'!$C$3, (_xlpm.week-1)*11, 0, 1, 7), _xlpm.taskRange, OFFSET('Marketing Executive'!$C$5, (_xlpm.week-1)*11, 0, 7, 7), _xlpm.colIndex, MATCH(_xlpm.d, _xlpm.dateHeader, 0), _xlpm.rawTask, IFERROR(INDEX(_xlpm.taskRange, _xlpm.nthTask, _xlpm.colIndex), ""), IF(OR(_xlpm.rawTask=0, _xlpm.rawTask="0"), "Task Unavailable", _xlpm.rawTask) )} -> Task Unavailable | E25: {=_xlfn.LET( _xlpm.week, $B$4, _xlpm.rowPerson, 3 + (_xlpm.week-1)*11, _xlpm.personName, INDEX('Marketing Executive'!$B:$B, _xlpm.rowPerson), IF($B25="", "", _xlpm.personName) )} -> Tuyen Nguyen | H25: {=IFERROR( _xlfn.LET( _xlpm.week, $B$4, _xlpm.pos, ROW()-ROW($H$6), _xlpm.dayIndex, INT(_xlpm.pos/7)+1, _xlpm.rowDate, 3 + (_xlpm.week-1)*11, IF(_xlpm.dayIndex>7,"", INDEX('Marketing Executive'!$C:$I, _xlpm.rowDate, _xlpm.dayIndex)) ), "")} -> 45994 | J25: =IF(I25="","",I25-TODAY())
... A47: 42 | B47: {=_xlfn.LET( _xlpm.week, $B$4, _xlpm.d, H47, _xlpm.nthTask, COUNTIF($H$6:H47, _xlpm.d), _xlpm.dateHeader, OFFSET('Marketing Executive'!$C$3, (_xlpm.week-1)*11, 0, 1, 7), _xlpm.taskRange, OFFSET('Marketing Executive'!$C$5, (_xlpm.week-1)*11, 0, 7, 7), _xlpm.colIndex, MATCH(_xlpm.d, _xlpm.dateHeader, 0), _xlpm.rawTask, IFERROR(INDEX(_xlpm.taskRange, _xlpm.nthTask, _xlpm.colIndex), ""), IF(OR(_xlpm.rawTask=0, _xlpm.rawTask="0"), "Task Unavailable", _xlpm.rawTask) )} -> Task Unavailable | E47: {=_xlfn.LET( _xlpm.week, $B$4, _xlpm.rowPerson, 3 + (_xlpm.week-1)*11, _xlpm.personName, INDEX('Marketing Executive'!$B:$B, _xlpm.rowPerson), IF($B47="", "", _xlpm.personName) )} -> Tuyen Nguyen | H47: {=IFERROR( _xlfn.LET( _xlpm.week, $B$4, _xlpm.pos, ROW()-ROW($H$6), _xlpm.dayIndex, INT(_xlpm.pos/7)+1, _xlpm.rowDate, 3 + (_xlpm.week-1)*11, IF(_xlpm.dayIndex>7,"", INDEX('Marketing Executive'!$C:$I, _xlpm.rowDate, _xlpm.dayIndex)) ), "")} -> 45997 | J47: =IF(I47="","",I47-TODAY())
A48: 1 | B48: {=_xlfn.LET( _xlpm.week, $B$4, _xlpm.d, H48, _xlpm.nthTask, COUNTIF($H$48:H48, _xlpm.d), _xlpm.dateHeader, OFFSET('Content Marketer'!$C$3, (_xlpm.week-1)*11, 0, 1, 7), _xlpm.taskRange, OFFSET('Content Marketer'!$C$5, (_xlpm.week-1)*11, 0, 7, 7), _xlpm.colIndex, MATCH(_xlpm.d, _xlpm.dateHeader, 0), _xlpm.rawTask, IFERROR(INDEX(_xlpm.taskRange, _xlpm.nthTask, _xlpm.colIndex), ""), IF(OR(_xlpm.rawTask=0, _xlpm.rawTask="0"), "Task Unavailable", _xlpm.rawTask) )} -> HHXXH | C48: Medium | E48: {=_xlfn.LET( _xlpm.week, $B$4, _xlpm.rowPerson, 3 + (_xlpm.week-1)*11, _xlpm.personName, INDEX('Content Marketer'!$B:$B, _xlpm.rowPerson), IF($B6="", "", _xlpm.personName) )} -> Tan Nguyen | F48: Boss | G48: In Progress | H48: {=IFERROR( _xlfn.LET( _xlpm.week, $B$4, _xlpm.pos, ROW()-ROW($H$48), _xlpm.dayIndex, INT(_xlpm.pos/7)+1, _xlpm.rowDate, 3 + (_xlpm.week-1)*11, IF(_xlpm.dayIndex>7,"", INDEX('Content Marketer'!$C:$I, _xlpm.rowDate, _xlpm.dayIndex)) ), "")} -> 45992 | I48: 46002 | J48: =IF(I48="","",I48-TODAY()) -> 0 | O48: TRUE
A49: 2 | B49: {=_xlfn.LET( _xlpm.week, $B$4, _xlpm.d, H49, _xlpm.nthTask, COUNTIF($H$48:H49, _xlpm.d), _xlpm.dateHeader, OFFSET('Content Marketer'!$C$3, (_xlpm.week-1)*11, 0, 1, 7), _xlpm.taskRange, OFFSET('Content Marketer'!$C$5, (_xlpm.week-1)*11, 0, 7, 7), _xlpm.colIndex, MATCH(_xlpm.d, _xlpm.dateHeader, 0), _xlpm.rawTask, IFERROR(INDEX(_xlpm.taskRange, _xlpm.nthTask, _xlpm.colIndex), ""), IF(OR(_xlpm.rawTask=0, _xlpm.rawTask="0"), "Task Unavailable", _xlpm.rawTask) )} -> LKMA | C49: Low | E49: {=_xlfn.LET( _xlpm.week, $B$4, _xlpm.rowPerson, 3 + (_xlpm.week-1)*11, _xlpm.personName, INDEX('Content Marketer'!$B:$B, _xlpm.rowPerson), IF($B7="", "", _xlpm.personName) )} -> Tan Nguyen | F49: Manager | G49: Pending | H49: {=IFERROR( _xlfn.LET( _xlpm.week, $B$4, _xlpm.pos, ROW()-ROW($H$48), _xlpm.dayIndex, INT(_xlpm.pos/7)+1, _xlpm.rowDate, 3 + (_xlpm.week-1)*11, IF(_xlpm.dayIndex>7,"", INDEX('Content Marketer'!$C:$I, _xlpm.rowDate, _xlpm.dayIndex)) ), "")} -> 45992 | I49: 46003 | J49: =IF(I49="","",I49-TODAY()) -> 1 | O49: TRUE
A50: 3 | B50: {=_xlfn.LET( _xlpm.week, $B$4, _xlpm.d, H50, _xlpm.nthTask, COUNTIF($H$48:H50, _xlpm.d), _xlpm.dateHeader, OFFSET('Content Marketer'!$C$3, (_xlpm.week-1)*11, 0, 1, 7), _xlpm.taskRange, OFFSET('Content Marketer'!$C$5, (_xlpm.week-1)*11, 0, 7, 7), _xlpm.colIndex, MATCH(_xlpm.d, _xlpm.dateHeader, 0), _xlpm.rawTask, IFERROR(INDEX(_xlpm.taskRange, _xlpm.nthTask, _xlpm.colIndex), ""), IF(OR(_xlpm.rawTask=0, _xlpm.rawTask="0"), "Task Unavailable", _xlpm.rawTask) )} -> Task Unavailable | E50: {=_xlfn.LET( _xlpm.week, $B$4, _xlpm.rowPerson, 3 + (_xlpm.week-1)*11, _xlpm.personName, INDEX('Content Marketer'!$B:$B, _xlpm.rowPerson), IF($B8="", "", _xlpm.personName) )} -> Tan Nguyen | H50: {=IFERROR( _xlfn.LET( _xlpm.week, $B$4, _xlpm.pos, ROW()-ROW($H$48), _xlpm.dayIndex, INT(_xlpm.pos/7)+1, _xlpm.rowDate, 3 + (_xlpm.week-1)*11, IF(_xlpm.dayIndex>7,"", INDEX('Content Marketer'!$C:$I, _xlpm.rowDate, _xlpm.dayIndex)) ), "")} -> 45992 | J50: =IF(I50="","",I50-TODAY())
A51: 4 | B51: {=_xlfn.LET( _xlpm.week, $B$4, _xlpm.d, H51, _xlpm.nthTask, COUNTIF($H$48:H51, _xlpm.d), _xlpm.dateHeader, OFFSET('Content Marketer'!$C$3, (_xlpm.week-1)*11, 0, 1, 7), _xlpm.taskRange, OFFSET('Content Marketer'!$C$5, (_xlpm.week-1)*11, 0, 7, 7), _xlpm.colIndex, MATCH(_xlpm.d, _xlpm.dateHeader, 0), _xlpm.rawTask, IFERROR(INDEX(_xlpm.taskRange, _xlpm.nthTask, _xlpm.colIndex), ""), IF(OR(_xlpm.rawTask=0, _xlpm.rawTask="0"), "Task Unavailable", _xlpm.rawTask) )} -> Task Unavailable | E51: {=_xlfn.LET( _xlpm.week, $B$4, _xlpm.rowPerson, 3 + (_xlpm.week-1)*11, _xlpm.personName, INDEX('Content Marketer'!$B:$B, _xlpm.rowPerson), IF($B9="", "", _xlpm.personName) )} -> Tan Nguyen | H51: {=IFERROR( _xlfn.LET( _xlpm.week, $B$4, _xlpm.pos, ROW()-ROW($H$48), _xlpm.dayIndex, INT(_xlpm.pos/7)+1, _xlpm.rowDate, 3 + (_xlpm.week-1)*11, IF(_xlpm.dayIndex>7,"", INDEX('Content Marketer'!$C:$I, _xlpm.rowDate, _xlpm.dayIndex)) ), "")} -> 45992 | J51: =IF(I51="","",I51-TODAY())
A52: 5 | B52: {=_xlfn.LET( _xlpm.week, $B$4, _xlpm.d, H52, _xlpm.nthTask, COUNTIF($H$48:H52, _xlpm.d), _xlpm.dateHeader, OFFSET('Content Marketer'!$C$3, (_xlpm.week-1)*11, 0, 1, 7), _xlpm.taskRange, OFFSET('Content Marketer'!$C$5, (_xlpm.week-1)*11, 0, 7, 7), _xlpm.colIndex, MATCH(_xlpm.d, _xlpm.dateHeader, 0), _xlpm.rawTask, IFERROR(INDEX(_xlpm.taskRange, _xlpm.nthTask, _xlpm.colIndex), ""), IF(OR(_xlpm.rawTask=0, _xlpm.rawTask="0"), "Task Unavailable", _xlpm.rawTask) )} -> Task Unavailable | E52: {=_xlfn.LET( _xlpm.week, $B$4, _xlpm.rowPerson, 3 + (_xlpm.week-1)*11, _xlpm.personName, INDEX('Content Marketer'!$B:$B, _xlpm.rowPerson), IF($B10="", "", _xlpm.personName) )} -> Tan Nguyen | H52: {=IFERROR( _xlfn.LET( _xlpm.week, $B$4, _xlpm.pos, ROW()-ROW($H$48), _xlpm.dayIndex, INT(_xlpm.pos/7)+1, _xlpm.rowDate, 3 + (_xlpm.week-1)*11, IF(_xlpm.dayIndex>7,"", INDEX('Content Marketer'!$C:$I, _xlpm.rowDate, _xlpm.dayIndex)) ), "")} -> 45992 | J52: =IF(I52="","",I52-TODAY())
A53: 6 | B53: {=_xlfn.LET( _xlpm.week, $B$4, _xlpm.d, H53, _xlpm.nthTask, COUNTIF($H$48:H53, _xlpm.d), _xlpm.dateHeader, OFFSET('Content Marketer'!$C$3, (_xlpm.week-1)*11, 0, 1, 7), _xlpm.taskRange, OFFSET('Content Marketer'!$C$5, (_xlpm.week-1)*11, 0, 7, 7), _xlpm.colIndex, MATCH(_xlpm.d, _xlpm.dateHeader, 0), _xlpm.rawTask, IFERROR(INDEX(_xlpm.taskRange, _xlpm.nthTask, _xlpm.colIndex), ""), IF(OR(_xlpm.rawTask=0, _xlpm.rawTask="0"), "Task Unavailable", _xlpm.rawTask) )} -> Task Unavailable | E53: {=_xlfn.LET( _xlpm.week, $B$4, _xlpm.rowPerson, 3 + (_xlpm.week-1)*11, _xlpm.personName, INDEX('Content Marketer'!$B:$B, _xlpm.rowPerson), IF($B11="", "", _xlpm.personName) )} -> Tan Nguyen | H53: {=IFERROR( _xlfn.LET( _xlpm.week, $B$4, _xlpm.pos, ROW()-ROW($H$48), _xlpm.dayIndex, INT(_xlpm.pos/7)+1, _xlpm.rowDate, 3 + (_xlpm.week-1)*11, IF(_xlpm.dayIndex>7,"", INDEX('Content Marketer'!$C:$I, _xlpm.rowDate, _xlpm.dayIndex)) ), "")} -> 45992 | J53: =IF(I53="","",I53-TODAY())
A54: 7 | B54: {=_xlfn.LET( _xlpm.week, $B$4, _xlpm.d, H54, _xlpm.nthTask, COUNTIF($H$48:H54, _xlpm.d), _xlpm.dateHeader, OFFSET('Content Marketer'!$C$3, (_xlpm.week-1)*11, 0, 1, 7), _xlpm.taskRange, OFFSET('Content Marketer'!$C$5, (_xlpm.week-1)*11, 0, 7, 7), _xlpm.colIndex, MATCH(_xlpm.d, _xlpm.dateHeader, 0), _xlpm.rawTask, IFERROR(INDEX(_xlpm.taskRange, _xlpm.nthTask, _xlpm.colIndex), ""), IF(OR(_xlpm.rawTask=0, _xlpm.rawTask="0"), "Task Unavailable", _xlpm.rawTask) )} -> Task Unavailable | E54: {=_xlfn.LET( _xlpm.week, $B$4, _xlpm.rowPerson, 3 + (_xlpm.week-1)*11, _xlpm.personName, INDEX('Content Marketer'!$B:$B, _xlpm.rowPerson), IF($B12="", "", _xlpm.personName) )} -> Tan Nguyen | H54: {=IFERROR( _xlfn.LET( _xlpm.week, $B$4, _xlpm.pos, ROW()-ROW($H$48), _xlpm.dayIndex, INT(_xlpm.pos/7)+1, _xlpm.rowDate, 3 + (_xlpm.week-1)*11, IF(_xlpm.dayIndex>7,"", INDEX('Content Marketer'!$C:$I, _xlpm.rowDate, _xlpm.dayIndex)) ), "")} -> 45992 | J54: =IF(I54="","",I54-TODAY())
A55: 8 | B55: {=_xlfn.LET( _xlpm.week, $B$4, _xlpm.d, H55, _xlpm.nthTask, COUNTIF($H$48:H55, _xlpm.d), _xlpm.dateHeader, OFFSET('Content Marketer'!$C$3, (_xlpm.week-1)*11, 0, 1, 7), _xlpm.taskRange, OFFSET('Content Marketer'!$C$5, (_xlpm.week-1)*11, 0, 7, 7), _xlpm.colIndex, MATCH(_xlpm.d, _xlpm.dateHeader, 0), _xlpm.rawTask, IFERROR(INDEX(_xlpm.taskRange, _xlpm.nthTask, _xlpm.colIndex), ""), IF(OR(_xlpm.rawTask=0, _xlpm.rawTask="0"), "Task Unavailable", _xlpm.rawTask) )} -> Task Unavailable | E55: {=_xlfn.LET( _xlpm.week, $B$4, _xlpm.rowPerson, 3 + (_xlpm.week-1)*11, _xlpm.personName, INDEX('Content Marketer'!$B:$B, _xlpm.rowPerson), IF($B13="", "", _xlpm.personName) )} -> Tan Nguyen | H55: {=IFERROR( _xlfn.LET( _xlpm.week, $B$4, _xlpm.pos, ROW()-ROW($H$48), _xlpm.dayIndex, INT(_xlpm.pos/7)+1, _xlpm.rowDate, 3 + (_xlpm.week-1)*11, IF(_xlpm.dayIndex>7,"", INDEX('Content Marketer'!$C:$I, _xlpm.rowDate, _xlpm.dayIndex)) ), "")} -> 45993 | J55: =IF(I55="","",I55-TODAY())
A56: 9 | B56: {=_xlfn.LET( _xlpm.week, $B$4, _xlpm.d, H56, _xlpm.nthTask, COUNTIF($H$48:H56, _xlpm.d), _xlpm.dateHeader, OFFSET('Content Marketer'!$C$3, (_xlpm.week-1)*11, 0, 1, 7), _xlpm.taskRange, OFFSET('Content Marketer'!$C$5, (_xlpm.week-1)*11, 0, 7, 7), _xlpm.colIndex, MATCH(_xlpm.d, _xlpm.dateHeader, 0), _xlpm.rawTask, IFERROR(INDEX(_xlpm.taskRange, _xlpm.nthTask, _xlpm.colIndex), ""), IF(OR(_xlpm.rawTask=0, _xlpm.rawTask="0"), "Task Unavailable", _xlpm.rawTask) )} -> Task Unavailable | E56: {=_xlfn.LET( _xlpm.week, $B$4, _xlpm.rowPerson, 3 + (_xlpm.week-1)*11, _xlpm.personName, INDEX('Content Marketer'!$B:$B, _xlpm.rowPerson), IF($B14="", "", _xlpm.personName) )} -> Tan Nguyen | H56: {=IFERROR( _xlfn.LET( _xlpm.week, $B$4, _xlpm.pos, ROW()-ROW($H$48), _xlpm.dayIndex, INT(_xlpm.pos/7)+1, _xlpm.rowDate, 3 + (_xlpm.week-1)*11, IF(_xlpm.dayIndex>7,"", INDEX('Content Marketer'!$C:$I, _xlpm.rowDate, _xlpm.dayIndex)) ), "")} -> 45993 | J56: =IF(I56="","",I56-TODAY())
A57: 10 | B57: {=_xlfn.LET( _xlpm.week, $B$4, _xlpm.d, H57, _xlpm.nthTask, COUNTIF($H$48:H57, _xlpm.d), _xlpm.dateHeader, OFFSET('Content Marketer'!$C$3, (_xlpm.week-1)*11, 0, 1, 7), _xlpm.taskRange, OFFSET('Content Marketer'!$C$5, (_xlpm.week-1)*11, 0, 7, 7), _xlpm.colIndex, MATCH(_xlpm.d, _xlpm.dateHeader, 0), _xlpm.rawTask, IFERROR(INDEX(_xlpm.taskRange, _xlpm.nthTask, _xlpm.colIndex), ""), IF(OR(_xlpm.rawTask=0, _xlpm.rawTask="0"), "Task Unavailable", _xlpm.rawTask) )} -> Task Unavailable | E57: {=_xlfn.LET( _xlpm.week, $B$4, _xlpm.rowPerson, 3 + (_xlpm.week-1)*11, _xlpm.personName, INDEX('Content Marketer'!$B:$B, _xlpm.rowPerson), IF($B15="", "", _xlpm.personName) )} -> Tan Nguyen | H57: {=IFERROR( _xlfn.LET( _xlpm.week, $B$4, _xlpm.pos, ROW()-ROW($H$48), _xlpm.dayIndex, INT(_xlpm.pos/7)+1, _xlpm.rowDate, 3 + (_xlpm.week-1)*11, IF(_xlpm.dayIndex>7,"", INDEX('Content Marketer'!$C:$I, _xlpm.rowDate, _xlpm.dayIndex)) ), "")} -> 45993 | J57: =IF(I57="","",I57-TODAY())
A58: 11 | B58: {=_xlfn.LET( _xlpm.week, $B$4, _xlpm.d, H58, _xlpm.nthTask, COUNTIF($H$48:H58, _xlpm.d), _xlpm.dateHeader, OFFSET('Content Marketer'!$C$3, (_xlpm.week-1)*11, 0, 1, 7), _xlpm.taskRange, OFFSET('Content Marketer'!$C$5, (_xlpm.week-1)*11, 0, 7, 7), _xlpm.colIndex, MATCH(_xlpm.d, _xlpm.dateHeader, 0), _xlpm.rawTask, IFERROR(INDEX(_xlpm.taskRange, _xlpm.nthTask, _xlpm.colIndex), ""), IF(OR(_xlpm.rawTask=0, _xlpm.rawTask="0"), "Task Unavailable", _xlpm.rawTask) )} -> Task Unavailable | E58: {=_xlfn.LET( _xlpm.week, $B$4, _xlpm.rowPerson, 3 + (_xlpm.week-1)*11, _xlpm.personName, INDEX('Content Marketer'!$B:$B, _xlpm.rowPerson), IF($B16="", "", _xlpm.personName) )} -> Tan Nguyen | H58: {=IFERROR( _xlfn.LET( _xlpm.week, $B$4, _xlpm.pos, ROW()-ROW($H$48), _xlpm.dayIndex, INT(_xlpm.pos/7)+1, _xlpm.rowDate, 3 + (_xlpm.week-1)*11, IF(_xlpm.dayIndex>7,"", INDEX('Content Marketer'!$C:$I, _xlpm.rowDate, _xlpm.dayIndex)) ), "")} -> 45993 | J58: =IF(I58="","",I58-TODAY())
A59: 12 | B59: {=_xlfn.LET( _xlpm.week, $B$4, _xlpm.d, H59, _xlpm.nthTask, COUNTIF($H$48:H59, _xlpm.d), _xlpm.dateHeader, OFFSET('Content Marketer'!$C$3, (_xlpm.week-1)*11, 0, 1, 7), _xlpm.taskRange, OFFSET('Content Marketer'!$C$5, (_xlpm.week-1)*11, 0, 7, 7), _xlpm.colIndex, MATCH(_xlpm.d, _xlpm.dateHeader, 0), _xlpm.rawTask, IFERROR(INDEX(_xlpm.taskRange, _xlpm.nthTask, _xlpm.colIndex), ""), IF(OR(_xlpm.rawTask=0, _xlpm.rawTask="0"), "Task Unavailable", _xlpm.rawTask) )} -> Task Unavailable | E59: {=_xlfn.LET( _xlpm.week, $B$4, _xlpm.rowPerson, 3 + (_xlpm.week-1)*11, _xlpm.personName, INDEX('Content Marketer'!$B:$B, _xlpm.rowPerson), IF($B17="", "", _xlpm.personName) )} -> Tan Nguyen | H59: {=IFERROR( _xlfn.LET( _xlpm.week, $B$4, _xlpm.pos, ROW()-ROW($H$48), _xlpm.dayIndex, INT(_xlpm.pos/7)+1, _xlpm.rowDate, 3 + (_xlpm.week-1)*11, IF(_xlpm.dayIndex>7,"", INDEX('Content Marketer'!$C:$I, _xlpm.rowDate, _xlpm.dayIndex)) ), "")} -> 45993 | J59: =IF(I59="","",I59-TODAY())
A60: 13 | B60: {=_xlfn.LET( _xlpm.week, $B$4, _xlpm.d, H60, _xlpm.nthTask, COUNTIF($H$48:H60, _xlpm.d), _xlpm.dateHeader, OFFSET('Content Marketer'!$C$3, (_xlpm.week-1)*11, 0, 1, 7), _xlpm.taskRange, OFFSET('Content Marketer'!$C$5, (_xlpm.week-1)*11, 0, 7, 7), _xlpm.colIndex, MATCH(_xlpm.d, _xlpm.dateHeader, 0), _xlpm.rawTask, IFERROR(INDEX(_xlpm.taskRange, _xlpm.nthTask, _xlpm.colIndex), ""), IF(OR(_xlpm.rawTask=0, _xlpm.rawTask="0"), "Task Unavailable", _xlpm.rawTask) )} -> Task Unavailable | E60: {=_xlfn.LET( _xlpm.week, $B$4, _xlpm.rowPerson, 3 + (_xlpm.week-1)*11, _xlpm.personName, INDEX('Content Marketer'!$B:$B, _xlpm.rowPerson), IF($B18="", "", _xlpm.personName) )} -> Tan Nguyen | H60: {=IFERROR( _xlfn.LET( _xlpm.week, $B$4, _xlpm.pos, ROW()-ROW($H$48), _xlpm.dayIndex, INT(_xlpm.pos/7)+1, _xlpm.rowDate, 3 + (_xlpm.week-1)*11, IF(_xlpm.dayIndex>7,"", INDEX('Content Marketer'!$C:$I, _xlpm.rowDate, _xlpm.dayIndex)) ), "")} -> 45993 | J60: =IF(I60="","",I60-TODAY())
A61: 14 | B61: {=_xlfn.LET( _xlpm.week, $B$4, _xlpm.d, H61, _xlpm.nthTask, COUNTIF($H$48:H61, _xlpm.d), _xlpm.dateHeader, OFFSET('Content Marketer'!$C$3, (_xlpm.week-1)*11, 0, 1, 7), _xlpm.taskRange, OFFSET('Content Marketer'!$C$5, (_xlpm.week-1)*11, 0, 7, 7), _xlpm.colIndex, MATCH(_xlpm.d, _xlpm.dateHeader, 0), _xlpm.rawTask, IFERROR(INDEX(_xlpm.taskRange, _xlpm.nthTask, _xlpm.colIndex), ""), IF(OR(_xlpm.rawTask=0, _xlpm.rawTask="0"), "Task Unavailable", _xlpm.rawTask) )} -> Task Unavailable | E61: {=_xlfn.LET( _xlpm.week, $B$4, _xlpm.rowPerson, 3 + (_xlpm.week-1)*11, _xlpm.personName, INDEX('Content Marketer'!$B:$B, _xlpm.rowPerson), IF($B19="", "", _xlpm.personName) )} -> Tan Nguyen | H61: {=IFERROR( _xlfn.LET( _xlpm.week, $B$4, _xlpm.pos, ROW()-ROW($H$48), _xlpm.dayIndex, INT(_xlpm.pos/7)+1, _xlpm.rowDate, 3 + (_xlpm.week-1)*11, IF(_xlpm.dayIndex>7,"", INDEX('Content Marketer'!$C:$I, _xlpm.rowDate, _xlpm.dayIndex)) ), "")} -> 45993 | J61: =IF(I61="","",I61-TODAY())
...

Sheet Task View
A1: TASKS VIEW
A2: YEAR | B2: ='Tasks Tracking'!B2 -> 2026 | H2: {=IFERROR( _xlfn.LET( _xlpm.week,$B$4, _xlpm.dayIndex,INT((ROW()-ROW($H$6))/3)+1, _xlpm.rowDate,3+(_xlpm.week-1)*7, IF(_xlpm.dayIndex>6,"",INDEX('Marketing Executive'!$C:$H,_xlpm.rowDate,_xlpm.dayIndex)) ), "")}
A3: MONTH | B3: ='Tasks Tracking'!B3 -> 1
A4: WEEK | B4: ='Tasks Tracking'!B4 -> 1
A5: No | B5: Task Name | C5: Priority | D5: Description | E5: Owner | F5: Request | G5: Status | H5: Start Date | I5: Due Date | J5: Days Left | K5: Progress % | L5: Report To | M5: File/ Cloud | N5: Results/ Note | O5: Check
A6: {=_xlfn.LET( _xlpm.src, 'Tasks Tracking'!$B$6:$O$173, _xlpm.taskCol, INDEX(_xlpm.src,,1), _xlpm.cleaned, _xlfn._xlws.FILTER(_xlpm.src, (_xlpm.taskCol<>"")*(_xlpm.taskCol<>"Task Unavailable")), _xlfn.HSTACK(_xlfn.SEQUENCE(ROWS(_xlpm.cleaned)), _xlpm.cleaned) )} -> 1 | B6: ABC | C6: Low | D6: 0 | E6: Tuyen Nguyen | F6: Manager | G6: Under Review | H6: 45992 | I6: 46003 | J6: 1 | K6: 0.2 | L6: Manager | M6: Google Drive | N6: 0 | O6: TRUE
A7: 2 | B7: XYZ | C7: Medium | D7: 0 | E7: Tuyen Nguyen | F7: Colleague | G7: Planned | H7: 45992 | I7: 46004 | J7: 2 | K7: 0 | L7: Colleague | M7: Cloud Storage | N7: 0 | O7: FALSE
A8: 3 | B8: 123 | C8: High | D8: 0 | E8: Tuyen Nguyen | F8: Boss | G8: Failed | H8: 45993 | I8: 46009 | J8: 7 | K8: 0 | L8: 0 | M8: 0 | N8: 0 | O8: TRUE
A9: 4 | B9: HHXXH | C9: Medium | D9: 0 | E9: Tan Nguyen | F9: Boss | G9: In Progress | H9: 45992 | I9: 46002 | J9: 0 | K9: 0 | L9: 0 | M9: 0 | N9: 0 | O9: TRUE
A10: 5 | B10: LKMA | C10: Low | D10: 0 | E10: Tan Nguyen | F10: Manager | G10: Pending | H10: 45992 | I10: 46003 | J10: 1 | K10: 0 | L10: 0 | M10: 0 | N10: 0 | O10: TRUE

Sheet Dashboard Report
A1: TASK STATUS SUMMARY
A2: Status | B2: Count | C2: Percentage
A3: Not Started | B3: =COUNTIFS('Task View'!$G:$G,"Not Started") -> 0 | C3: =IF($B$10=0,0,B3/$B$10) -> 0
A4: Planned | B4: =COUNTIFS('Task View'!$G:$G,"Planned") -> 1 | C4: =IF($B$10=0,0,B4/$B$10) -> 0.2
A5: In Progress | B5: =COUNTIFS('Task View'!$G:$G,"In Progress") -> 1 | C5: =IF($B$10=0,0,B5/$B$10) -> 0.2
A6: Pending | B6: =COUNTIF('Task View'!$G:$G,"Pending") -> 1 | C6: =IF($B$10=0,0,B6/$B$10) -> 0.2
A7: Under Review | B7: =COUNTIF('Task View'!$G:$G,"Under Review") -> 1 | C7: =IF($B$10=0,0,B7/$B$10) -> 0.2
A8: Failed | B8: =COUNTIF('Task View'!$G:$G,"Failed") -> 1 | C8: =IF($B$10=0,0,B8/$B$10) -> 0.2
A9: Completed | B9: =COUNTIF('Task View'!$G:$G,"Completed") -> 0 | C9: =IF($B$10=0,0,B9/$B$10) -> 0
A10: Total | B10: =SUM(B3:B9) -> 5 | C10: =SUM(C3:C9) -> 1
A12: TEAM WORKLOAD BY REPORTER
A13: Report To | B13: Active Tasks | C13: Completed Tasks | D13: Total Tasks | E13: Avg Progress %
A14: Boss | B14: =COUNTIFS('Task View'!$F:$F,"Boss",'Task View'!$G:$G,"<>Completed") -> 2 | C14: =COUNTIFS('Task View'!$F:$F,"Boss",'Task View'!$G:$G,"Completed") -> 0 | D14: =B14+C14 -> 2 | E14: =IF(D14=0,0,AVERAGEIF('Task View'!$F:$F,"Boss",'Task View'!$K:$K)) -> 0
A15: Manager | B15: =COUNTIFS('Task View'!$F:$F,"Manager",'Task View'!$G:$G,"<>Completed") -> 2 | C15: =COUNTIFS('Task View'!$F:$F,"Manager",'Task View'!$G:$G,"Completed") -> 0 | D15: =B15+C15 -> 2 | E15: =IF(D15=0,0,AVERAGEIF('Task View'!$F:$F,"Manager",'Task View'!$K:$K)) -> 0.1
A16: Colleague | B16: =COUNTIFS('Task View'!$F:$F,"Colleague",'Task View'!$G:$G,"<>Completed") -> 1 | C16: =COUNTIFS('Task View'!$F:$F,"Colleague",'Task View'!$G:$G,"Completed") -> 0 | D16: =B16+C16 -> 1 | E16: =IF(D16=0,0,AVERAGEIF('Task View'!$F:$F,"Colleague",'Task View'!$K:$K)) -> 0
A17: Total | B17: =SUM(B14:B16) -> 5 | C17: =SUM(C14:C16) -> 0 | D17: =SUM(D14:D16) -> 5
A19: PRIORITY DISTRIBUTION
A20: Priority | B20: Count | C20: % of Total | D20: In Progress | E20: Pending | F20: Completed
A21: High | B21: =COUNTIFS('Task View'!$C:$C, "High") -> 1 | C21: =IF($B$24=0,0,B21/$B$24) -> 0.2 | D21: =COUNTIFS('Task View'!$C:$C,"High",'Task View'!$G:$G,"In Progress") -> 0 | E21: =COUNTIFS('Task View'!$C:$C,"High",'Task View'!$G:$G,"Pending") -> 0 | F21: =COUNTIFS('Task View'!$C:$C,"High",'Task View'!$G:$G,"Completed") -> 0
A22: Medium | B22: =COUNTIFS('Task View'!$C:$C, "Medium") -> 2 | C22: =IF($B$24=0,0,B22/$B$24) -> 0.4 | D22: =COUNTIFS('Task View'!$C:$C,"Medium",'Task View'!$G:$G,"In Progress") -> 1 | E22: =COUNTIFS('Task View'!$C:$C,"Medium",'Task View'!$G:$G,"Pending") -> 0 | F22: =COUNTIFS('Task View'!$C:$C,"Medium",'Task View'!$G:$G,"Completed") -> 0
A23: Low | B23: =COUNTIFS('Task View'!$C:$C, "Low") -> 2 | C23: =IF($B$24=0,0,B23/$B$24) -> 0.4 | D23: =COUNTIFS('Task View'!$C:$C,"Low",'Task View'!$G:$G,"In Progress") -> 0 | E23: =COUNTIFS('Task View'!$C:$C,"Low",'Task View'!$G:$G,"Pending") -> 1 | F23: =COUNTIFS('Task View'!$C:$C,"Low",'Task View'!$G:$G,"Completed") -> 0
A24: Total | B24: =SUM(B21:B23) -> 5 | C24: =SUM(C21:C23) -> 1 | D24: =SUM(D21:D23) -> 1 | E24: =SUM(E21:E23) -> 1 | F24: =SUM(F21:F23) -> 0
A26: UPCOMING DEADLINES (Next 7 Days)
A27: No | B27: Task | C27: Due Date | D27: Days Remaining | E27: Priority | F27: Status
